[2025-06-19T11:31:17.046+0000] {taskinstance.py:1957} INFO - Dependencies all met for dep_context=non-requeueable deps ti=<TaskInstance: week_3_weather_api_dag.create_weather_table scheduled__2025-06-19T06:00:00+00:00 [queued]>
[2025-06-19T11:31:17.077+0000] {taskinstance.py:1957} INFO - Dependencies all met for dep_context=requeueable deps ti=<TaskInstance: week_3_weather_api_dag.create_weather_table scheduled__2025-06-19T06:00:00+00:00 [queued]>
[2025-06-19T11:31:17.078+0000] {taskinstance.py:2171} INFO - Starting attempt 1 of 1
[2025-06-19T11:31:17.102+0000] {taskinstance.py:2192} INFO - Executing <Task(PythonOperator): create_weather_table> on 2025-06-19 06:00:00+00:00
[2025-06-19T11:31:17.122+0000] {standard_task_runner.py:60} INFO - Started process 1062 to run task
[2025-06-19T11:31:17.156+0000] {standard_task_runner.py:87} INFO - Running: ['***', 'tasks', 'run', 'week_3_weather_api_dag', 'create_weather_table', 'scheduled__2025-06-19T06:00:00+00:00', '--job-id', '22', '--raw', '--subdir', 'DAGS_FOLDER/week_3_weather_api_dag.py', '--cfg-path', '/tmp/tmpx4au5u1w']
[2025-06-19T11:31:17.166+0000] {standard_task_runner.py:88} INFO - Job 22: Subtask create_weather_table
[2025-06-19T11:31:17.321+0000] {task_command.py:423} INFO - Running <TaskInstance: week_3_weather_api_dag.create_weather_table scheduled__2025-06-19T06:00:00+00:00 [running]> on host 77bf71b7bc3a
[2025-06-19T11:31:17.546+0000] {taskinstance.py:2481} INFO - Exporting env vars: AIRFLOW_CTX_DAG_OWNER='***' AIRFLOW_CTX_DAG_ID='week_3_weather_api_dag' AIRFLOW_CTX_TASK_ID='create_weather_table' AIRFLOW_CTX_EXECUTION_DATE='2025-06-19T06:00:00+00:00' AIRFLOW_CTX_TRY_NUMBER='1' AIRFLOW_CTX_DAG_RUN_ID='scheduled__2025-06-19T06:00:00+00:00'
[2025-06-19T11:31:17.618+0000] {taskinstance.py:2699} ERROR - Task failed with exception
Traceback (most recent call last):
  File "/home/airflow/.local/lib/python3.8/site-packages/airflow/models/taskinstance.py", line 433, in _execute_task
    result = execute_callable(context=context, **execute_callable_kwargs)
  File "/home/airflow/.local/lib/python3.8/site-packages/airflow/operators/python.py", line 199, in execute
    return_value = self.execute_callable()
  File "/home/airflow/.local/lib/python3.8/site-packages/airflow/operators/python.py", line 216, in execute_callable
    return self.python_callable(*self.op_args, **self.op_kwargs)
  File "/opt/airflow/dags/week_3_weather_api_dag.py", line 47, in _create_weather_table
    connection = pg_hook.get_conn()
  File "/home/airflow/.local/lib/python3.8/site-packages/airflow/providers/postgres/hooks/postgres.py", line 128, in get_conn
    conn = deepcopy(self.connection or self.get_connection(conn_id))
  File "/home/airflow/.local/lib/python3.8/site-packages/airflow/hooks/base.py", line 82, in get_connection
    conn = Connection.get_connection_from_secrets(conn_id)
  File "/home/airflow/.local/lib/python3.8/site-packages/airflow/models/connection.py", line 479, in get_connection_from_secrets
    raise AirflowNotFoundException(f"The conn_id `{conn_id}` isn't defined")
airflow.exceptions.AirflowNotFoundException: The conn_id `weather_postgres_conn` isn't defined
[2025-06-19T11:31:17.632+0000] {taskinstance.py:1138} INFO - Marking task as FAILED. dag_id=week_3_weather_api_dag, task_id=create_weather_table, execution_date=20250619T060000, start_date=20250619T113117, end_date=20250619T113117
[2025-06-19T11:31:17.667+0000] {standard_task_runner.py:107} ERROR - Failed to execute job 22 for task create_weather_table (The conn_id `weather_postgres_conn` isn't defined; 1062)
[2025-06-19T11:31:17.724+0000] {local_task_job_runner.py:234} INFO - Task exited with return code 1
[2025-06-19T11:31:17.807+0000] {taskinstance.py:3281} INFO - 0 downstream tasks scheduled from follow-on schedule check
[2025-06-19T12:06:11.584+0000] {taskinstance.py:1957} INFO - Dependencies all met for dep_context=non-requeueable deps ti=<TaskInstance: week_3_weather_api_dag.create_weather_table scheduled__2025-06-19T06:00:00+00:00 [queued]>
[2025-06-19T12:06:11.652+0000] {taskinstance.py:1957} INFO - Dependencies all met for dep_context=requeueable deps ti=<TaskInstance: week_3_weather_api_dag.create_weather_table scheduled__2025-06-19T06:00:00+00:00 [queued]>
[2025-06-19T12:06:11.655+0000] {taskinstance.py:2171} INFO - Starting attempt 1 of 1
[2025-06-19T12:06:11.854+0000] {taskinstance.py:2192} INFO - Executing <Task(PythonOperator): create_weather_table> on 2025-06-19 06:00:00+00:00
[2025-06-19T12:06:11.874+0000] {standard_task_runner.py:60} INFO - Started process 1585 to run task
[2025-06-19T12:06:11.921+0000] {standard_task_runner.py:87} INFO - Running: ['***', 'tasks', 'run', 'week_3_weather_api_dag', 'create_weather_table', 'scheduled__2025-06-19T06:00:00+00:00', '--job-id', '32', '--raw', '--subdir', 'DAGS_FOLDER/week_3_weather_api_dag.py', '--cfg-path', '/tmp/tmptdzjgxjc']
[2025-06-19T12:06:11.922+0000] {standard_task_runner.py:88} INFO - Job 32: Subtask create_weather_table
[2025-06-19T12:06:12.449+0000] {task_command.py:423} INFO - Running <TaskInstance: week_3_weather_api_dag.create_weather_table scheduled__2025-06-19T06:00:00+00:00 [running]> on host 77bf71b7bc3a
[2025-06-19T12:06:13.253+0000] {taskinstance.py:2481} INFO - Exporting env vars: AIRFLOW_CTX_DAG_OWNER='***' AIRFLOW_CTX_DAG_ID='week_3_weather_api_dag' AIRFLOW_CTX_TASK_ID='create_weather_table' AIRFLOW_CTX_EXECUTION_DATE='2025-06-19T06:00:00+00:00' AIRFLOW_CTX_TRY_NUMBER='1' AIRFLOW_CTX_DAG_RUN_ID='scheduled__2025-06-19T06:00:00+00:00'
[2025-06-19T12:06:13.321+0000] {taskinstance.py:2699} ERROR - Task failed with exception
Traceback (most recent call last):
  File "/home/airflow/.local/lib/python3.8/site-packages/airflow/models/taskinstance.py", line 433, in _execute_task
    result = execute_callable(context=context, **execute_callable_kwargs)
  File "/home/airflow/.local/lib/python3.8/site-packages/airflow/operators/python.py", line 199, in execute
    return_value = self.execute_callable()
  File "/home/airflow/.local/lib/python3.8/site-packages/airflow/operators/python.py", line 216, in execute_callable
    return self.python_callable(*self.op_args, **self.op_kwargs)
  File "/opt/airflow/dags/week_3_weather_api_dag.py", line 44, in _create_weather_table
    connection = pg_hook.get_conn()
  File "/home/airflow/.local/lib/python3.8/site-packages/airflow/providers/postgres/hooks/postgres.py", line 128, in get_conn
    conn = deepcopy(self.connection or self.get_connection(conn_id))
  File "/home/airflow/.local/lib/python3.8/site-packages/airflow/hooks/base.py", line 82, in get_connection
    conn = Connection.get_connection_from_secrets(conn_id)
  File "/home/airflow/.local/lib/python3.8/site-packages/airflow/models/connection.py", line 479, in get_connection_from_secrets
    raise AirflowNotFoundException(f"The conn_id `{conn_id}` isn't defined")
airflow.exceptions.AirflowNotFoundException: The conn_id `weather_postgres_conn` isn't defined
[2025-06-19T12:06:13.343+0000] {taskinstance.py:1138} INFO - Marking task as FAILED. dag_id=week_3_weather_api_dag, task_id=create_weather_table, execution_date=20250619T060000, start_date=20250619T120611, end_date=20250619T120613
[2025-06-19T12:06:13.378+0000] {standard_task_runner.py:107} ERROR - Failed to execute job 32 for task create_weather_table (The conn_id `weather_postgres_conn` isn't defined; 1585)
[2025-06-19T12:06:13.439+0000] {local_task_job_runner.py:234} INFO - Task exited with return code 1
[2025-06-19T12:06:13.597+0000] {taskinstance.py:3281} INFO - 0 downstream tasks scheduled from follow-on schedule check
[2025-06-19T12:19:03.604+0000] {taskinstance.py:1957} INFO - Dependencies all met for dep_context=non-requeueable deps ti=<TaskInstance: week_3_weather_api_dag.create_weather_table scheduled__2025-06-19T06:00:00+00:00 [queued]>
[2025-06-19T12:19:03.688+0000] {taskinstance.py:1957} INFO - Dependencies all met for dep_context=requeueable deps ti=<TaskInstance: week_3_weather_api_dag.create_weather_table scheduled__2025-06-19T06:00:00+00:00 [queued]>
[2025-06-19T12:19:03.693+0000] {taskinstance.py:2171} INFO - Starting attempt 1 of 1
[2025-06-19T12:19:03.792+0000] {taskinstance.py:2192} INFO - Executing <Task(PythonOperator): create_weather_table> on 2025-06-19 06:00:00+00:00
[2025-06-19T12:19:03.834+0000] {standard_task_runner.py:60} INFO - Started process 139 to run task
[2025-06-19T12:19:03.852+0000] {standard_task_runner.py:87} INFO - Running: ['***', 'tasks', 'run', 'week_3_weather_api_dag', 'create_weather_table', 'scheduled__2025-06-19T06:00:00+00:00', '--job-id', '50', '--raw', '--subdir', 'DAGS_FOLDER/week_3_weather_api_dag.py', '--cfg-path', '/tmp/tmp24m_q97n']
[2025-06-19T12:19:03.865+0000] {standard_task_runner.py:88} INFO - Job 50: Subtask create_weather_table
[2025-06-19T12:19:04.290+0000] {task_command.py:423} INFO - Running <TaskInstance: week_3_weather_api_dag.create_weather_table scheduled__2025-06-19T06:00:00+00:00 [running]> on host b96384fab38e
[2025-06-19T12:19:04.752+0000] {taskinstance.py:2481} INFO - Exporting env vars: AIRFLOW_CTX_DAG_OWNER='***' AIRFLOW_CTX_DAG_ID='week_3_weather_api_dag' AIRFLOW_CTX_TASK_ID='create_weather_table' AIRFLOW_CTX_EXECUTION_DATE='2025-06-19T06:00:00+00:00' AIRFLOW_CTX_TRY_NUMBER='1' AIRFLOW_CTX_DAG_RUN_ID='scheduled__2025-06-19T06:00:00+00:00'
[2025-06-19T12:19:04.805+0000] {base.py:83} INFO - Using connection ID 'weather_***_conn' for task execution.
[2025-06-19T12:19:04.822+0000] {python.py:201} INFO - Done. Returned value was: None
[2025-06-19T12:19:04.871+0000] {taskinstance.py:1138} INFO - Marking task as SUCCESS. dag_id=week_3_weather_api_dag, task_id=create_weather_table, execution_date=20250619T060000, start_date=20250619T121903, end_date=20250619T121904
[2025-06-19T12:19:05.058+0000] {local_task_job_runner.py:234} INFO - Task exited with return code 0
[2025-06-19T12:19:05.359+0000] {taskinstance.py:3281} INFO - 0 downstream tasks scheduled from follow-on schedule check
