[2025-06-19T12:24:03.237+0000] {taskinstance.py:1957} INFO - Dependencies all met for dep_context=non-requeueable deps ti=<TaskInstance: weather_api_dag.validate_temperature scheduled__2025-06-19T11:00:00+00:00 [queued]>
[2025-06-19T12:24:03.262+0000] {taskinstance.py:1957} INFO - Dependencies all met for dep_context=requeueable deps ti=<TaskInstance: weather_api_dag.validate_temperature scheduled__2025-06-19T11:00:00+00:00 [queued]>
[2025-06-19T12:24:03.264+0000] {taskinstance.py:2171} INFO - Starting attempt 1 of 1
[2025-06-19T12:24:03.304+0000] {taskinstance.py:2192} INFO - Executing <Task(PythonOperator): validate_temperature> on 2025-06-19 11:00:00+00:00
[2025-06-19T12:24:03.324+0000] {standard_task_runner.py:60} INFO - Started process 233 to run task
[2025-06-19T12:24:03.331+0000] {standard_task_runner.py:87} INFO - Running: ['***', 'tasks', 'run', 'weather_api_dag', 'validate_temperature', 'scheduled__2025-06-19T11:00:00+00:00', '--job-id', '62', '--raw', '--subdir', 'DAGS_FOLDER/weather_api_dag.py', '--cfg-path', '/tmp/tmpmg48x93l']
[2025-06-19T12:24:03.335+0000] {standard_task_runner.py:88} INFO - Job 62: Subtask validate_temperature
[2025-06-19T12:24:03.407+0000] {task_command.py:423} INFO - Running <TaskInstance: weather_api_dag.validate_temperature scheduled__2025-06-19T11:00:00+00:00 [running]> on host b96384fab38e
[2025-06-19T12:24:03.593+0000] {taskinstance.py:2481} INFO - Exporting env vars: AIRFLOW_CTX_DAG_EMAIL='supitchaya.p99@gmail.com' AIRFLOW_CTX_DAG_OWNER='***' AIRFLOW_CTX_DAG_ID='weather_api_dag' AIRFLOW_CTX_TASK_ID='validate_temperature' AIRFLOW_CTX_EXECUTION_DATE='2025-06-19T11:00:00+00:00' AIRFLOW_CTX_TRY_NUMBER='1' AIRFLOW_CTX_DAG_RUN_ID='scheduled__2025-06-19T11:00:00+00:00'
[2025-06-19T12:24:03.719+0000] {context_factory.py:354} INFO - Could not find local file-backed GX project
[2025-06-19T12:24:03.721+0000] {base.py:1511} INFO - Created temporary directory '/tmp/tmp8gs7z408' for ephemeral docs site
[2025-06-19T12:24:03.722+0000] {config.py:191} INFO - Loading 'datasources' ->
[]
[2025-06-19T12:24:03.746+0000] {taskinstance.py:2699} ERROR - Task failed with exception
Traceback (most recent call last):
  File "/home/airflow/.local/lib/python3.8/site-packages/airflow/models/taskinstance.py", line 433, in _execute_task
    result = execute_callable(context=context, **execute_callable_kwargs)
  File "/home/airflow/.local/lib/python3.8/site-packages/airflow/operators/python.py", line 199, in execute
    return_value = self.execute_callable()
  File "/home/airflow/.local/lib/python3.8/site-packages/airflow/operators/python.py", line 216, in execute_callable
    return self.python_callable(*self.op_args, **self.op_kwargs)
  File "/opt/airflow/dags/weather_api_dag.py", line 52, in _validate_temperature
    validator = context_ge.sources.pandas_default.read_dataframe(df)
AttributeError: 'EphemeralDataContext' object has no attribute 'sources'
[2025-06-19T12:24:03.761+0000] {taskinstance.py:1138} INFO - Marking task as FAILED. dag_id=weather_api_dag, task_id=validate_temperature, execution_date=20250619T110000, start_date=20250619T122403, end_date=20250619T122403
[2025-06-19T12:24:03.789+0000] {logging_mixin.py:188} WARNING - /home/***/.local/lib/python3.8/site-packages/***/utils/email.py:154 RemovedInAirflow3Warning: Fetching SMTP credentials from configuration variables will be deprecated in a future release. Please set credentials using a connection instead.
[2025-06-19T12:24:03.790+0000] {configuration.py:1046} WARNING - section/key [smtp/smtp_user] not found in config
[2025-06-19T12:24:03.790+0000] {email.py:270} INFO - Email alerting: attempt 1
[2025-06-19T12:24:03.878+0000] {configuration.py:1046} WARNING - section/key [smtp/smtp_user] not found in config
[2025-06-19T12:24:03.883+0000] {email.py:270} INFO - Email alerting: attempt 1
[2025-06-19T12:24:03.898+0000] {taskinstance.py:826} ERROR - Failed to send email to: ['supitchaya.p99@gmail.com']
Traceback (most recent call last):
  File "/home/airflow/.local/lib/python3.8/site-packages/airflow/models/taskinstance.py", line 2335, in _run_raw_task
    self._execute_task_with_callbacks(context, test_mode, session=session)
  File "/home/airflow/.local/lib/python3.8/site-packages/airflow/models/taskinstance.py", line 2500, in _execute_task_with_callbacks
    result = self._execute_task(context, task_orig)
  File "/home/airflow/.local/lib/python3.8/site-packages/airflow/models/taskinstance.py", line 2517, in _execute_task
    return _execute_task(self, context, task_orig)
  File "/home/airflow/.local/lib/python3.8/site-packages/airflow/models/taskinstance.py", line 433, in _execute_task
    result = execute_callable(context=context, **execute_callable_kwargs)
  File "/home/airflow/.local/lib/python3.8/site-packages/airflow/operators/python.py", line 199, in execute
    return_value = self.execute_callable()
  File "/home/airflow/.local/lib/python3.8/site-packages/airflow/operators/python.py", line 216, in execute_callable
    return self.python_callable(*self.op_args, **self.op_kwargs)
  File "/opt/airflow/dags/weather_api_dag.py", line 52, in _validate_temperature
    validator = context_ge.sources.pandas_default.read_dataframe(df)
AttributeError: 'EphemeralDataContext' object has no attribute 'sources'

During handling of the above exception, another exception occurred:

Traceback (most recent call last):
  File "/home/airflow/.local/lib/python3.8/site-packages/airflow/models/taskinstance.py", line 1000, in _email_alert
    send_email(task.email, subject, html_content)
  File "/home/airflow/.local/lib/python3.8/site-packages/airflow/utils/email.py", line 80, in send_email
    return backend(
  File "/home/airflow/.local/lib/python3.8/site-packages/airflow/utils/email.py", line 154, in send_email_smtp
    send_mime_email(e_from=mail_from, e_to=recipients, mime_msg=msg, conn_id=conn_id, dryrun=dryrun)
  File "/home/airflow/.local/lib/python3.8/site-packages/airflow/utils/email.py", line 272, in send_mime_email
    smtp_conn = _get_smtp_connection(smtp_host, smtp_port, smtp_timeout, smtp_ssl)
  File "/home/airflow/.local/lib/python3.8/site-packages/airflow/utils/email.py", line 316, in _get_smtp_connection
    return smtplib.SMTP(host=host, port=port, timeout=timeout)
  File "/usr/local/lib/python3.8/smtplib.py", line 255, in __init__
    (code, msg) = self.connect(host, port)
  File "/usr/local/lib/python3.8/smtplib.py", line 339, in connect
    self.sock = self._get_socket(host, port, self.timeout)
  File "/usr/local/lib/python3.8/smtplib.py", line 310, in _get_socket
    return socket.create_connection((host, port), timeout,
  File "/usr/local/lib/python3.8/socket.py", line 787, in create_connection
    for res in getaddrinfo(host, port, 0, SOCK_STREAM):
  File "/usr/local/lib/python3.8/socket.py", line 918, in getaddrinfo
    for res in _socket.getaddrinfo(host, port, family, type, proto, flags):
socket.gaierror: [Errno -2] Name or service not known

During handling of the above exception, another exception occurred:

Traceback (most recent call last):
  File "/home/airflow/.local/lib/python3.8/site-packages/airflow/models/taskinstance.py", line 824, in _handle_failure
    task_instance.email_alert(error, failure_context["task"])
  File "/home/airflow/.local/lib/python3.8/site-packages/airflow/models/taskinstance.py", line 2947, in email_alert
    _email_alert(task_instance=self, exception=exception, task=task)
  File "/home/airflow/.local/lib/python3.8/site-packages/airflow/models/taskinstance.py", line 1002, in _email_alert
    send_email(task.email, subject, html_content_err)
  File "/home/airflow/.local/lib/python3.8/site-packages/airflow/utils/email.py", line 80, in send_email
    return backend(
  File "/home/airflow/.local/lib/python3.8/site-packages/airflow/utils/email.py", line 154, in send_email_smtp
    send_mime_email(e_from=mail_from, e_to=recipients, mime_msg=msg, conn_id=conn_id, dryrun=dryrun)
  File "/home/airflow/.local/lib/python3.8/site-packages/airflow/utils/email.py", line 272, in send_mime_email
    smtp_conn = _get_smtp_connection(smtp_host, smtp_port, smtp_timeout, smtp_ssl)
  File "/home/airflow/.local/lib/python3.8/site-packages/airflow/utils/email.py", line 316, in _get_smtp_connection
    return smtplib.SMTP(host=host, port=port, timeout=timeout)
  File "/usr/local/lib/python3.8/smtplib.py", line 255, in __init__
    (code, msg) = self.connect(host, port)
  File "/usr/local/lib/python3.8/smtplib.py", line 339, in connect
    self.sock = self._get_socket(host, port, self.timeout)
  File "/usr/local/lib/python3.8/smtplib.py", line 310, in _get_socket
    return socket.create_connection((host, port), timeout,
  File "/usr/local/lib/python3.8/socket.py", line 787, in create_connection
    for res in getaddrinfo(host, port, 0, SOCK_STREAM):
  File "/usr/local/lib/python3.8/socket.py", line 918, in getaddrinfo
    for res in _socket.getaddrinfo(host, port, family, type, proto, flags):
socket.gaierror: [Errno -2] Name or service not known
[2025-06-19T12:24:03.919+0000] {standard_task_runner.py:107} ERROR - Failed to execute job 62 for task validate_temperature ('EphemeralDataContext' object has no attribute 'sources'; 233)
[2025-06-19T12:24:03.993+0000] {local_task_job_runner.py:234} INFO - Task exited with return code 1
[2025-06-19T12:24:04.083+0000] {taskinstance.py:3281} INFO - 0 downstream tasks scheduled from follow-on schedule check
