[2025-06-16T10:17:14.987+0000] {processor.py:161} INFO - Started process (PID=64) to work on /opt/airflow/dags/weather_api_dag.py
[2025-06-16T10:17:14.999+0000] {processor.py:830} INFO - Processing file /opt/airflow/dags/weather_api_dag.py for tasks to queue
[2025-06-16T10:17:15.019+0000] {logging_mixin.py:188} INFO - [2025-06-16T10:17:15.011+0000] {dagbag.py:538} INFO - Filling up the DagBag from /opt/airflow/dags/weather_api_dag.py
[2025-06-16T10:17:29.708+0000] {logging_mixin.py:188} INFO - [2025-06-16T10:17:29.706+0000] {dagbag.py:348} ERROR - Failed to import: /opt/airflow/dags/weather_api_dag.py
Traceback (most recent call last):
  File "/home/airflow/.local/lib/python3.8/site-packages/airflow/models/dagbag.py", line 344, in parse
    loader.exec_module(new_module)
  File "<frozen importlib._bootstrap_external>", line 843, in exec_module
  File "<frozen importlib._bootstrap>", line 219, in _call_with_frames_removed
  File "/opt/airflow/dags/weather_api_dag.py", line 13, in <module>
    from great_expectations.dataset import PandasDataset
ModuleNotFoundError: No module named 'great_expectations.dataset'
[2025-06-16T10:17:29.709+0000] {processor.py:842} WARNING - No viable dags retrieved from /opt/airflow/dags/weather_api_dag.py
[2025-06-16T10:17:29.722+0000] {processor.py:183} INFO - Processing /opt/airflow/dags/weather_api_dag.py took 14.744 seconds
[2025-06-16T10:18:00.681+0000] {processor.py:161} INFO - Started process (PID=98) to work on /opt/airflow/dags/weather_api_dag.py
[2025-06-16T10:18:00.682+0000] {processor.py:830} INFO - Processing file /opt/airflow/dags/weather_api_dag.py for tasks to queue
[2025-06-16T10:18:00.685+0000] {logging_mixin.py:188} INFO - [2025-06-16T10:18:00.684+0000] {dagbag.py:538} INFO - Filling up the DagBag from /opt/airflow/dags/weather_api_dag.py
[2025-06-16T10:18:03.781+0000] {logging_mixin.py:188} INFO - [2025-06-16T10:18:03.780+0000] {dagbag.py:348} ERROR - Failed to import: /opt/airflow/dags/weather_api_dag.py
Traceback (most recent call last):
  File "/home/airflow/.local/lib/python3.8/site-packages/airflow/models/dagbag.py", line 344, in parse
    loader.exec_module(new_module)
  File "<frozen importlib._bootstrap_external>", line 843, in exec_module
  File "<frozen importlib._bootstrap>", line 219, in _call_with_frames_removed
  File "/opt/airflow/dags/weather_api_dag.py", line 13, in <module>
    from great_expectations.dataset import PandasDataset
ModuleNotFoundError: No module named 'great_expectations.dataset'
[2025-06-16T10:18:03.782+0000] {processor.py:842} WARNING - No viable dags retrieved from /opt/airflow/dags/weather_api_dag.py
[2025-06-16T10:18:03.795+0000] {processor.py:183} INFO - Processing /opt/airflow/dags/weather_api_dag.py took 3.118 seconds
[2025-06-16T10:18:34.202+0000] {processor.py:161} INFO - Started process (PID=122) to work on /opt/airflow/dags/weather_api_dag.py
[2025-06-16T10:18:34.202+0000] {processor.py:830} INFO - Processing file /opt/airflow/dags/weather_api_dag.py for tasks to queue
[2025-06-16T10:18:34.204+0000] {logging_mixin.py:188} INFO - [2025-06-16T10:18:34.204+0000] {dagbag.py:538} INFO - Filling up the DagBag from /opt/airflow/dags/weather_api_dag.py
[2025-06-16T10:18:37.892+0000] {logging_mixin.py:188} INFO - [2025-06-16T10:18:37.891+0000] {dagbag.py:348} ERROR - Failed to import: /opt/airflow/dags/weather_api_dag.py
Traceback (most recent call last):
  File "/home/airflow/.local/lib/python3.8/site-packages/airflow/models/dagbag.py", line 344, in parse
    loader.exec_module(new_module)
  File "<frozen importlib._bootstrap_external>", line 843, in exec_module
  File "<frozen importlib._bootstrap>", line 219, in _call_with_frames_removed
  File "/opt/airflow/dags/weather_api_dag.py", line 13, in <module>
    from great_expectations.dataset import PandasDataset
ModuleNotFoundError: No module named 'great_expectations.dataset'
[2025-06-16T10:18:37.893+0000] {processor.py:842} WARNING - No viable dags retrieved from /opt/airflow/dags/weather_api_dag.py
[2025-06-16T10:18:37.911+0000] {processor.py:183} INFO - Processing /opt/airflow/dags/weather_api_dag.py took 3.712 seconds
[2025-06-16T10:19:08.516+0000] {processor.py:161} INFO - Started process (PID=153) to work on /opt/airflow/dags/weather_api_dag.py
[2025-06-16T10:19:08.517+0000] {processor.py:830} INFO - Processing file /opt/airflow/dags/weather_api_dag.py for tasks to queue
[2025-06-16T10:19:08.519+0000] {logging_mixin.py:188} INFO - [2025-06-16T10:19:08.519+0000] {dagbag.py:538} INFO - Filling up the DagBag from /opt/airflow/dags/weather_api_dag.py
[2025-06-16T10:19:11.271+0000] {logging_mixin.py:188} INFO - [2025-06-16T10:19:11.269+0000] {dagbag.py:348} ERROR - Failed to import: /opt/airflow/dags/weather_api_dag.py
Traceback (most recent call last):
  File "/home/airflow/.local/lib/python3.8/site-packages/airflow/models/dagbag.py", line 344, in parse
    loader.exec_module(new_module)
  File "<frozen importlib._bootstrap_external>", line 843, in exec_module
  File "<frozen importlib._bootstrap>", line 219, in _call_with_frames_removed
  File "/opt/airflow/dags/weather_api_dag.py", line 13, in <module>
    from great_expectations.dataset import PandasDataset
ModuleNotFoundError: No module named 'great_expectations.dataset'
[2025-06-16T10:19:11.271+0000] {processor.py:842} WARNING - No viable dags retrieved from /opt/airflow/dags/weather_api_dag.py
[2025-06-16T10:19:11.286+0000] {processor.py:183} INFO - Processing /opt/airflow/dags/weather_api_dag.py took 2.775 seconds
[2025-06-16T10:19:41.720+0000] {processor.py:161} INFO - Started process (PID=184) to work on /opt/airflow/dags/weather_api_dag.py
[2025-06-16T10:19:41.721+0000] {processor.py:830} INFO - Processing file /opt/airflow/dags/weather_api_dag.py for tasks to queue
[2025-06-16T10:19:41.724+0000] {logging_mixin.py:188} INFO - [2025-06-16T10:19:41.723+0000] {dagbag.py:538} INFO - Filling up the DagBag from /opt/airflow/dags/weather_api_dag.py
[2025-06-16T10:19:45.133+0000] {logging_mixin.py:188} INFO - [2025-06-16T10:19:45.132+0000] {dagbag.py:348} ERROR - Failed to import: /opt/airflow/dags/weather_api_dag.py
Traceback (most recent call last):
  File "/home/airflow/.local/lib/python3.8/site-packages/airflow/models/dagbag.py", line 344, in parse
    loader.exec_module(new_module)
  File "<frozen importlib._bootstrap_external>", line 843, in exec_module
  File "<frozen importlib._bootstrap>", line 219, in _call_with_frames_removed
  File "/opt/airflow/dags/weather_api_dag.py", line 13, in <module>
    from great_expectations.dataset import PandasDataset
ModuleNotFoundError: No module named 'great_expectations.dataset'
[2025-06-16T10:19:45.133+0000] {processor.py:842} WARNING - No viable dags retrieved from /opt/airflow/dags/weather_api_dag.py
[2025-06-16T10:19:45.145+0000] {processor.py:183} INFO - Processing /opt/airflow/dags/weather_api_dag.py took 3.429 seconds
[2025-06-16T10:20:15.563+0000] {processor.py:161} INFO - Started process (PID=209) to work on /opt/airflow/dags/weather_api_dag.py
[2025-06-16T10:20:15.564+0000] {processor.py:830} INFO - Processing file /opt/airflow/dags/weather_api_dag.py for tasks to queue
[2025-06-16T10:20:15.565+0000] {logging_mixin.py:188} INFO - [2025-06-16T10:20:15.565+0000] {dagbag.py:538} INFO - Filling up the DagBag from /opt/airflow/dags/weather_api_dag.py
[2025-06-16T10:20:18.381+0000] {logging_mixin.py:188} INFO - [2025-06-16T10:20:18.380+0000] {dagbag.py:348} ERROR - Failed to import: /opt/airflow/dags/weather_api_dag.py
Traceback (most recent call last):
  File "/home/airflow/.local/lib/python3.8/site-packages/airflow/models/dagbag.py", line 344, in parse
    loader.exec_module(new_module)
  File "<frozen importlib._bootstrap_external>", line 843, in exec_module
  File "<frozen importlib._bootstrap>", line 219, in _call_with_frames_removed
  File "/opt/airflow/dags/weather_api_dag.py", line 13, in <module>
    from great_expectations.dataset import PandasDataset
ModuleNotFoundError: No module named 'great_expectations.dataset'
[2025-06-16T10:20:18.382+0000] {processor.py:842} WARNING - No viable dags retrieved from /opt/airflow/dags/weather_api_dag.py
[2025-06-16T10:20:18.395+0000] {processor.py:183} INFO - Processing /opt/airflow/dags/weather_api_dag.py took 2.835 seconds
[2025-06-16T10:20:48.693+0000] {processor.py:161} INFO - Started process (PID=242) to work on /opt/airflow/dags/weather_api_dag.py
[2025-06-16T10:20:48.693+0000] {processor.py:830} INFO - Processing file /opt/airflow/dags/weather_api_dag.py for tasks to queue
[2025-06-16T10:20:48.695+0000] {logging_mixin.py:188} INFO - [2025-06-16T10:20:48.695+0000] {dagbag.py:538} INFO - Filling up the DagBag from /opt/airflow/dags/weather_api_dag.py
[2025-06-16T10:20:51.698+0000] {logging_mixin.py:188} INFO - [2025-06-16T10:20:51.696+0000] {dagbag.py:348} ERROR - Failed to import: /opt/airflow/dags/weather_api_dag.py
Traceback (most recent call last):
  File "/home/airflow/.local/lib/python3.8/site-packages/airflow/models/dagbag.py", line 344, in parse
    loader.exec_module(new_module)
  File "<frozen importlib._bootstrap_external>", line 843, in exec_module
  File "<frozen importlib._bootstrap>", line 219, in _call_with_frames_removed
  File "/opt/airflow/dags/weather_api_dag.py", line 13, in <module>
    from great_expectations.dataset import PandasDataset
ModuleNotFoundError: No module named 'great_expectations.dataset'
[2025-06-16T10:20:51.699+0000] {processor.py:842} WARNING - No viable dags retrieved from /opt/airflow/dags/weather_api_dag.py
[2025-06-16T10:20:51.734+0000] {processor.py:183} INFO - Processing /opt/airflow/dags/weather_api_dag.py took 3.044 seconds
[2025-06-16T10:21:22.190+0000] {processor.py:161} INFO - Started process (PID=266) to work on /opt/airflow/dags/weather_api_dag.py
[2025-06-16T10:21:22.195+0000] {processor.py:830} INFO - Processing file /opt/airflow/dags/weather_api_dag.py for tasks to queue
[2025-06-16T10:21:22.201+0000] {logging_mixin.py:188} INFO - [2025-06-16T10:21:22.201+0000] {dagbag.py:538} INFO - Filling up the DagBag from /opt/airflow/dags/weather_api_dag.py
[2025-06-16T10:21:27.023+0000] {logging_mixin.py:188} INFO - [2025-06-16T10:21:27.021+0000] {dagbag.py:348} ERROR - Failed to import: /opt/airflow/dags/weather_api_dag.py
Traceback (most recent call last):
  File "/home/airflow/.local/lib/python3.8/site-packages/airflow/models/dagbag.py", line 344, in parse
    loader.exec_module(new_module)
  File "<frozen importlib._bootstrap_external>", line 843, in exec_module
  File "<frozen importlib._bootstrap>", line 219, in _call_with_frames_removed
  File "/opt/airflow/dags/weather_api_dag.py", line 13, in <module>
    from great_expectations.dataset import PandasDataset
ModuleNotFoundError: No module named 'great_expectations.dataset'
[2025-06-16T10:21:27.024+0000] {processor.py:842} WARNING - No viable dags retrieved from /opt/airflow/dags/weather_api_dag.py
[2025-06-16T10:21:27.043+0000] {processor.py:183} INFO - Processing /opt/airflow/dags/weather_api_dag.py took 4.872 seconds
[2025-06-16T10:21:57.677+0000] {processor.py:161} INFO - Started process (PID=299) to work on /opt/airflow/dags/weather_api_dag.py
[2025-06-16T10:21:57.678+0000] {processor.py:830} INFO - Processing file /opt/airflow/dags/weather_api_dag.py for tasks to queue
[2025-06-16T10:21:57.681+0000] {logging_mixin.py:188} INFO - [2025-06-16T10:21:57.681+0000] {dagbag.py:538} INFO - Filling up the DagBag from /opt/airflow/dags/weather_api_dag.py
[2025-06-16T10:22:00.676+0000] {logging_mixin.py:188} INFO - [2025-06-16T10:22:00.675+0000] {dagbag.py:348} ERROR - Failed to import: /opt/airflow/dags/weather_api_dag.py
Traceback (most recent call last):
  File "/home/airflow/.local/lib/python3.8/site-packages/airflow/models/dagbag.py", line 344, in parse
    loader.exec_module(new_module)
  File "<frozen importlib._bootstrap_external>", line 843, in exec_module
  File "<frozen importlib._bootstrap>", line 219, in _call_with_frames_removed
  File "/opt/airflow/dags/weather_api_dag.py", line 13, in <module>
    from great_expectations.dataset import PandasDataset
ModuleNotFoundError: No module named 'great_expectations.dataset'
[2025-06-16T10:22:00.677+0000] {processor.py:842} WARNING - No viable dags retrieved from /opt/airflow/dags/weather_api_dag.py
[2025-06-16T10:22:00.690+0000] {processor.py:183} INFO - Processing /opt/airflow/dags/weather_api_dag.py took 3.015 seconds
[2025-06-16T10:22:30.854+0000] {processor.py:161} INFO - Started process (PID=331) to work on /opt/airflow/dags/weather_api_dag.py
[2025-06-16T10:22:30.855+0000] {processor.py:830} INFO - Processing file /opt/airflow/dags/weather_api_dag.py for tasks to queue
[2025-06-16T10:22:30.857+0000] {logging_mixin.py:188} INFO - [2025-06-16T10:22:30.857+0000] {dagbag.py:538} INFO - Filling up the DagBag from /opt/airflow/dags/weather_api_dag.py
[2025-06-16T10:22:33.732+0000] {logging_mixin.py:188} INFO - [2025-06-16T10:22:33.731+0000] {dagbag.py:348} ERROR - Failed to import: /opt/airflow/dags/weather_api_dag.py
Traceback (most recent call last):
  File "/home/airflow/.local/lib/python3.8/site-packages/airflow/models/dagbag.py", line 344, in parse
    loader.exec_module(new_module)
  File "<frozen importlib._bootstrap_external>", line 843, in exec_module
  File "<frozen importlib._bootstrap>", line 219, in _call_with_frames_removed
  File "/opt/airflow/dags/weather_api_dag.py", line 13, in <module>
    from great_expectations.dataset import PandasDataset
ModuleNotFoundError: No module named 'great_expectations.dataset'
[2025-06-16T10:22:33.732+0000] {processor.py:842} WARNING - No viable dags retrieved from /opt/airflow/dags/weather_api_dag.py
[2025-06-16T10:22:33.745+0000] {processor.py:183} INFO - Processing /opt/airflow/dags/weather_api_dag.py took 2.893 seconds
[2025-06-16T10:23:03.803+0000] {processor.py:161} INFO - Started process (PID=355) to work on /opt/airflow/dags/weather_api_dag.py
[2025-06-16T10:23:03.804+0000] {processor.py:830} INFO - Processing file /opt/airflow/dags/weather_api_dag.py for tasks to queue
[2025-06-16T10:23:03.806+0000] {logging_mixin.py:188} INFO - [2025-06-16T10:23:03.806+0000] {dagbag.py:538} INFO - Filling up the DagBag from /opt/airflow/dags/weather_api_dag.py
[2025-06-16T10:23:07.066+0000] {logging_mixin.py:188} INFO - [2025-06-16T10:23:07.065+0000] {dagbag.py:348} ERROR - Failed to import: /opt/airflow/dags/weather_api_dag.py
Traceback (most recent call last):
  File "/home/airflow/.local/lib/python3.8/site-packages/airflow/models/dagbag.py", line 344, in parse
    loader.exec_module(new_module)
  File "<frozen importlib._bootstrap_external>", line 843, in exec_module
  File "<frozen importlib._bootstrap>", line 219, in _call_with_frames_removed
  File "/opt/airflow/dags/weather_api_dag.py", line 13, in <module>
    from great_expectations.dataset import PandasDataset
ModuleNotFoundError: No module named 'great_expectations.dataset'
[2025-06-16T10:23:07.067+0000] {processor.py:842} WARNING - No viable dags retrieved from /opt/airflow/dags/weather_api_dag.py
[2025-06-16T10:23:07.087+0000] {processor.py:183} INFO - Processing /opt/airflow/dags/weather_api_dag.py took 3.287 seconds
[2025-06-16T10:23:37.420+0000] {processor.py:161} INFO - Started process (PID=387) to work on /opt/airflow/dags/weather_api_dag.py
[2025-06-16T10:23:37.421+0000] {processor.py:830} INFO - Processing file /opt/airflow/dags/weather_api_dag.py for tasks to queue
[2025-06-16T10:23:37.422+0000] {logging_mixin.py:188} INFO - [2025-06-16T10:23:37.422+0000] {dagbag.py:538} INFO - Filling up the DagBag from /opt/airflow/dags/weather_api_dag.py
[2025-06-16T10:23:40.228+0000] {logging_mixin.py:188} INFO - [2025-06-16T10:23:40.227+0000] {dagbag.py:348} ERROR - Failed to import: /opt/airflow/dags/weather_api_dag.py
Traceback (most recent call last):
  File "/home/airflow/.local/lib/python3.8/site-packages/airflow/models/dagbag.py", line 344, in parse
    loader.exec_module(new_module)
  File "<frozen importlib._bootstrap_external>", line 843, in exec_module
  File "<frozen importlib._bootstrap>", line 219, in _call_with_frames_removed
  File "/opt/airflow/dags/weather_api_dag.py", line 13, in <module>
    from great_expectations.dataset import PandasDataset
ModuleNotFoundError: No module named 'great_expectations.dataset'
[2025-06-16T10:23:40.228+0000] {processor.py:842} WARNING - No viable dags retrieved from /opt/airflow/dags/weather_api_dag.py
[2025-06-16T10:23:40.241+0000] {processor.py:183} INFO - Processing /opt/airflow/dags/weather_api_dag.py took 2.824 seconds
[2025-06-16T10:24:10.312+0000] {processor.py:161} INFO - Started process (PID=420) to work on /opt/airflow/dags/weather_api_dag.py
[2025-06-16T10:24:10.316+0000] {processor.py:830} INFO - Processing file /opt/airflow/dags/weather_api_dag.py for tasks to queue
[2025-06-16T10:24:10.319+0000] {logging_mixin.py:188} INFO - [2025-06-16T10:24:10.318+0000] {dagbag.py:538} INFO - Filling up the DagBag from /opt/airflow/dags/weather_api_dag.py
[2025-06-16T10:24:13.942+0000] {logging_mixin.py:188} INFO - [2025-06-16T10:24:13.941+0000] {dagbag.py:348} ERROR - Failed to import: /opt/airflow/dags/weather_api_dag.py
Traceback (most recent call last):
  File "/home/airflow/.local/lib/python3.8/site-packages/airflow/models/dagbag.py", line 344, in parse
    loader.exec_module(new_module)
  File "<frozen importlib._bootstrap_external>", line 843, in exec_module
  File "<frozen importlib._bootstrap>", line 219, in _call_with_frames_removed
  File "/opt/airflow/dags/weather_api_dag.py", line 13, in <module>
    from great_expectations.dataset import PandasDataset
ModuleNotFoundError: No module named 'great_expectations.dataset'
[2025-06-16T10:24:13.942+0000] {processor.py:842} WARNING - No viable dags retrieved from /opt/airflow/dags/weather_api_dag.py
[2025-06-16T10:24:13.955+0000] {processor.py:183} INFO - Processing /opt/airflow/dags/weather_api_dag.py took 3.647 seconds
[2025-06-16T10:24:44.025+0000] {processor.py:161} INFO - Started process (PID=447) to work on /opt/airflow/dags/weather_api_dag.py
[2025-06-16T10:24:44.026+0000] {processor.py:830} INFO - Processing file /opt/airflow/dags/weather_api_dag.py for tasks to queue
[2025-06-16T10:24:44.027+0000] {logging_mixin.py:188} INFO - [2025-06-16T10:24:44.027+0000] {dagbag.py:538} INFO - Filling up the DagBag from /opt/airflow/dags/weather_api_dag.py
[2025-06-16T10:24:47.091+0000] {logging_mixin.py:188} INFO - [2025-06-16T10:24:47.090+0000] {dagbag.py:348} ERROR - Failed to import: /opt/airflow/dags/weather_api_dag.py
Traceback (most recent call last):
  File "/home/airflow/.local/lib/python3.8/site-packages/airflow/models/dagbag.py", line 344, in parse
    loader.exec_module(new_module)
  File "<frozen importlib._bootstrap_external>", line 843, in exec_module
  File "<frozen importlib._bootstrap>", line 219, in _call_with_frames_removed
  File "/opt/airflow/dags/weather_api_dag.py", line 13, in <module>
    from great_expectations.dataset import PandasDataset
ModuleNotFoundError: No module named 'great_expectations.dataset'
[2025-06-16T10:24:47.092+0000] {processor.py:842} WARNING - No viable dags retrieved from /opt/airflow/dags/weather_api_dag.py
[2025-06-16T10:24:47.110+0000] {processor.py:183} INFO - Processing /opt/airflow/dags/weather_api_dag.py took 3.087 seconds
[2025-06-16T10:25:17.266+0000] {processor.py:161} INFO - Started process (PID=479) to work on /opt/airflow/dags/weather_api_dag.py
[2025-06-16T10:25:17.267+0000] {processor.py:830} INFO - Processing file /opt/airflow/dags/weather_api_dag.py for tasks to queue
[2025-06-16T10:25:17.269+0000] {logging_mixin.py:188} INFO - [2025-06-16T10:25:17.269+0000] {dagbag.py:538} INFO - Filling up the DagBag from /opt/airflow/dags/weather_api_dag.py
[2025-06-16T10:25:20.187+0000] {logging_mixin.py:188} INFO - [2025-06-16T10:25:20.186+0000] {dagbag.py:348} ERROR - Failed to import: /opt/airflow/dags/weather_api_dag.py
Traceback (most recent call last):
  File "/home/airflow/.local/lib/python3.8/site-packages/airflow/models/dagbag.py", line 344, in parse
    loader.exec_module(new_module)
  File "<frozen importlib._bootstrap_external>", line 843, in exec_module
  File "<frozen importlib._bootstrap>", line 219, in _call_with_frames_removed
  File "/opt/airflow/dags/weather_api_dag.py", line 13, in <module>
    from great_expectations.dataset import PandasDataset
ModuleNotFoundError: No module named 'great_expectations.dataset'
[2025-06-16T10:25:20.187+0000] {processor.py:842} WARNING - No viable dags retrieved from /opt/airflow/dags/weather_api_dag.py
[2025-06-16T10:25:20.200+0000] {processor.py:183} INFO - Processing /opt/airflow/dags/weather_api_dag.py took 2.936 seconds
[2025-06-16T10:25:50.620+0000] {processor.py:161} INFO - Started process (PID=505) to work on /opt/airflow/dags/weather_api_dag.py
[2025-06-16T10:25:50.621+0000] {processor.py:830} INFO - Processing file /opt/airflow/dags/weather_api_dag.py for tasks to queue
[2025-06-16T10:25:50.623+0000] {logging_mixin.py:188} INFO - [2025-06-16T10:25:50.622+0000] {dagbag.py:538} INFO - Filling up the DagBag from /opt/airflow/dags/weather_api_dag.py
[2025-06-16T10:25:57.039+0000] {logging_mixin.py:188} INFO - [2025-06-16T10:25:57.038+0000] {dagbag.py:348} ERROR - Failed to import: /opt/airflow/dags/weather_api_dag.py
Traceback (most recent call last):
  File "/home/airflow/.local/lib/python3.8/site-packages/airflow/models/dagbag.py", line 344, in parse
    loader.exec_module(new_module)
  File "<frozen importlib._bootstrap_external>", line 843, in exec_module
  File "<frozen importlib._bootstrap>", line 219, in _call_with_frames_removed
  File "/opt/airflow/dags/weather_api_dag.py", line 13, in <module>
    from great_expectations.dataset import PandasDataset
ModuleNotFoundError: No module named 'great_expectations.dataset'
[2025-06-16T10:25:57.040+0000] {processor.py:842} WARNING - No viable dags retrieved from /opt/airflow/dags/weather_api_dag.py
[2025-06-16T10:25:57.056+0000] {processor.py:183} INFO - Processing /opt/airflow/dags/weather_api_dag.py took 6.439 seconds
[2025-06-16T10:26:27.245+0000] {processor.py:161} INFO - Started process (PID=537) to work on /opt/airflow/dags/weather_api_dag.py
[2025-06-16T10:26:27.246+0000] {processor.py:830} INFO - Processing file /opt/airflow/dags/weather_api_dag.py for tasks to queue
[2025-06-16T10:26:27.249+0000] {logging_mixin.py:188} INFO - [2025-06-16T10:26:27.249+0000] {dagbag.py:538} INFO - Filling up the DagBag from /opt/airflow/dags/weather_api_dag.py
[2025-06-16T10:26:31.425+0000] {logging_mixin.py:188} INFO - [2025-06-16T10:26:31.423+0000] {dagbag.py:348} ERROR - Failed to import: /opt/airflow/dags/weather_api_dag.py
Traceback (most recent call last):
  File "/home/airflow/.local/lib/python3.8/site-packages/airflow/models/dagbag.py", line 344, in parse
    loader.exec_module(new_module)
  File "<frozen importlib._bootstrap_external>", line 843, in exec_module
  File "<frozen importlib._bootstrap>", line 219, in _call_with_frames_removed
  File "/opt/airflow/dags/weather_api_dag.py", line 13, in <module>
    from great_expectations.dataset import PandasDataset
ModuleNotFoundError: No module named 'great_expectations.dataset'
[2025-06-16T10:26:31.425+0000] {processor.py:842} WARNING - No viable dags retrieved from /opt/airflow/dags/weather_api_dag.py
[2025-06-16T10:26:31.441+0000] {processor.py:183} INFO - Processing /opt/airflow/dags/weather_api_dag.py took 4.200 seconds
[2025-06-16T10:27:01.874+0000] {processor.py:161} INFO - Started process (PID=570) to work on /opt/airflow/dags/weather_api_dag.py
[2025-06-16T10:27:01.875+0000] {processor.py:830} INFO - Processing file /opt/airflow/dags/weather_api_dag.py for tasks to queue
[2025-06-16T10:27:01.878+0000] {logging_mixin.py:188} INFO - [2025-06-16T10:27:01.878+0000] {dagbag.py:538} INFO - Filling up the DagBag from /opt/airflow/dags/weather_api_dag.py
[2025-06-16T10:27:05.006+0000] {logging_mixin.py:188} INFO - [2025-06-16T10:27:05.005+0000] {dagbag.py:348} ERROR - Failed to import: /opt/airflow/dags/weather_api_dag.py
Traceback (most recent call last):
  File "/home/airflow/.local/lib/python3.8/site-packages/airflow/models/dagbag.py", line 344, in parse
    loader.exec_module(new_module)
  File "<frozen importlib._bootstrap_external>", line 843, in exec_module
  File "<frozen importlib._bootstrap>", line 219, in _call_with_frames_removed
  File "/opt/airflow/dags/weather_api_dag.py", line 13, in <module>
    from great_expectations.dataset import PandasDataset
ModuleNotFoundError: No module named 'great_expectations.dataset'
[2025-06-16T10:27:05.007+0000] {processor.py:842} WARNING - No viable dags retrieved from /opt/airflow/dags/weather_api_dag.py
[2025-06-16T10:27:05.020+0000] {processor.py:183} INFO - Processing /opt/airflow/dags/weather_api_dag.py took 3.153 seconds
[2025-06-16T10:27:35.341+0000] {processor.py:161} INFO - Started process (PID=601) to work on /opt/airflow/dags/weather_api_dag.py
[2025-06-16T10:27:35.345+0000] {processor.py:830} INFO - Processing file /opt/airflow/dags/weather_api_dag.py for tasks to queue
[2025-06-16T10:27:35.347+0000] {logging_mixin.py:188} INFO - [2025-06-16T10:27:35.347+0000] {dagbag.py:538} INFO - Filling up the DagBag from /opt/airflow/dags/weather_api_dag.py
[2025-06-16T10:27:40.056+0000] {logging_mixin.py:188} INFO - [2025-06-16T10:27:40.055+0000] {dagbag.py:348} ERROR - Failed to import: /opt/airflow/dags/weather_api_dag.py
Traceback (most recent call last):
  File "/home/airflow/.local/lib/python3.8/site-packages/airflow/models/dagbag.py", line 344, in parse
    loader.exec_module(new_module)
  File "<frozen importlib._bootstrap_external>", line 843, in exec_module
  File "<frozen importlib._bootstrap>", line 219, in _call_with_frames_removed
  File "/opt/airflow/dags/weather_api_dag.py", line 13, in <module>
    from great_expectations.dataset import PandasDataset
ModuleNotFoundError: No module named 'great_expectations.dataset'
[2025-06-16T10:27:40.056+0000] {processor.py:842} WARNING - No viable dags retrieved from /opt/airflow/dags/weather_api_dag.py
[2025-06-16T10:27:40.069+0000] {processor.py:183} INFO - Processing /opt/airflow/dags/weather_api_dag.py took 4.735 seconds
[2025-06-16T10:28:10.487+0000] {processor.py:161} INFO - Started process (PID=627) to work on /opt/airflow/dags/weather_api_dag.py
[2025-06-16T10:28:10.491+0000] {processor.py:830} INFO - Processing file /opt/airflow/dags/weather_api_dag.py for tasks to queue
[2025-06-16T10:28:10.497+0000] {logging_mixin.py:188} INFO - [2025-06-16T10:28:10.496+0000] {dagbag.py:538} INFO - Filling up the DagBag from /opt/airflow/dags/weather_api_dag.py
[2025-06-16T10:28:13.930+0000] {logging_mixin.py:188} INFO - [2025-06-16T10:28:13.929+0000] {dagbag.py:348} ERROR - Failed to import: /opt/airflow/dags/weather_api_dag.py
Traceback (most recent call last):
  File "/home/airflow/.local/lib/python3.8/site-packages/airflow/models/dagbag.py", line 344, in parse
    loader.exec_module(new_module)
  File "<frozen importlib._bootstrap_external>", line 843, in exec_module
  File "<frozen importlib._bootstrap>", line 219, in _call_with_frames_removed
  File "/opt/airflow/dags/weather_api_dag.py", line 13, in <module>
    from great_expectations.dataset import PandasDataset
ModuleNotFoundError: No module named 'great_expectations.dataset'
[2025-06-16T10:28:13.931+0000] {processor.py:842} WARNING - No viable dags retrieved from /opt/airflow/dags/weather_api_dag.py
[2025-06-16T10:28:13.950+0000] {processor.py:183} INFO - Processing /opt/airflow/dags/weather_api_dag.py took 3.478 seconds
[2025-06-16T10:30:31.043+0000] {processor.py:161} INFO - Started process (PID=57) to work on /opt/airflow/dags/weather_api_dag.py
[2025-06-16T10:30:31.056+0000] {processor.py:830} INFO - Processing file /opt/airflow/dags/weather_api_dag.py for tasks to queue
[2025-06-16T10:30:31.064+0000] {logging_mixin.py:188} INFO - [2025-06-16T10:30:31.063+0000] {dagbag.py:538} INFO - Filling up the DagBag from /opt/airflow/dags/weather_api_dag.py
[2025-06-16T10:30:46.264+0000] {logging_mixin.py:188} INFO - [2025-06-16T10:30:46.262+0000] {dagbag.py:348} ERROR - Failed to import: /opt/airflow/dags/weather_api_dag.py
Traceback (most recent call last):
  File "/home/airflow/.local/lib/python3.8/site-packages/airflow/models/dagbag.py", line 344, in parse
    loader.exec_module(new_module)
  File "<frozen importlib._bootstrap_external>", line 843, in exec_module
  File "<frozen importlib._bootstrap>", line 219, in _call_with_frames_removed
  File "/opt/airflow/dags/weather_api_dag.py", line 13, in <module>
    from great_expectations.dataset import PandasDataset
ModuleNotFoundError: No module named 'great_expectations.dataset'
[2025-06-16T10:30:46.265+0000] {processor.py:842} WARNING - No viable dags retrieved from /opt/airflow/dags/weather_api_dag.py
[2025-06-16T10:30:46.280+0000] {processor.py:183} INFO - Processing /opt/airflow/dags/weather_api_dag.py took 15.247 seconds
[2025-06-16T10:31:16.597+0000] {processor.py:161} INFO - Started process (PID=90) to work on /opt/airflow/dags/weather_api_dag.py
[2025-06-16T10:31:16.598+0000] {processor.py:830} INFO - Processing file /opt/airflow/dags/weather_api_dag.py for tasks to queue
[2025-06-16T10:31:16.600+0000] {logging_mixin.py:188} INFO - [2025-06-16T10:31:16.600+0000] {dagbag.py:538} INFO - Filling up the DagBag from /opt/airflow/dags/weather_api_dag.py
[2025-06-16T10:31:21.452+0000] {logging_mixin.py:188} INFO - [2025-06-16T10:31:21.448+0000] {dagbag.py:348} ERROR - Failed to import: /opt/airflow/dags/weather_api_dag.py
Traceback (most recent call last):
  File "/home/airflow/.local/lib/python3.8/site-packages/airflow/models/dagbag.py", line 344, in parse
    loader.exec_module(new_module)
  File "<frozen importlib._bootstrap_external>", line 843, in exec_module
  File "<frozen importlib._bootstrap>", line 219, in _call_with_frames_removed
  File "/opt/airflow/dags/weather_api_dag.py", line 13, in <module>
    from great_expectations.dataset import PandasDataset
ModuleNotFoundError: No module named 'great_expectations.dataset'
[2025-06-16T10:31:21.453+0000] {processor.py:842} WARNING - No viable dags retrieved from /opt/airflow/dags/weather_api_dag.py
[2025-06-16T10:31:21.487+0000] {processor.py:183} INFO - Processing /opt/airflow/dags/weather_api_dag.py took 4.892 seconds
[2025-06-16T10:31:51.966+0000] {processor.py:161} INFO - Started process (PID=121) to work on /opt/airflow/dags/weather_api_dag.py
[2025-06-16T10:31:51.967+0000] {processor.py:830} INFO - Processing file /opt/airflow/dags/weather_api_dag.py for tasks to queue
[2025-06-16T10:31:51.968+0000] {logging_mixin.py:188} INFO - [2025-06-16T10:31:51.968+0000] {dagbag.py:538} INFO - Filling up the DagBag from /opt/airflow/dags/weather_api_dag.py
[2025-06-16T10:31:55.380+0000] {logging_mixin.py:188} INFO - [2025-06-16T10:31:55.376+0000] {dagbag.py:348} ERROR - Failed to import: /opt/airflow/dags/weather_api_dag.py
Traceback (most recent call last):
  File "/home/airflow/.local/lib/python3.8/site-packages/airflow/models/dagbag.py", line 344, in parse
    loader.exec_module(new_module)
  File "<frozen importlib._bootstrap_external>", line 843, in exec_module
  File "<frozen importlib._bootstrap>", line 219, in _call_with_frames_removed
  File "/opt/airflow/dags/weather_api_dag.py", line 13, in <module>
    from great_expectations.dataset import PandasDataset
ModuleNotFoundError: No module named 'great_expectations.dataset'
[2025-06-16T10:31:55.380+0000] {processor.py:842} WARNING - No viable dags retrieved from /opt/airflow/dags/weather_api_dag.py
[2025-06-16T10:31:55.403+0000] {processor.py:183} INFO - Processing /opt/airflow/dags/weather_api_dag.py took 3.440 seconds
[2025-06-16T10:32:25.625+0000] {processor.py:161} INFO - Started process (PID=152) to work on /opt/airflow/dags/weather_api_dag.py
[2025-06-16T10:32:25.626+0000] {processor.py:830} INFO - Processing file /opt/airflow/dags/weather_api_dag.py for tasks to queue
[2025-06-16T10:32:25.627+0000] {logging_mixin.py:188} INFO - [2025-06-16T10:32:25.627+0000] {dagbag.py:538} INFO - Filling up the DagBag from /opt/airflow/dags/weather_api_dag.py
[2025-06-16T10:32:28.577+0000] {logging_mixin.py:188} INFO - [2025-06-16T10:32:28.576+0000] {dagbag.py:348} ERROR - Failed to import: /opt/airflow/dags/weather_api_dag.py
Traceback (most recent call last):
  File "/home/airflow/.local/lib/python3.8/site-packages/airflow/models/dagbag.py", line 344, in parse
    loader.exec_module(new_module)
  File "<frozen importlib._bootstrap_external>", line 843, in exec_module
  File "<frozen importlib._bootstrap>", line 219, in _call_with_frames_removed
  File "/opt/airflow/dags/weather_api_dag.py", line 13, in <module>
    from great_expectations.dataset import PandasDataset
ModuleNotFoundError: No module named 'great_expectations.dataset'
[2025-06-16T10:32:28.577+0000] {processor.py:842} WARNING - No viable dags retrieved from /opt/airflow/dags/weather_api_dag.py
[2025-06-16T10:32:28.590+0000] {processor.py:183} INFO - Processing /opt/airflow/dags/weather_api_dag.py took 2.968 seconds
[2025-06-16T10:32:58.786+0000] {processor.py:161} INFO - Started process (PID=176) to work on /opt/airflow/dags/weather_api_dag.py
[2025-06-16T10:32:58.787+0000] {processor.py:830} INFO - Processing file /opt/airflow/dags/weather_api_dag.py for tasks to queue
[2025-06-16T10:32:58.790+0000] {logging_mixin.py:188} INFO - [2025-06-16T10:32:58.789+0000] {dagbag.py:538} INFO - Filling up the DagBag from /opt/airflow/dags/weather_api_dag.py
[2025-06-16T10:33:02.977+0000] {logging_mixin.py:188} INFO - [2025-06-16T10:33:02.975+0000] {dagbag.py:348} ERROR - Failed to import: /opt/airflow/dags/weather_api_dag.py
Traceback (most recent call last):
  File "/home/airflow/.local/lib/python3.8/site-packages/airflow/models/dagbag.py", line 344, in parse
    loader.exec_module(new_module)
  File "<frozen importlib._bootstrap_external>", line 843, in exec_module
  File "<frozen importlib._bootstrap>", line 219, in _call_with_frames_removed
  File "/opt/airflow/dags/weather_api_dag.py", line 13, in <module>
    from great_expectations.dataset import PandasDataset
ModuleNotFoundError: No module named 'great_expectations.dataset'
[2025-06-16T10:33:02.981+0000] {processor.py:842} WARNING - No viable dags retrieved from /opt/airflow/dags/weather_api_dag.py
[2025-06-16T10:33:03.005+0000] {processor.py:183} INFO - Processing /opt/airflow/dags/weather_api_dag.py took 4.222 seconds
[2025-06-16T10:33:33.205+0000] {processor.py:161} INFO - Started process (PID=210) to work on /opt/airflow/dags/weather_api_dag.py
[2025-06-16T10:33:33.206+0000] {processor.py:830} INFO - Processing file /opt/airflow/dags/weather_api_dag.py for tasks to queue
[2025-06-16T10:33:33.208+0000] {logging_mixin.py:188} INFO - [2025-06-16T10:33:33.208+0000] {dagbag.py:538} INFO - Filling up the DagBag from /opt/airflow/dags/weather_api_dag.py
[2025-06-16T10:33:39.422+0000] {logging_mixin.py:188} INFO - [2025-06-16T10:33:39.420+0000] {dagbag.py:348} ERROR - Failed to import: /opt/airflow/dags/weather_api_dag.py
Traceback (most recent call last):
  File "/home/airflow/.local/lib/python3.8/site-packages/airflow/models/dagbag.py", line 344, in parse
    loader.exec_module(new_module)
  File "<frozen importlib._bootstrap_external>", line 843, in exec_module
  File "<frozen importlib._bootstrap>", line 219, in _call_with_frames_removed
  File "/opt/airflow/dags/weather_api_dag.py", line 13, in <module>
    from great_expectations.dataset import PandasDataset
ModuleNotFoundError: No module named 'great_expectations.dataset'
[2025-06-16T10:33:39.422+0000] {processor.py:842} WARNING - No viable dags retrieved from /opt/airflow/dags/weather_api_dag.py
[2025-06-16T10:33:39.465+0000] {processor.py:183} INFO - Processing /opt/airflow/dags/weather_api_dag.py took 6.263 seconds
[2025-06-16T10:34:10.429+0000] {processor.py:161} INFO - Started process (PID=242) to work on /opt/airflow/dags/weather_api_dag.py
[2025-06-16T10:34:10.430+0000] {processor.py:830} INFO - Processing file /opt/airflow/dags/weather_api_dag.py for tasks to queue
[2025-06-16T10:34:10.432+0000] {logging_mixin.py:188} INFO - [2025-06-16T10:34:10.431+0000] {dagbag.py:538} INFO - Filling up the DagBag from /opt/airflow/dags/weather_api_dag.py
[2025-06-16T10:34:13.622+0000] {logging_mixin.py:188} INFO - [2025-06-16T10:34:13.621+0000] {dagbag.py:348} ERROR - Failed to import: /opt/airflow/dags/weather_api_dag.py
Traceback (most recent call last):
  File "/home/airflow/.local/lib/python3.8/site-packages/airflow/models/dagbag.py", line 344, in parse
    loader.exec_module(new_module)
  File "<frozen importlib._bootstrap_external>", line 843, in exec_module
  File "<frozen importlib._bootstrap>", line 219, in _call_with_frames_removed
  File "/opt/airflow/dags/weather_api_dag.py", line 13, in <module>
    from great_expectations.dataset import PandasDataset
ModuleNotFoundError: No module named 'great_expectations.dataset'
[2025-06-16T10:34:13.623+0000] {processor.py:842} WARNING - No viable dags retrieved from /opt/airflow/dags/weather_api_dag.py
[2025-06-16T10:34:13.636+0000] {processor.py:183} INFO - Processing /opt/airflow/dags/weather_api_dag.py took 3.209 seconds
[2025-06-16T10:34:43.978+0000] {processor.py:161} INFO - Started process (PID=267) to work on /opt/airflow/dags/weather_api_dag.py
[2025-06-16T10:34:43.979+0000] {processor.py:830} INFO - Processing file /opt/airflow/dags/weather_api_dag.py for tasks to queue
[2025-06-16T10:34:43.982+0000] {logging_mixin.py:188} INFO - [2025-06-16T10:34:43.981+0000] {dagbag.py:538} INFO - Filling up the DagBag from /opt/airflow/dags/weather_api_dag.py
[2025-06-16T10:34:48.480+0000] {logging_mixin.py:188} INFO - [2025-06-16T10:34:48.479+0000] {dagbag.py:348} ERROR - Failed to import: /opt/airflow/dags/weather_api_dag.py
Traceback (most recent call last):
  File "/home/airflow/.local/lib/python3.8/site-packages/airflow/models/dagbag.py", line 344, in parse
    loader.exec_module(new_module)
  File "<frozen importlib._bootstrap_external>", line 843, in exec_module
  File "<frozen importlib._bootstrap>", line 219, in _call_with_frames_removed
  File "/opt/airflow/dags/weather_api_dag.py", line 13, in <module>
    from great_expectations.dataset import PandasDataset
ModuleNotFoundError: No module named 'great_expectations.dataset'
[2025-06-16T10:34:48.481+0000] {processor.py:842} WARNING - No viable dags retrieved from /opt/airflow/dags/weather_api_dag.py
[2025-06-16T10:34:48.499+0000] {processor.py:183} INFO - Processing /opt/airflow/dags/weather_api_dag.py took 4.525 seconds
[2025-06-16T10:35:19.089+0000] {processor.py:161} INFO - Started process (PID=300) to work on /opt/airflow/dags/weather_api_dag.py
[2025-06-16T10:35:19.091+0000] {processor.py:830} INFO - Processing file /opt/airflow/dags/weather_api_dag.py for tasks to queue
[2025-06-16T10:35:19.093+0000] {logging_mixin.py:188} INFO - [2025-06-16T10:35:19.093+0000] {dagbag.py:538} INFO - Filling up the DagBag from /opt/airflow/dags/weather_api_dag.py
[2025-06-16T10:35:22.613+0000] {logging_mixin.py:188} INFO - [2025-06-16T10:35:22.612+0000] {dagbag.py:348} ERROR - Failed to import: /opt/airflow/dags/weather_api_dag.py
Traceback (most recent call last):
  File "/home/airflow/.local/lib/python3.8/site-packages/airflow/models/dagbag.py", line 344, in parse
    loader.exec_module(new_module)
  File "<frozen importlib._bootstrap_external>", line 843, in exec_module
  File "<frozen importlib._bootstrap>", line 219, in _call_with_frames_removed
  File "/opt/airflow/dags/weather_api_dag.py", line 13, in <module>
    from great_expectations.dataset import PandasDataset
ModuleNotFoundError: No module named 'great_expectations.dataset'
[2025-06-16T10:35:22.613+0000] {processor.py:842} WARNING - No viable dags retrieved from /opt/airflow/dags/weather_api_dag.py
[2025-06-16T10:35:22.626+0000] {processor.py:183} INFO - Processing /opt/airflow/dags/weather_api_dag.py took 3.540 seconds
[2025-06-16T10:35:52.984+0000] {processor.py:161} INFO - Started process (PID=330) to work on /opt/airflow/dags/weather_api_dag.py
[2025-06-16T10:35:52.985+0000] {processor.py:830} INFO - Processing file /opt/airflow/dags/weather_api_dag.py for tasks to queue
[2025-06-16T10:35:52.991+0000] {logging_mixin.py:188} INFO - [2025-06-16T10:35:52.991+0000] {dagbag.py:538} INFO - Filling up the DagBag from /opt/airflow/dags/weather_api_dag.py
[2025-06-16T10:35:57.194+0000] {logging_mixin.py:188} INFO - [2025-06-16T10:35:57.192+0000] {dagbag.py:348} ERROR - Failed to import: /opt/airflow/dags/weather_api_dag.py
Traceback (most recent call last):
  File "/home/airflow/.local/lib/python3.8/site-packages/airflow/models/dagbag.py", line 344, in parse
    loader.exec_module(new_module)
  File "<frozen importlib._bootstrap_external>", line 843, in exec_module
  File "<frozen importlib._bootstrap>", line 219, in _call_with_frames_removed
  File "/opt/airflow/dags/weather_api_dag.py", line 13, in <module>
    from great_expectations.dataset import PandasDataset
ModuleNotFoundError: No module named 'great_expectations.dataset'
[2025-06-16T10:35:57.194+0000] {processor.py:842} WARNING - No viable dags retrieved from /opt/airflow/dags/weather_api_dag.py
[2025-06-16T10:35:57.252+0000] {processor.py:183} INFO - Processing /opt/airflow/dags/weather_api_dag.py took 4.275 seconds
[2025-06-16T10:36:27.610+0000] {processor.py:161} INFO - Started process (PID=355) to work on /opt/airflow/dags/weather_api_dag.py
[2025-06-16T10:36:27.611+0000] {processor.py:830} INFO - Processing file /opt/airflow/dags/weather_api_dag.py for tasks to queue
[2025-06-16T10:36:27.614+0000] {logging_mixin.py:188} INFO - [2025-06-16T10:36:27.614+0000] {dagbag.py:538} INFO - Filling up the DagBag from /opt/airflow/dags/weather_api_dag.py
[2025-06-16T10:36:30.652+0000] {logging_mixin.py:188} INFO - [2025-06-16T10:36:30.651+0000] {dagbag.py:348} ERROR - Failed to import: /opt/airflow/dags/weather_api_dag.py
Traceback (most recent call last):
  File "/home/airflow/.local/lib/python3.8/site-packages/airflow/models/dagbag.py", line 344, in parse
    loader.exec_module(new_module)
  File "<frozen importlib._bootstrap_external>", line 843, in exec_module
  File "<frozen importlib._bootstrap>", line 219, in _call_with_frames_removed
  File "/opt/airflow/dags/weather_api_dag.py", line 13, in <module>
    from great_expectations.dataset import PandasDataset
ModuleNotFoundError: No module named 'great_expectations.dataset'
[2025-06-16T10:36:30.653+0000] {processor.py:842} WARNING - No viable dags retrieved from /opt/airflow/dags/weather_api_dag.py
[2025-06-16T10:36:30.666+0000] {processor.py:183} INFO - Processing /opt/airflow/dags/weather_api_dag.py took 3.060 seconds
[2025-06-16T10:38:25.325+0000] {processor.py:161} INFO - Started process (PID=47) to work on /opt/airflow/dags/weather_api_dag.py
[2025-06-16T10:38:25.328+0000] {processor.py:830} INFO - Processing file /opt/airflow/dags/weather_api_dag.py for tasks to queue
[2025-06-16T10:38:25.332+0000] {logging_mixin.py:188} INFO - [2025-06-16T10:38:25.331+0000] {dagbag.py:538} INFO - Filling up the DagBag from /opt/airflow/dags/weather_api_dag.py
[2025-06-16T10:38:29.748+0000] {logging_mixin.py:188} INFO - [2025-06-16T10:38:29.747+0000] {dagbag.py:348} ERROR - Failed to import: /opt/airflow/dags/weather_api_dag.py
Traceback (most recent call last):
  File "/home/airflow/.local/lib/python3.8/site-packages/airflow/models/dagbag.py", line 344, in parse
    loader.exec_module(new_module)
  File "<frozen importlib._bootstrap_external>", line 843, in exec_module
  File "<frozen importlib._bootstrap>", line 219, in _call_with_frames_removed
  File "/opt/airflow/dags/weather_api_dag.py", line 13, in <module>
    from great_expectations.dataset import PandasDataset
ModuleNotFoundError: No module named 'great_expectations.dataset'
[2025-06-16T10:38:29.748+0000] {processor.py:842} WARNING - No viable dags retrieved from /opt/airflow/dags/weather_api_dag.py
[2025-06-16T10:38:29.761+0000] {processor.py:183} INFO - Processing /opt/airflow/dags/weather_api_dag.py took 4.442 seconds
[2025-06-16T10:39:00.108+0000] {processor.py:161} INFO - Started process (PID=80) to work on /opt/airflow/dags/weather_api_dag.py
[2025-06-16T10:39:00.109+0000] {processor.py:830} INFO - Processing file /opt/airflow/dags/weather_api_dag.py for tasks to queue
[2025-06-16T10:39:00.112+0000] {logging_mixin.py:188} INFO - [2025-06-16T10:39:00.112+0000] {dagbag.py:538} INFO - Filling up the DagBag from /opt/airflow/dags/weather_api_dag.py
[2025-06-16T10:39:03.421+0000] {logging_mixin.py:188} INFO - [2025-06-16T10:39:03.418+0000] {dagbag.py:348} ERROR - Failed to import: /opt/airflow/dags/weather_api_dag.py
Traceback (most recent call last):
  File "/home/airflow/.local/lib/python3.8/site-packages/airflow/models/dagbag.py", line 344, in parse
    loader.exec_module(new_module)
  File "<frozen importlib._bootstrap_external>", line 843, in exec_module
  File "<frozen importlib._bootstrap>", line 219, in _call_with_frames_removed
  File "/opt/airflow/dags/weather_api_dag.py", line 13, in <module>
    from great_expectations.dataset import PandasDataset
ModuleNotFoundError: No module named 'great_expectations.dataset'
[2025-06-16T10:39:03.422+0000] {processor.py:842} WARNING - No viable dags retrieved from /opt/airflow/dags/weather_api_dag.py
[2025-06-16T10:39:03.437+0000] {processor.py:183} INFO - Processing /opt/airflow/dags/weather_api_dag.py took 3.332 seconds
[2025-06-16T10:39:33.556+0000] {processor.py:161} INFO - Started process (PID=104) to work on /opt/airflow/dags/weather_api_dag.py
[2025-06-16T10:39:33.557+0000] {processor.py:830} INFO - Processing file /opt/airflow/dags/weather_api_dag.py for tasks to queue
[2025-06-16T10:39:33.558+0000] {logging_mixin.py:188} INFO - [2025-06-16T10:39:33.558+0000] {dagbag.py:538} INFO - Filling up the DagBag from /opt/airflow/dags/weather_api_dag.py
[2025-06-16T10:39:38.046+0000] {logging_mixin.py:188} INFO - [2025-06-16T10:39:38.043+0000] {dagbag.py:348} ERROR - Failed to import: /opt/airflow/dags/weather_api_dag.py
Traceback (most recent call last):
  File "/home/airflow/.local/lib/python3.8/site-packages/airflow/models/dagbag.py", line 344, in parse
    loader.exec_module(new_module)
  File "<frozen importlib._bootstrap_external>", line 843, in exec_module
  File "<frozen importlib._bootstrap>", line 219, in _call_with_frames_removed
  File "/opt/airflow/dags/weather_api_dag.py", line 13, in <module>
    from great_expectations.dataset import PandasDataset
ModuleNotFoundError: No module named 'great_expectations.dataset'
[2025-06-16T10:39:38.047+0000] {processor.py:842} WARNING - No viable dags retrieved from /opt/airflow/dags/weather_api_dag.py
[2025-06-16T10:39:38.079+0000] {processor.py:183} INFO - Processing /opt/airflow/dags/weather_api_dag.py took 4.526 seconds
[2025-06-16T10:40:08.381+0000] {processor.py:161} INFO - Started process (PID=135) to work on /opt/airflow/dags/weather_api_dag.py
[2025-06-16T10:40:08.382+0000] {processor.py:830} INFO - Processing file /opt/airflow/dags/weather_api_dag.py for tasks to queue
[2025-06-16T10:40:08.383+0000] {logging_mixin.py:188} INFO - [2025-06-16T10:40:08.383+0000] {dagbag.py:538} INFO - Filling up the DagBag from /opt/airflow/dags/weather_api_dag.py
[2025-06-16T10:40:11.352+0000] {logging_mixin.py:188} INFO - [2025-06-16T10:40:11.351+0000] {dagbag.py:348} ERROR - Failed to import: /opt/airflow/dags/weather_api_dag.py
Traceback (most recent call last):
  File "/home/airflow/.local/lib/python3.8/site-packages/airflow/models/dagbag.py", line 344, in parse
    loader.exec_module(new_module)
  File "<frozen importlib._bootstrap_external>", line 843, in exec_module
  File "<frozen importlib._bootstrap>", line 219, in _call_with_frames_removed
  File "/opt/airflow/dags/weather_api_dag.py", line 13, in <module>
    from great_expectations.dataset import PandasDataset
ModuleNotFoundError: No module named 'great_expectations.dataset'
[2025-06-16T10:40:11.352+0000] {processor.py:842} WARNING - No viable dags retrieved from /opt/airflow/dags/weather_api_dag.py
[2025-06-16T10:40:11.365+0000] {processor.py:183} INFO - Processing /opt/airflow/dags/weather_api_dag.py took 2.987 seconds
[2025-06-16T10:40:41.699+0000] {processor.py:161} INFO - Started process (PID=167) to work on /opt/airflow/dags/weather_api_dag.py
[2025-06-16T10:40:41.700+0000] {processor.py:830} INFO - Processing file /opt/airflow/dags/weather_api_dag.py for tasks to queue
[2025-06-16T10:40:41.702+0000] {logging_mixin.py:188} INFO - [2025-06-16T10:40:41.702+0000] {dagbag.py:538} INFO - Filling up the DagBag from /opt/airflow/dags/weather_api_dag.py
[2025-06-16T10:40:46.024+0000] {logging_mixin.py:188} INFO - [2025-06-16T10:40:46.023+0000] {dagbag.py:348} ERROR - Failed to import: /opt/airflow/dags/weather_api_dag.py
Traceback (most recent call last):
  File "/home/airflow/.local/lib/python3.8/site-packages/airflow/models/dagbag.py", line 344, in parse
    loader.exec_module(new_module)
  File "<frozen importlib._bootstrap_external>", line 843, in exec_module
  File "<frozen importlib._bootstrap>", line 219, in _call_with_frames_removed
  File "/opt/airflow/dags/weather_api_dag.py", line 13, in <module>
    from great_expectations.dataset import PandasDataset
ModuleNotFoundError: No module named 'great_expectations.dataset'
[2025-06-16T10:40:46.025+0000] {processor.py:842} WARNING - No viable dags retrieved from /opt/airflow/dags/weather_api_dag.py
[2025-06-16T10:40:46.037+0000] {processor.py:183} INFO - Processing /opt/airflow/dags/weather_api_dag.py took 4.342 seconds
[2025-06-16T10:41:16.097+0000] {processor.py:161} INFO - Started process (PID=191) to work on /opt/airflow/dags/weather_api_dag.py
[2025-06-16T10:41:16.098+0000] {processor.py:830} INFO - Processing file /opt/airflow/dags/weather_api_dag.py for tasks to queue
[2025-06-16T10:41:16.100+0000] {logging_mixin.py:188} INFO - [2025-06-16T10:41:16.099+0000] {dagbag.py:538} INFO - Filling up the DagBag from /opt/airflow/dags/weather_api_dag.py
[2025-06-16T10:41:18.819+0000] {logging_mixin.py:188} INFO - [2025-06-16T10:41:18.818+0000] {dagbag.py:348} ERROR - Failed to import: /opt/airflow/dags/weather_api_dag.py
Traceback (most recent call last):
  File "/home/airflow/.local/lib/python3.8/site-packages/airflow/models/dagbag.py", line 344, in parse
    loader.exec_module(new_module)
  File "<frozen importlib._bootstrap_external>", line 843, in exec_module
  File "<frozen importlib._bootstrap>", line 219, in _call_with_frames_removed
  File "/opt/airflow/dags/weather_api_dag.py", line 13, in <module>
    from great_expectations.dataset import PandasDataset
ModuleNotFoundError: No module named 'great_expectations.dataset'
[2025-06-16T10:41:18.820+0000] {processor.py:842} WARNING - No viable dags retrieved from /opt/airflow/dags/weather_api_dag.py
[2025-06-16T10:41:18.838+0000] {processor.py:183} INFO - Processing /opt/airflow/dags/weather_api_dag.py took 2.743 seconds
[2025-06-16T10:41:49.002+0000] {processor.py:161} INFO - Started process (PID=223) to work on /opt/airflow/dags/weather_api_dag.py
[2025-06-16T10:41:49.003+0000] {processor.py:830} INFO - Processing file /opt/airflow/dags/weather_api_dag.py for tasks to queue
[2025-06-16T10:41:49.005+0000] {logging_mixin.py:188} INFO - [2025-06-16T10:41:49.004+0000] {dagbag.py:538} INFO - Filling up the DagBag from /opt/airflow/dags/weather_api_dag.py
[2025-06-16T10:41:51.866+0000] {logging_mixin.py:188} INFO - [2025-06-16T10:41:51.865+0000] {dagbag.py:348} ERROR - Failed to import: /opt/airflow/dags/weather_api_dag.py
Traceback (most recent call last):
  File "/home/airflow/.local/lib/python3.8/site-packages/airflow/models/dagbag.py", line 344, in parse
    loader.exec_module(new_module)
  File "<frozen importlib._bootstrap_external>", line 843, in exec_module
  File "<frozen importlib._bootstrap>", line 219, in _call_with_frames_removed
  File "/opt/airflow/dags/weather_api_dag.py", line 13, in <module>
    from great_expectations.dataset import PandasDataset
ModuleNotFoundError: No module named 'great_expectations.dataset'
[2025-06-16T10:41:51.866+0000] {processor.py:842} WARNING - No viable dags retrieved from /opt/airflow/dags/weather_api_dag.py
[2025-06-16T10:41:51.879+0000] {processor.py:183} INFO - Processing /opt/airflow/dags/weather_api_dag.py took 2.879 seconds
