[2025-06-16T10:17:12.993+0000] {processor.py:161} INFO - Started process (PID=55) to work on /opt/airflow/dags/weather_dbt_dag.py
[2025-06-16T10:17:12.994+0000] {processor.py:830} INFO - Processing file /opt/airflow/dags/weather_dbt_dag.py for tasks to queue
[2025-06-16T10:17:12.998+0000] {logging_mixin.py:188} INFO - [2025-06-16T10:17:12.998+0000] {dagbag.py:538} INFO - Filling up the DagBag from /opt/airflow/dags/weather_dbt_dag.py
[2025-06-16T10:17:13.477+0000] {logging_mixin.py:188} INFO - [2025-06-16T10:17:13.477+0000] {configuration.py:1046} WARNING - section/key [openlineage/namespace] not found in config
[2025-06-16T10:17:19.781+0000] {logging_mixin.py:188} INFO - [2025-06-16T10:17:19.776+0000] {dagbag.py:348} ERROR - Failed to import: /opt/airflow/dags/weather_dbt_dag.py
Traceback (most recent call last):
  File "/home/airflow/.local/lib/python3.8/site-packages/airflow/models/dagbag.py", line 344, in parse
    loader.exec_module(new_module)
  File "<frozen importlib._bootstrap_external>", line 843, in exec_module
  File "<frozen importlib._bootstrap>", line 219, in _call_with_frames_removed
  File "/opt/airflow/dags/weather_dbt_dag.py", line 16, in <module>
    weather_dbt_dag = DbtDag(
  File "/home/airflow/.local/lib/python3.8/site-packages/cosmos/airflow/dag.py", line 25, in __init__
    DbtToAirflowConverter.__init__(self, *args, **specific_kwargs(**kwargs))
  File "/home/airflow/.local/lib/python3.8/site-packages/cosmos/converter.py", line 209, in __init__
    project_config.validate_project()
  File "/home/airflow/.local/lib/python3.8/site-packages/cosmos/config.py", line 193, in validate_project
    raise CosmosValueError(f"Could not find {name} at {path}")
cosmos.exceptions.CosmosValueError: Could not find dbt_project.yml at /opt/airflow/dbt/weather/dbt_project.yml
[2025-06-16T10:17:19.782+0000] {logging_mixin.py:188} WARNING - [2025-06-16T10:17:19.776+0000] {dagbag.py:348} ERROR - (astronomer-cosmos) - Failed to import: /opt/airflow/dags/weather_dbt_dag.py
Traceback (most recent call last):
  File "/home/airflow/.local/lib/python3.8/site-packages/airflow/models/dagbag.py", line 344, in parse
    loader.exec_module(new_module)
  File "<frozen importlib._bootstrap_external>", line 843, in exec_module
  File "<frozen importlib._bootstrap>", line 219, in _call_with_frames_removed
  File "/opt/airflow/dags/weather_dbt_dag.py", line 16, in <module>
    weather_dbt_dag = DbtDag(
  File "/home/airflow/.local/lib/python3.8/site-packages/cosmos/airflow/dag.py", line 25, in __init__
    DbtToAirflowConverter.__init__(self, *args, **specific_kwargs(**kwargs))
  File "/home/airflow/.local/lib/python3.8/site-packages/cosmos/converter.py", line 209, in __init__
    project_config.validate_project()
  File "/home/airflow/.local/lib/python3.8/site-packages/cosmos/config.py", line 193, in validate_project
    raise CosmosValueError(f"Could not find {name} at {path}")
cosmos.exceptions.CosmosValueError: Could not find dbt_project.yml at /opt/airflow/dbt/weather/dbt_project.yml
[2025-06-16T10:17:19.785+0000] {processor.py:842} WARNING - No viable dags retrieved from /opt/airflow/dags/weather_dbt_dag.py
[2025-06-16T10:17:19.817+0000] {processor.py:183} INFO - Processing /opt/airflow/dags/weather_dbt_dag.py took 6.831 seconds
[2025-06-16T10:17:50.150+0000] {processor.py:161} INFO - Started process (PID=88) to work on /opt/airflow/dags/weather_dbt_dag.py
[2025-06-16T10:17:50.151+0000] {processor.py:830} INFO - Processing file /opt/airflow/dags/weather_dbt_dag.py for tasks to queue
[2025-06-16T10:17:50.153+0000] {logging_mixin.py:188} INFO - [2025-06-16T10:17:50.153+0000] {dagbag.py:538} INFO - Filling up the DagBag from /opt/airflow/dags/weather_dbt_dag.py
[2025-06-16T10:17:50.200+0000] {logging_mixin.py:188} INFO - [2025-06-16T10:17:50.199+0000] {configuration.py:1046} WARNING - section/key [openlineage/namespace] not found in config
[2025-06-16T10:17:50.558+0000] {logging_mixin.py:188} INFO - [2025-06-16T10:17:50.555+0000] {dagbag.py:348} ERROR - Failed to import: /opt/airflow/dags/weather_dbt_dag.py
Traceback (most recent call last):
  File "/home/airflow/.local/lib/python3.8/site-packages/airflow/models/dagbag.py", line 344, in parse
    loader.exec_module(new_module)
  File "<frozen importlib._bootstrap_external>", line 843, in exec_module
  File "<frozen importlib._bootstrap>", line 219, in _call_with_frames_removed
  File "/opt/airflow/dags/weather_dbt_dag.py", line 16, in <module>
    weather_dbt_dag = DbtDag(
  File "/home/airflow/.local/lib/python3.8/site-packages/cosmos/airflow/dag.py", line 25, in __init__
    DbtToAirflowConverter.__init__(self, *args, **specific_kwargs(**kwargs))
  File "/home/airflow/.local/lib/python3.8/site-packages/cosmos/converter.py", line 209, in __init__
    project_config.validate_project()
  File "/home/airflow/.local/lib/python3.8/site-packages/cosmos/config.py", line 193, in validate_project
    raise CosmosValueError(f"Could not find {name} at {path}")
cosmos.exceptions.CosmosValueError: Could not find dbt_project.yml at /opt/airflow/dbt/weather/dbt_project.yml
[2025-06-16T10:17:50.559+0000] {logging_mixin.py:188} WARNING - [2025-06-16T10:17:50.555+0000] {dagbag.py:348} ERROR - (astronomer-cosmos) - Failed to import: /opt/airflow/dags/weather_dbt_dag.py
Traceback (most recent call last):
  File "/home/airflow/.local/lib/python3.8/site-packages/airflow/models/dagbag.py", line 344, in parse
    loader.exec_module(new_module)
  File "<frozen importlib._bootstrap_external>", line 843, in exec_module
  File "<frozen importlib._bootstrap>", line 219, in _call_with_frames_removed
  File "/opt/airflow/dags/weather_dbt_dag.py", line 16, in <module>
    weather_dbt_dag = DbtDag(
  File "/home/airflow/.local/lib/python3.8/site-packages/cosmos/airflow/dag.py", line 25, in __init__
    DbtToAirflowConverter.__init__(self, *args, **specific_kwargs(**kwargs))
  File "/home/airflow/.local/lib/python3.8/site-packages/cosmos/converter.py", line 209, in __init__
    project_config.validate_project()
  File "/home/airflow/.local/lib/python3.8/site-packages/cosmos/config.py", line 193, in validate_project
    raise CosmosValueError(f"Could not find {name} at {path}")
cosmos.exceptions.CosmosValueError: Could not find dbt_project.yml at /opt/airflow/dbt/weather/dbt_project.yml
[2025-06-16T10:17:50.559+0000] {processor.py:842} WARNING - No viable dags retrieved from /opt/airflow/dags/weather_dbt_dag.py
[2025-06-16T10:17:50.580+0000] {processor.py:183} INFO - Processing /opt/airflow/dags/weather_dbt_dag.py took 0.432 seconds
[2025-06-16T10:18:21.006+0000] {processor.py:161} INFO - Started process (PID=112) to work on /opt/airflow/dags/weather_dbt_dag.py
[2025-06-16T10:18:21.007+0000] {processor.py:830} INFO - Processing file /opt/airflow/dags/weather_dbt_dag.py for tasks to queue
[2025-06-16T10:18:21.010+0000] {logging_mixin.py:188} INFO - [2025-06-16T10:18:21.010+0000] {dagbag.py:538} INFO - Filling up the DagBag from /opt/airflow/dags/weather_dbt_dag.py
[2025-06-16T10:18:21.069+0000] {logging_mixin.py:188} INFO - [2025-06-16T10:18:21.069+0000] {configuration.py:1046} WARNING - section/key [openlineage/namespace] not found in config
[2025-06-16T10:18:21.437+0000] {logging_mixin.py:188} INFO - [2025-06-16T10:18:21.436+0000] {dagbag.py:348} ERROR - Failed to import: /opt/airflow/dags/weather_dbt_dag.py
Traceback (most recent call last):
  File "/home/airflow/.local/lib/python3.8/site-packages/airflow/models/dagbag.py", line 344, in parse
    loader.exec_module(new_module)
  File "<frozen importlib._bootstrap_external>", line 843, in exec_module
  File "<frozen importlib._bootstrap>", line 219, in _call_with_frames_removed
  File "/opt/airflow/dags/weather_dbt_dag.py", line 16, in <module>
    weather_dbt_dag = DbtDag(
  File "/home/airflow/.local/lib/python3.8/site-packages/cosmos/airflow/dag.py", line 25, in __init__
    DbtToAirflowConverter.__init__(self, *args, **specific_kwargs(**kwargs))
  File "/home/airflow/.local/lib/python3.8/site-packages/cosmos/converter.py", line 209, in __init__
    project_config.validate_project()
  File "/home/airflow/.local/lib/python3.8/site-packages/cosmos/config.py", line 193, in validate_project
    raise CosmosValueError(f"Could not find {name} at {path}")
cosmos.exceptions.CosmosValueError: Could not find dbt_project.yml at /opt/airflow/dbt/weather/dbt_project.yml
[2025-06-16T10:18:21.438+0000] {logging_mixin.py:188} WARNING - [2025-06-16T10:18:21.436+0000] {dagbag.py:348} ERROR - (astronomer-cosmos) - Failed to import: /opt/airflow/dags/weather_dbt_dag.py
Traceback (most recent call last):
  File "/home/airflow/.local/lib/python3.8/site-packages/airflow/models/dagbag.py", line 344, in parse
    loader.exec_module(new_module)
  File "<frozen importlib._bootstrap_external>", line 843, in exec_module
  File "<frozen importlib._bootstrap>", line 219, in _call_with_frames_removed
  File "/opt/airflow/dags/weather_dbt_dag.py", line 16, in <module>
    weather_dbt_dag = DbtDag(
  File "/home/airflow/.local/lib/python3.8/site-packages/cosmos/airflow/dag.py", line 25, in __init__
    DbtToAirflowConverter.__init__(self, *args, **specific_kwargs(**kwargs))
  File "/home/airflow/.local/lib/python3.8/site-packages/cosmos/converter.py", line 209, in __init__
    project_config.validate_project()
  File "/home/airflow/.local/lib/python3.8/site-packages/cosmos/config.py", line 193, in validate_project
    raise CosmosValueError(f"Could not find {name} at {path}")
cosmos.exceptions.CosmosValueError: Could not find dbt_project.yml at /opt/airflow/dbt/weather/dbt_project.yml
[2025-06-16T10:18:21.438+0000] {processor.py:842} WARNING - No viable dags retrieved from /opt/airflow/dags/weather_dbt_dag.py
[2025-06-16T10:18:21.451+0000] {processor.py:183} INFO - Processing /opt/airflow/dags/weather_dbt_dag.py took 0.448 seconds
[2025-06-16T10:18:52.334+0000] {processor.py:161} INFO - Started process (PID=144) to work on /opt/airflow/dags/weather_dbt_dag.py
[2025-06-16T10:18:52.335+0000] {processor.py:830} INFO - Processing file /opt/airflow/dags/weather_dbt_dag.py for tasks to queue
[2025-06-16T10:18:52.338+0000] {logging_mixin.py:188} INFO - [2025-06-16T10:18:52.337+0000] {dagbag.py:538} INFO - Filling up the DagBag from /opt/airflow/dags/weather_dbt_dag.py
[2025-06-16T10:18:52.396+0000] {logging_mixin.py:188} INFO - [2025-06-16T10:18:52.396+0000] {configuration.py:1046} WARNING - section/key [openlineage/namespace] not found in config
[2025-06-16T10:18:52.717+0000] {logging_mixin.py:188} INFO - [2025-06-16T10:18:52.716+0000] {dagbag.py:348} ERROR - Failed to import: /opt/airflow/dags/weather_dbt_dag.py
Traceback (most recent call last):
  File "/home/airflow/.local/lib/python3.8/site-packages/airflow/models/dagbag.py", line 344, in parse
    loader.exec_module(new_module)
  File "<frozen importlib._bootstrap_external>", line 843, in exec_module
  File "<frozen importlib._bootstrap>", line 219, in _call_with_frames_removed
  File "/opt/airflow/dags/weather_dbt_dag.py", line 16, in <module>
    weather_dbt_dag = DbtDag(
  File "/home/airflow/.local/lib/python3.8/site-packages/cosmos/airflow/dag.py", line 25, in __init__
    DbtToAirflowConverter.__init__(self, *args, **specific_kwargs(**kwargs))
  File "/home/airflow/.local/lib/python3.8/site-packages/cosmos/converter.py", line 209, in __init__
    project_config.validate_project()
  File "/home/airflow/.local/lib/python3.8/site-packages/cosmos/config.py", line 193, in validate_project
    raise CosmosValueError(f"Could not find {name} at {path}")
cosmos.exceptions.CosmosValueError: Could not find dbt_project.yml at /opt/airflow/dbt/weather/dbt_project.yml
[2025-06-16T10:18:52.717+0000] {logging_mixin.py:188} WARNING - [2025-06-16T10:18:52.716+0000] {dagbag.py:348} ERROR - (astronomer-cosmos) - Failed to import: /opt/airflow/dags/weather_dbt_dag.py
Traceback (most recent call last):
  File "/home/airflow/.local/lib/python3.8/site-packages/airflow/models/dagbag.py", line 344, in parse
    loader.exec_module(new_module)
  File "<frozen importlib._bootstrap_external>", line 843, in exec_module
  File "<frozen importlib._bootstrap>", line 219, in _call_with_frames_removed
  File "/opt/airflow/dags/weather_dbt_dag.py", line 16, in <module>
    weather_dbt_dag = DbtDag(
  File "/home/airflow/.local/lib/python3.8/site-packages/cosmos/airflow/dag.py", line 25, in __init__
    DbtToAirflowConverter.__init__(self, *args, **specific_kwargs(**kwargs))
  File "/home/airflow/.local/lib/python3.8/site-packages/cosmos/converter.py", line 209, in __init__
    project_config.validate_project()
  File "/home/airflow/.local/lib/python3.8/site-packages/cosmos/config.py", line 193, in validate_project
    raise CosmosValueError(f"Could not find {name} at {path}")
cosmos.exceptions.CosmosValueError: Could not find dbt_project.yml at /opt/airflow/dbt/weather/dbt_project.yml
[2025-06-16T10:18:52.717+0000] {processor.py:842} WARNING - No viable dags retrieved from /opt/airflow/dags/weather_dbt_dag.py
[2025-06-16T10:18:52.731+0000] {processor.py:183} INFO - Processing /opt/airflow/dags/weather_dbt_dag.py took 0.402 seconds
[2025-06-16T10:19:23.559+0000] {processor.py:161} INFO - Started process (PID=168) to work on /opt/airflow/dags/weather_dbt_dag.py
[2025-06-16T10:19:23.561+0000] {processor.py:830} INFO - Processing file /opt/airflow/dags/weather_dbt_dag.py for tasks to queue
[2025-06-16T10:19:23.564+0000] {logging_mixin.py:188} INFO - [2025-06-16T10:19:23.564+0000] {dagbag.py:538} INFO - Filling up the DagBag from /opt/airflow/dags/weather_dbt_dag.py
[2025-06-16T10:19:23.620+0000] {logging_mixin.py:188} INFO - [2025-06-16T10:19:23.620+0000] {configuration.py:1046} WARNING - section/key [openlineage/namespace] not found in config
[2025-06-16T10:19:23.967+0000] {logging_mixin.py:188} INFO - [2025-06-16T10:19:23.966+0000] {dagbag.py:348} ERROR - Failed to import: /opt/airflow/dags/weather_dbt_dag.py
Traceback (most recent call last):
  File "/home/airflow/.local/lib/python3.8/site-packages/airflow/models/dagbag.py", line 344, in parse
    loader.exec_module(new_module)
  File "<frozen importlib._bootstrap_external>", line 843, in exec_module
  File "<frozen importlib._bootstrap>", line 219, in _call_with_frames_removed
  File "/opt/airflow/dags/weather_dbt_dag.py", line 16, in <module>
    weather_dbt_dag = DbtDag(
  File "/home/airflow/.local/lib/python3.8/site-packages/cosmos/airflow/dag.py", line 25, in __init__
    DbtToAirflowConverter.__init__(self, *args, **specific_kwargs(**kwargs))
  File "/home/airflow/.local/lib/python3.8/site-packages/cosmos/converter.py", line 209, in __init__
    project_config.validate_project()
  File "/home/airflow/.local/lib/python3.8/site-packages/cosmos/config.py", line 193, in validate_project
    raise CosmosValueError(f"Could not find {name} at {path}")
cosmos.exceptions.CosmosValueError: Could not find dbt_project.yml at /opt/airflow/dbt/weather/dbt_project.yml
[2025-06-16T10:19:23.968+0000] {logging_mixin.py:188} WARNING - [2025-06-16T10:19:23.966+0000] {dagbag.py:348} ERROR - (astronomer-cosmos) - Failed to import: /opt/airflow/dags/weather_dbt_dag.py
Traceback (most recent call last):
  File "/home/airflow/.local/lib/python3.8/site-packages/airflow/models/dagbag.py", line 344, in parse
    loader.exec_module(new_module)
  File "<frozen importlib._bootstrap_external>", line 843, in exec_module
  File "<frozen importlib._bootstrap>", line 219, in _call_with_frames_removed
  File "/opt/airflow/dags/weather_dbt_dag.py", line 16, in <module>
    weather_dbt_dag = DbtDag(
  File "/home/airflow/.local/lib/python3.8/site-packages/cosmos/airflow/dag.py", line 25, in __init__
    DbtToAirflowConverter.__init__(self, *args, **specific_kwargs(**kwargs))
  File "/home/airflow/.local/lib/python3.8/site-packages/cosmos/converter.py", line 209, in __init__
    project_config.validate_project()
  File "/home/airflow/.local/lib/python3.8/site-packages/cosmos/config.py", line 193, in validate_project
    raise CosmosValueError(f"Could not find {name} at {path}")
cosmos.exceptions.CosmosValueError: Could not find dbt_project.yml at /opt/airflow/dbt/weather/dbt_project.yml
[2025-06-16T10:19:23.969+0000] {processor.py:842} WARNING - No viable dags retrieved from /opt/airflow/dags/weather_dbt_dag.py
[2025-06-16T10:19:23.988+0000] {processor.py:183} INFO - Processing /opt/airflow/dags/weather_dbt_dag.py took 0.438 seconds
[2025-06-16T10:19:54.257+0000] {processor.py:161} INFO - Started process (PID=198) to work on /opt/airflow/dags/weather_dbt_dag.py
[2025-06-16T10:19:54.265+0000] {processor.py:830} INFO - Processing file /opt/airflow/dags/weather_dbt_dag.py for tasks to queue
[2025-06-16T10:19:54.271+0000] {logging_mixin.py:188} INFO - [2025-06-16T10:19:54.271+0000] {dagbag.py:538} INFO - Filling up the DagBag from /opt/airflow/dags/weather_dbt_dag.py
[2025-06-16T10:19:54.404+0000] {logging_mixin.py:188} INFO - [2025-06-16T10:19:54.403+0000] {configuration.py:1046} WARNING - section/key [openlineage/namespace] not found in config
[2025-06-16T10:19:55.429+0000] {logging_mixin.py:188} INFO - [2025-06-16T10:19:55.428+0000] {dagbag.py:348} ERROR - Failed to import: /opt/airflow/dags/weather_dbt_dag.py
Traceback (most recent call last):
  File "/home/airflow/.local/lib/python3.8/site-packages/airflow/models/dagbag.py", line 344, in parse
    loader.exec_module(new_module)
  File "<frozen importlib._bootstrap_external>", line 843, in exec_module
  File "<frozen importlib._bootstrap>", line 219, in _call_with_frames_removed
  File "/opt/airflow/dags/weather_dbt_dag.py", line 16, in <module>
    weather_dbt_dag = DbtDag(
  File "/home/airflow/.local/lib/python3.8/site-packages/cosmos/airflow/dag.py", line 25, in __init__
    DbtToAirflowConverter.__init__(self, *args, **specific_kwargs(**kwargs))
  File "/home/airflow/.local/lib/python3.8/site-packages/cosmos/converter.py", line 209, in __init__
    project_config.validate_project()
  File "/home/airflow/.local/lib/python3.8/site-packages/cosmos/config.py", line 193, in validate_project
    raise CosmosValueError(f"Could not find {name} at {path}")
cosmos.exceptions.CosmosValueError: Could not find dbt_project.yml at /opt/airflow/dbt/weather/dbt_project.yml
[2025-06-16T10:19:55.430+0000] {logging_mixin.py:188} WARNING - [2025-06-16T10:19:55.428+0000] {dagbag.py:348} ERROR - (astronomer-cosmos) - Failed to import: /opt/airflow/dags/weather_dbt_dag.py
Traceback (most recent call last):
  File "/home/airflow/.local/lib/python3.8/site-packages/airflow/models/dagbag.py", line 344, in parse
    loader.exec_module(new_module)
  File "<frozen importlib._bootstrap_external>", line 843, in exec_module
  File "<frozen importlib._bootstrap>", line 219, in _call_with_frames_removed
  File "/opt/airflow/dags/weather_dbt_dag.py", line 16, in <module>
    weather_dbt_dag = DbtDag(
  File "/home/airflow/.local/lib/python3.8/site-packages/cosmos/airflow/dag.py", line 25, in __init__
    DbtToAirflowConverter.__init__(self, *args, **specific_kwargs(**kwargs))
  File "/home/airflow/.local/lib/python3.8/site-packages/cosmos/converter.py", line 209, in __init__
    project_config.validate_project()
  File "/home/airflow/.local/lib/python3.8/site-packages/cosmos/config.py", line 193, in validate_project
    raise CosmosValueError(f"Could not find {name} at {path}")
cosmos.exceptions.CosmosValueError: Could not find dbt_project.yml at /opt/airflow/dbt/weather/dbt_project.yml
[2025-06-16T10:19:55.431+0000] {processor.py:842} WARNING - No viable dags retrieved from /opt/airflow/dags/weather_dbt_dag.py
[2025-06-16T10:19:55.450+0000] {processor.py:183} INFO - Processing /opt/airflow/dags/weather_dbt_dag.py took 1.202 seconds
[2025-06-16T10:20:25.542+0000] {processor.py:161} INFO - Started process (PID=222) to work on /opt/airflow/dags/weather_dbt_dag.py
[2025-06-16T10:20:25.543+0000] {processor.py:830} INFO - Processing file /opt/airflow/dags/weather_dbt_dag.py for tasks to queue
[2025-06-16T10:20:25.545+0000] {logging_mixin.py:188} INFO - [2025-06-16T10:20:25.545+0000] {dagbag.py:538} INFO - Filling up the DagBag from /opt/airflow/dags/weather_dbt_dag.py
[2025-06-16T10:20:25.585+0000] {logging_mixin.py:188} INFO - [2025-06-16T10:20:25.585+0000] {configuration.py:1046} WARNING - section/key [openlineage/namespace] not found in config
[2025-06-16T10:20:25.911+0000] {logging_mixin.py:188} INFO - [2025-06-16T10:20:25.910+0000] {dagbag.py:348} ERROR - Failed to import: /opt/airflow/dags/weather_dbt_dag.py
Traceback (most recent call last):
  File "/home/airflow/.local/lib/python3.8/site-packages/airflow/models/dagbag.py", line 344, in parse
    loader.exec_module(new_module)
  File "<frozen importlib._bootstrap_external>", line 843, in exec_module
  File "<frozen importlib._bootstrap>", line 219, in _call_with_frames_removed
  File "/opt/airflow/dags/weather_dbt_dag.py", line 16, in <module>
    weather_dbt_dag = DbtDag(
  File "/home/airflow/.local/lib/python3.8/site-packages/cosmos/airflow/dag.py", line 25, in __init__
    DbtToAirflowConverter.__init__(self, *args, **specific_kwargs(**kwargs))
  File "/home/airflow/.local/lib/python3.8/site-packages/cosmos/converter.py", line 209, in __init__
    project_config.validate_project()
  File "/home/airflow/.local/lib/python3.8/site-packages/cosmos/config.py", line 193, in validate_project
    raise CosmosValueError(f"Could not find {name} at {path}")
cosmos.exceptions.CosmosValueError: Could not find dbt_project.yml at /opt/airflow/dbt/weather/dbt_project.yml
[2025-06-16T10:20:25.911+0000] {logging_mixin.py:188} WARNING - [2025-06-16T10:20:25.910+0000] {dagbag.py:348} ERROR - (astronomer-cosmos) - Failed to import: /opt/airflow/dags/weather_dbt_dag.py
Traceback (most recent call last):
  File "/home/airflow/.local/lib/python3.8/site-packages/airflow/models/dagbag.py", line 344, in parse
    loader.exec_module(new_module)
  File "<frozen importlib._bootstrap_external>", line 843, in exec_module
  File "<frozen importlib._bootstrap>", line 219, in _call_with_frames_removed
  File "/opt/airflow/dags/weather_dbt_dag.py", line 16, in <module>
    weather_dbt_dag = DbtDag(
  File "/home/airflow/.local/lib/python3.8/site-packages/cosmos/airflow/dag.py", line 25, in __init__
    DbtToAirflowConverter.__init__(self, *args, **specific_kwargs(**kwargs))
  File "/home/airflow/.local/lib/python3.8/site-packages/cosmos/converter.py", line 209, in __init__
    project_config.validate_project()
  File "/home/airflow/.local/lib/python3.8/site-packages/cosmos/config.py", line 193, in validate_project
    raise CosmosValueError(f"Could not find {name} at {path}")
cosmos.exceptions.CosmosValueError: Could not find dbt_project.yml at /opt/airflow/dbt/weather/dbt_project.yml
[2025-06-16T10:20:25.912+0000] {processor.py:842} WARNING - No viable dags retrieved from /opt/airflow/dags/weather_dbt_dag.py
[2025-06-16T10:20:25.925+0000] {processor.py:183} INFO - Processing /opt/airflow/dags/weather_dbt_dag.py took 0.385 seconds
[2025-06-16T10:20:56.813+0000] {processor.py:161} INFO - Started process (PID=246) to work on /opt/airflow/dags/weather_dbt_dag.py
[2025-06-16T10:20:56.814+0000] {processor.py:830} INFO - Processing file /opt/airflow/dags/weather_dbt_dag.py for tasks to queue
[2025-06-16T10:20:56.819+0000] {logging_mixin.py:188} INFO - [2025-06-16T10:20:56.819+0000] {dagbag.py:538} INFO - Filling up the DagBag from /opt/airflow/dags/weather_dbt_dag.py
[2025-06-16T10:20:56.878+0000] {logging_mixin.py:188} INFO - [2025-06-16T10:20:56.878+0000] {configuration.py:1046} WARNING - section/key [openlineage/namespace] not found in config
[2025-06-16T10:20:57.242+0000] {logging_mixin.py:188} INFO - [2025-06-16T10:20:57.240+0000] {dagbag.py:348} ERROR - Failed to import: /opt/airflow/dags/weather_dbt_dag.py
Traceback (most recent call last):
  File "/home/airflow/.local/lib/python3.8/site-packages/airflow/models/dagbag.py", line 344, in parse
    loader.exec_module(new_module)
  File "<frozen importlib._bootstrap_external>", line 843, in exec_module
  File "<frozen importlib._bootstrap>", line 219, in _call_with_frames_removed
  File "/opt/airflow/dags/weather_dbt_dag.py", line 16, in <module>
    weather_dbt_dag = DbtDag(
  File "/home/airflow/.local/lib/python3.8/site-packages/cosmos/airflow/dag.py", line 25, in __init__
    DbtToAirflowConverter.__init__(self, *args, **specific_kwargs(**kwargs))
  File "/home/airflow/.local/lib/python3.8/site-packages/cosmos/converter.py", line 209, in __init__
    project_config.validate_project()
  File "/home/airflow/.local/lib/python3.8/site-packages/cosmos/config.py", line 193, in validate_project
    raise CosmosValueError(f"Could not find {name} at {path}")
cosmos.exceptions.CosmosValueError: Could not find dbt_project.yml at /opt/airflow/dbt/weather/dbt_project.yml
[2025-06-16T10:20:57.242+0000] {logging_mixin.py:188} WARNING - [2025-06-16T10:20:57.240+0000] {dagbag.py:348} ERROR - (astronomer-cosmos) - Failed to import: /opt/airflow/dags/weather_dbt_dag.py
Traceback (most recent call last):
  File "/home/airflow/.local/lib/python3.8/site-packages/airflow/models/dagbag.py", line 344, in parse
    loader.exec_module(new_module)
  File "<frozen importlib._bootstrap_external>", line 843, in exec_module
  File "<frozen importlib._bootstrap>", line 219, in _call_with_frames_removed
  File "/opt/airflow/dags/weather_dbt_dag.py", line 16, in <module>
    weather_dbt_dag = DbtDag(
  File "/home/airflow/.local/lib/python3.8/site-packages/cosmos/airflow/dag.py", line 25, in __init__
    DbtToAirflowConverter.__init__(self, *args, **specific_kwargs(**kwargs))
  File "/home/airflow/.local/lib/python3.8/site-packages/cosmos/converter.py", line 209, in __init__
    project_config.validate_project()
  File "/home/airflow/.local/lib/python3.8/site-packages/cosmos/config.py", line 193, in validate_project
    raise CosmosValueError(f"Could not find {name} at {path}")
cosmos.exceptions.CosmosValueError: Could not find dbt_project.yml at /opt/airflow/dbt/weather/dbt_project.yml
[2025-06-16T10:20:57.243+0000] {processor.py:842} WARNING - No viable dags retrieved from /opt/airflow/dags/weather_dbt_dag.py
[2025-06-16T10:20:57.260+0000] {processor.py:183} INFO - Processing /opt/airflow/dags/weather_dbt_dag.py took 0.451 seconds
[2025-06-16T10:21:27.348+0000] {processor.py:161} INFO - Started process (PID=278) to work on /opt/airflow/dags/weather_dbt_dag.py
[2025-06-16T10:21:27.349+0000] {processor.py:830} INFO - Processing file /opt/airflow/dags/weather_dbt_dag.py for tasks to queue
[2025-06-16T10:21:27.352+0000] {logging_mixin.py:188} INFO - [2025-06-16T10:21:27.352+0000] {dagbag.py:538} INFO - Filling up the DagBag from /opt/airflow/dags/weather_dbt_dag.py
[2025-06-16T10:21:27.429+0000] {logging_mixin.py:188} INFO - [2025-06-16T10:21:27.428+0000] {configuration.py:1046} WARNING - section/key [openlineage/namespace] not found in config
[2025-06-16T10:21:27.913+0000] {logging_mixin.py:188} INFO - [2025-06-16T10:21:27.912+0000] {dagbag.py:348} ERROR - Failed to import: /opt/airflow/dags/weather_dbt_dag.py
Traceback (most recent call last):
  File "/home/airflow/.local/lib/python3.8/site-packages/airflow/models/dagbag.py", line 344, in parse
    loader.exec_module(new_module)
  File "<frozen importlib._bootstrap_external>", line 843, in exec_module
  File "<frozen importlib._bootstrap>", line 219, in _call_with_frames_removed
  File "/opt/airflow/dags/weather_dbt_dag.py", line 16, in <module>
    weather_dbt_dag = DbtDag(
  File "/home/airflow/.local/lib/python3.8/site-packages/cosmos/airflow/dag.py", line 25, in __init__
    DbtToAirflowConverter.__init__(self, *args, **specific_kwargs(**kwargs))
  File "/home/airflow/.local/lib/python3.8/site-packages/cosmos/converter.py", line 209, in __init__
    project_config.validate_project()
  File "/home/airflow/.local/lib/python3.8/site-packages/cosmos/config.py", line 193, in validate_project
    raise CosmosValueError(f"Could not find {name} at {path}")
cosmos.exceptions.CosmosValueError: Could not find dbt_project.yml at /opt/airflow/dbt/weather/dbt_project.yml
[2025-06-16T10:21:27.913+0000] {logging_mixin.py:188} WARNING - [2025-06-16T10:21:27.912+0000] {dagbag.py:348} ERROR - (astronomer-cosmos) - Failed to import: /opt/airflow/dags/weather_dbt_dag.py
Traceback (most recent call last):
  File "/home/airflow/.local/lib/python3.8/site-packages/airflow/models/dagbag.py", line 344, in parse
    loader.exec_module(new_module)
  File "<frozen importlib._bootstrap_external>", line 843, in exec_module
  File "<frozen importlib._bootstrap>", line 219, in _call_with_frames_removed
  File "/opt/airflow/dags/weather_dbt_dag.py", line 16, in <module>
    weather_dbt_dag = DbtDag(
  File "/home/airflow/.local/lib/python3.8/site-packages/cosmos/airflow/dag.py", line 25, in __init__
    DbtToAirflowConverter.__init__(self, *args, **specific_kwargs(**kwargs))
  File "/home/airflow/.local/lib/python3.8/site-packages/cosmos/converter.py", line 209, in __init__
    project_config.validate_project()
  File "/home/airflow/.local/lib/python3.8/site-packages/cosmos/config.py", line 193, in validate_project
    raise CosmosValueError(f"Could not find {name} at {path}")
cosmos.exceptions.CosmosValueError: Could not find dbt_project.yml at /opt/airflow/dbt/weather/dbt_project.yml
[2025-06-16T10:21:27.913+0000] {processor.py:842} WARNING - No viable dags retrieved from /opt/airflow/dags/weather_dbt_dag.py
[2025-06-16T10:21:27.927+0000] {processor.py:183} INFO - Processing /opt/airflow/dags/weather_dbt_dag.py took 0.582 seconds
[2025-06-16T10:21:58.696+0000] {processor.py:161} INFO - Started process (PID=301) to work on /opt/airflow/dags/weather_dbt_dag.py
[2025-06-16T10:21:58.697+0000] {processor.py:830} INFO - Processing file /opt/airflow/dags/weather_dbt_dag.py for tasks to queue
[2025-06-16T10:21:58.699+0000] {logging_mixin.py:188} INFO - [2025-06-16T10:21:58.699+0000] {dagbag.py:538} INFO - Filling up the DagBag from /opt/airflow/dags/weather_dbt_dag.py
[2025-06-16T10:21:58.779+0000] {logging_mixin.py:188} INFO - [2025-06-16T10:21:58.779+0000] {configuration.py:1046} WARNING - section/key [openlineage/namespace] not found in config
[2025-06-16T10:21:59.284+0000] {logging_mixin.py:188} INFO - [2025-06-16T10:21:59.283+0000] {dagbag.py:348} ERROR - Failed to import: /opt/airflow/dags/weather_dbt_dag.py
Traceback (most recent call last):
  File "/home/airflow/.local/lib/python3.8/site-packages/airflow/models/dagbag.py", line 344, in parse
    loader.exec_module(new_module)
  File "<frozen importlib._bootstrap_external>", line 843, in exec_module
  File "<frozen importlib._bootstrap>", line 219, in _call_with_frames_removed
  File "/opt/airflow/dags/weather_dbt_dag.py", line 16, in <module>
    weather_dbt_dag = DbtDag(
  File "/home/airflow/.local/lib/python3.8/site-packages/cosmos/airflow/dag.py", line 25, in __init__
    DbtToAirflowConverter.__init__(self, *args, **specific_kwargs(**kwargs))
  File "/home/airflow/.local/lib/python3.8/site-packages/cosmos/converter.py", line 209, in __init__
    project_config.validate_project()
  File "/home/airflow/.local/lib/python3.8/site-packages/cosmos/config.py", line 193, in validate_project
    raise CosmosValueError(f"Could not find {name} at {path}")
cosmos.exceptions.CosmosValueError: Could not find dbt_project.yml at /opt/airflow/dbt/weather/dbt_project.yml
[2025-06-16T10:21:59.285+0000] {logging_mixin.py:188} WARNING - [2025-06-16T10:21:59.283+0000] {dagbag.py:348} ERROR - (astronomer-cosmos) - Failed to import: /opt/airflow/dags/weather_dbt_dag.py
Traceback (most recent call last):
  File "/home/airflow/.local/lib/python3.8/site-packages/airflow/models/dagbag.py", line 344, in parse
    loader.exec_module(new_module)
  File "<frozen importlib._bootstrap_external>", line 843, in exec_module
  File "<frozen importlib._bootstrap>", line 219, in _call_with_frames_removed
  File "/opt/airflow/dags/weather_dbt_dag.py", line 16, in <module>
    weather_dbt_dag = DbtDag(
  File "/home/airflow/.local/lib/python3.8/site-packages/cosmos/airflow/dag.py", line 25, in __init__
    DbtToAirflowConverter.__init__(self, *args, **specific_kwargs(**kwargs))
  File "/home/airflow/.local/lib/python3.8/site-packages/cosmos/converter.py", line 209, in __init__
    project_config.validate_project()
  File "/home/airflow/.local/lib/python3.8/site-packages/cosmos/config.py", line 193, in validate_project
    raise CosmosValueError(f"Could not find {name} at {path}")
cosmos.exceptions.CosmosValueError: Could not find dbt_project.yml at /opt/airflow/dbt/weather/dbt_project.yml
[2025-06-16T10:21:59.286+0000] {processor.py:842} WARNING - No viable dags retrieved from /opt/airflow/dags/weather_dbt_dag.py
[2025-06-16T10:21:59.326+0000] {processor.py:183} INFO - Processing /opt/airflow/dags/weather_dbt_dag.py took 0.634 seconds
[2025-06-16T10:22:30.099+0000] {processor.py:161} INFO - Started process (PID=330) to work on /opt/airflow/dags/weather_dbt_dag.py
[2025-06-16T10:22:30.100+0000] {processor.py:830} INFO - Processing file /opt/airflow/dags/weather_dbt_dag.py for tasks to queue
[2025-06-16T10:22:30.102+0000] {logging_mixin.py:188} INFO - [2025-06-16T10:22:30.102+0000] {dagbag.py:538} INFO - Filling up the DagBag from /opt/airflow/dags/weather_dbt_dag.py
[2025-06-16T10:22:30.211+0000] {logging_mixin.py:188} INFO - [2025-06-16T10:22:30.207+0000] {configuration.py:1046} WARNING - section/key [openlineage/namespace] not found in config
[2025-06-16T10:22:30.814+0000] {logging_mixin.py:188} INFO - [2025-06-16T10:22:30.813+0000] {dagbag.py:348} ERROR - Failed to import: /opt/airflow/dags/weather_dbt_dag.py
Traceback (most recent call last):
  File "/home/airflow/.local/lib/python3.8/site-packages/airflow/models/dagbag.py", line 344, in parse
    loader.exec_module(new_module)
  File "<frozen importlib._bootstrap_external>", line 843, in exec_module
  File "<frozen importlib._bootstrap>", line 219, in _call_with_frames_removed
  File "/opt/airflow/dags/weather_dbt_dag.py", line 16, in <module>
    weather_dbt_dag = DbtDag(
  File "/home/airflow/.local/lib/python3.8/site-packages/cosmos/airflow/dag.py", line 25, in __init__
    DbtToAirflowConverter.__init__(self, *args, **specific_kwargs(**kwargs))
  File "/home/airflow/.local/lib/python3.8/site-packages/cosmos/converter.py", line 209, in __init__
    project_config.validate_project()
  File "/home/airflow/.local/lib/python3.8/site-packages/cosmos/config.py", line 193, in validate_project
    raise CosmosValueError(f"Could not find {name} at {path}")
cosmos.exceptions.CosmosValueError: Could not find dbt_project.yml at /opt/airflow/dbt/weather/dbt_project.yml
[2025-06-16T10:22:30.815+0000] {logging_mixin.py:188} WARNING - [2025-06-16T10:22:30.813+0000] {dagbag.py:348} ERROR - (astronomer-cosmos) - Failed to import: /opt/airflow/dags/weather_dbt_dag.py
Traceback (most recent call last):
  File "/home/airflow/.local/lib/python3.8/site-packages/airflow/models/dagbag.py", line 344, in parse
    loader.exec_module(new_module)
  File "<frozen importlib._bootstrap_external>", line 843, in exec_module
  File "<frozen importlib._bootstrap>", line 219, in _call_with_frames_removed
  File "/opt/airflow/dags/weather_dbt_dag.py", line 16, in <module>
    weather_dbt_dag = DbtDag(
  File "/home/airflow/.local/lib/python3.8/site-packages/cosmos/airflow/dag.py", line 25, in __init__
    DbtToAirflowConverter.__init__(self, *args, **specific_kwargs(**kwargs))
  File "/home/airflow/.local/lib/python3.8/site-packages/cosmos/converter.py", line 209, in __init__
    project_config.validate_project()
  File "/home/airflow/.local/lib/python3.8/site-packages/cosmos/config.py", line 193, in validate_project
    raise CosmosValueError(f"Could not find {name} at {path}")
cosmos.exceptions.CosmosValueError: Could not find dbt_project.yml at /opt/airflow/dbt/weather/dbt_project.yml
[2025-06-16T10:22:30.815+0000] {processor.py:842} WARNING - No viable dags retrieved from /opt/airflow/dags/weather_dbt_dag.py
[2025-06-16T10:22:30.828+0000] {processor.py:183} INFO - Processing /opt/airflow/dags/weather_dbt_dag.py took 0.733 seconds
[2025-06-16T10:23:01.644+0000] {processor.py:161} INFO - Started process (PID=354) to work on /opt/airflow/dags/weather_dbt_dag.py
[2025-06-16T10:23:01.644+0000] {processor.py:830} INFO - Processing file /opt/airflow/dags/weather_dbt_dag.py for tasks to queue
[2025-06-16T10:23:01.647+0000] {logging_mixin.py:188} INFO - [2025-06-16T10:23:01.646+0000] {dagbag.py:538} INFO - Filling up the DagBag from /opt/airflow/dags/weather_dbt_dag.py
[2025-06-16T10:23:01.695+0000] {logging_mixin.py:188} INFO - [2025-06-16T10:23:01.695+0000] {configuration.py:1046} WARNING - section/key [openlineage/namespace] not found in config
[2025-06-16T10:23:02.039+0000] {logging_mixin.py:188} INFO - [2025-06-16T10:23:02.038+0000] {dagbag.py:348} ERROR - Failed to import: /opt/airflow/dags/weather_dbt_dag.py
Traceback (most recent call last):
  File "/home/airflow/.local/lib/python3.8/site-packages/airflow/models/dagbag.py", line 344, in parse
    loader.exec_module(new_module)
  File "<frozen importlib._bootstrap_external>", line 843, in exec_module
  File "<frozen importlib._bootstrap>", line 219, in _call_with_frames_removed
  File "/opt/airflow/dags/weather_dbt_dag.py", line 16, in <module>
    weather_dbt_dag = DbtDag(
  File "/home/airflow/.local/lib/python3.8/site-packages/cosmos/airflow/dag.py", line 25, in __init__
    DbtToAirflowConverter.__init__(self, *args, **specific_kwargs(**kwargs))
  File "/home/airflow/.local/lib/python3.8/site-packages/cosmos/converter.py", line 209, in __init__
    project_config.validate_project()
  File "/home/airflow/.local/lib/python3.8/site-packages/cosmos/config.py", line 193, in validate_project
    raise CosmosValueError(f"Could not find {name} at {path}")
cosmos.exceptions.CosmosValueError: Could not find dbt_project.yml at /opt/airflow/dbt/weather/dbt_project.yml
[2025-06-16T10:23:02.040+0000] {logging_mixin.py:188} WARNING - [2025-06-16T10:23:02.038+0000] {dagbag.py:348} ERROR - (astronomer-cosmos) - Failed to import: /opt/airflow/dags/weather_dbt_dag.py
Traceback (most recent call last):
  File "/home/airflow/.local/lib/python3.8/site-packages/airflow/models/dagbag.py", line 344, in parse
    loader.exec_module(new_module)
  File "<frozen importlib._bootstrap_external>", line 843, in exec_module
  File "<frozen importlib._bootstrap>", line 219, in _call_with_frames_removed
  File "/opt/airflow/dags/weather_dbt_dag.py", line 16, in <module>
    weather_dbt_dag = DbtDag(
  File "/home/airflow/.local/lib/python3.8/site-packages/cosmos/airflow/dag.py", line 25, in __init__
    DbtToAirflowConverter.__init__(self, *args, **specific_kwargs(**kwargs))
  File "/home/airflow/.local/lib/python3.8/site-packages/cosmos/converter.py", line 209, in __init__
    project_config.validate_project()
  File "/home/airflow/.local/lib/python3.8/site-packages/cosmos/config.py", line 193, in validate_project
    raise CosmosValueError(f"Could not find {name} at {path}")
cosmos.exceptions.CosmosValueError: Could not find dbt_project.yml at /opt/airflow/dbt/weather/dbt_project.yml
[2025-06-16T10:23:02.040+0000] {processor.py:842} WARNING - No viable dags retrieved from /opt/airflow/dags/weather_dbt_dag.py
[2025-06-16T10:23:02.053+0000] {processor.py:183} INFO - Processing /opt/airflow/dags/weather_dbt_dag.py took 0.412 seconds
[2025-06-16T10:23:32.512+0000] {processor.py:161} INFO - Started process (PID=386) to work on /opt/airflow/dags/weather_dbt_dag.py
[2025-06-16T10:23:32.512+0000] {processor.py:830} INFO - Processing file /opt/airflow/dags/weather_dbt_dag.py for tasks to queue
[2025-06-16T10:23:32.516+0000] {logging_mixin.py:188} INFO - [2025-06-16T10:23:32.515+0000] {dagbag.py:538} INFO - Filling up the DagBag from /opt/airflow/dags/weather_dbt_dag.py
[2025-06-16T10:23:32.578+0000] {logging_mixin.py:188} INFO - [2025-06-16T10:23:32.577+0000] {configuration.py:1046} WARNING - section/key [openlineage/namespace] not found in config
[2025-06-16T10:23:33.335+0000] {logging_mixin.py:188} INFO - [2025-06-16T10:23:33.333+0000] {dagbag.py:348} ERROR - Failed to import: /opt/airflow/dags/weather_dbt_dag.py
Traceback (most recent call last):
  File "/home/airflow/.local/lib/python3.8/site-packages/airflow/models/dagbag.py", line 344, in parse
    loader.exec_module(new_module)
  File "<frozen importlib._bootstrap_external>", line 843, in exec_module
  File "<frozen importlib._bootstrap>", line 219, in _call_with_frames_removed
  File "/opt/airflow/dags/weather_dbt_dag.py", line 16, in <module>
    weather_dbt_dag = DbtDag(
  File "/home/airflow/.local/lib/python3.8/site-packages/cosmos/airflow/dag.py", line 25, in __init__
    DbtToAirflowConverter.__init__(self, *args, **specific_kwargs(**kwargs))
  File "/home/airflow/.local/lib/python3.8/site-packages/cosmos/converter.py", line 209, in __init__
    project_config.validate_project()
  File "/home/airflow/.local/lib/python3.8/site-packages/cosmos/config.py", line 193, in validate_project
    raise CosmosValueError(f"Could not find {name} at {path}")
cosmos.exceptions.CosmosValueError: Could not find dbt_project.yml at /opt/airflow/dbt/weather/dbt_project.yml
[2025-06-16T10:23:33.337+0000] {logging_mixin.py:188} WARNING - [2025-06-16T10:23:33.333+0000] {dagbag.py:348} ERROR - (astronomer-cosmos) - Failed to import: /opt/airflow/dags/weather_dbt_dag.py
Traceback (most recent call last):
  File "/home/airflow/.local/lib/python3.8/site-packages/airflow/models/dagbag.py", line 344, in parse
    loader.exec_module(new_module)
  File "<frozen importlib._bootstrap_external>", line 843, in exec_module
  File "<frozen importlib._bootstrap>", line 219, in _call_with_frames_removed
  File "/opt/airflow/dags/weather_dbt_dag.py", line 16, in <module>
    weather_dbt_dag = DbtDag(
  File "/home/airflow/.local/lib/python3.8/site-packages/cosmos/airflow/dag.py", line 25, in __init__
    DbtToAirflowConverter.__init__(self, *args, **specific_kwargs(**kwargs))
  File "/home/airflow/.local/lib/python3.8/site-packages/cosmos/converter.py", line 209, in __init__
    project_config.validate_project()
  File "/home/airflow/.local/lib/python3.8/site-packages/cosmos/config.py", line 193, in validate_project
    raise CosmosValueError(f"Could not find {name} at {path}")
cosmos.exceptions.CosmosValueError: Could not find dbt_project.yml at /opt/airflow/dbt/weather/dbt_project.yml
[2025-06-16T10:23:33.339+0000] {processor.py:842} WARNING - No viable dags retrieved from /opt/airflow/dags/weather_dbt_dag.py
[2025-06-16T10:23:33.367+0000] {processor.py:183} INFO - Processing /opt/airflow/dags/weather_dbt_dag.py took 0.861 seconds
[2025-06-16T10:24:03.649+0000] {processor.py:161} INFO - Started process (PID=412) to work on /opt/airflow/dags/weather_dbt_dag.py
[2025-06-16T10:24:03.650+0000] {processor.py:830} INFO - Processing file /opt/airflow/dags/weather_dbt_dag.py for tasks to queue
[2025-06-16T10:24:03.652+0000] {logging_mixin.py:188} INFO - [2025-06-16T10:24:03.652+0000] {dagbag.py:538} INFO - Filling up the DagBag from /opt/airflow/dags/weather_dbt_dag.py
[2025-06-16T10:24:03.709+0000] {logging_mixin.py:188} INFO - [2025-06-16T10:24:03.709+0000] {configuration.py:1046} WARNING - section/key [openlineage/namespace] not found in config
[2025-06-16T10:24:04.214+0000] {logging_mixin.py:188} INFO - [2025-06-16T10:24:04.213+0000] {dagbag.py:348} ERROR - Failed to import: /opt/airflow/dags/weather_dbt_dag.py
Traceback (most recent call last):
  File "/home/airflow/.local/lib/python3.8/site-packages/airflow/models/dagbag.py", line 344, in parse
    loader.exec_module(new_module)
  File "<frozen importlib._bootstrap_external>", line 843, in exec_module
  File "<frozen importlib._bootstrap>", line 219, in _call_with_frames_removed
  File "/opt/airflow/dags/weather_dbt_dag.py", line 16, in <module>
    weather_dbt_dag = DbtDag(
  File "/home/airflow/.local/lib/python3.8/site-packages/cosmos/airflow/dag.py", line 25, in __init__
    DbtToAirflowConverter.__init__(self, *args, **specific_kwargs(**kwargs))
  File "/home/airflow/.local/lib/python3.8/site-packages/cosmos/converter.py", line 209, in __init__
    project_config.validate_project()
  File "/home/airflow/.local/lib/python3.8/site-packages/cosmos/config.py", line 193, in validate_project
    raise CosmosValueError(f"Could not find {name} at {path}")
cosmos.exceptions.CosmosValueError: Could not find dbt_project.yml at /opt/airflow/dbt/weather/dbt_project.yml
[2025-06-16T10:24:04.214+0000] {logging_mixin.py:188} WARNING - [2025-06-16T10:24:04.213+0000] {dagbag.py:348} ERROR - (astronomer-cosmos) - Failed to import: /opt/airflow/dags/weather_dbt_dag.py
Traceback (most recent call last):
  File "/home/airflow/.local/lib/python3.8/site-packages/airflow/models/dagbag.py", line 344, in parse
    loader.exec_module(new_module)
  File "<frozen importlib._bootstrap_external>", line 843, in exec_module
  File "<frozen importlib._bootstrap>", line 219, in _call_with_frames_removed
  File "/opt/airflow/dags/weather_dbt_dag.py", line 16, in <module>
    weather_dbt_dag = DbtDag(
  File "/home/airflow/.local/lib/python3.8/site-packages/cosmos/airflow/dag.py", line 25, in __init__
    DbtToAirflowConverter.__init__(self, *args, **specific_kwargs(**kwargs))
  File "/home/airflow/.local/lib/python3.8/site-packages/cosmos/converter.py", line 209, in __init__
    project_config.validate_project()
  File "/home/airflow/.local/lib/python3.8/site-packages/cosmos/config.py", line 193, in validate_project
    raise CosmosValueError(f"Could not find {name} at {path}")
cosmos.exceptions.CosmosValueError: Could not find dbt_project.yml at /opt/airflow/dbt/weather/dbt_project.yml
[2025-06-16T10:24:04.215+0000] {processor.py:842} WARNING - No viable dags retrieved from /opt/airflow/dags/weather_dbt_dag.py
[2025-06-16T10:24:04.228+0000] {processor.py:183} INFO - Processing /opt/airflow/dags/weather_dbt_dag.py took 0.582 seconds
[2025-06-16T10:24:34.351+0000] {processor.py:161} INFO - Started process (PID=438) to work on /opt/airflow/dags/weather_dbt_dag.py
[2025-06-16T10:24:34.351+0000] {processor.py:830} INFO - Processing file /opt/airflow/dags/weather_dbt_dag.py for tasks to queue
[2025-06-16T10:24:34.353+0000] {logging_mixin.py:188} INFO - [2025-06-16T10:24:34.353+0000] {dagbag.py:538} INFO - Filling up the DagBag from /opt/airflow/dags/weather_dbt_dag.py
[2025-06-16T10:24:34.396+0000] {logging_mixin.py:188} INFO - [2025-06-16T10:24:34.396+0000] {configuration.py:1046} WARNING - section/key [openlineage/namespace] not found in config
[2025-06-16T10:24:34.950+0000] {logging_mixin.py:188} INFO - [2025-06-16T10:24:34.949+0000] {dagbag.py:348} ERROR - Failed to import: /opt/airflow/dags/weather_dbt_dag.py
Traceback (most recent call last):
  File "/home/airflow/.local/lib/python3.8/site-packages/airflow/models/dagbag.py", line 344, in parse
    loader.exec_module(new_module)
  File "<frozen importlib._bootstrap_external>", line 843, in exec_module
  File "<frozen importlib._bootstrap>", line 219, in _call_with_frames_removed
  File "/opt/airflow/dags/weather_dbt_dag.py", line 16, in <module>
    weather_dbt_dag = DbtDag(
  File "/home/airflow/.local/lib/python3.8/site-packages/cosmos/airflow/dag.py", line 25, in __init__
    DbtToAirflowConverter.__init__(self, *args, **specific_kwargs(**kwargs))
  File "/home/airflow/.local/lib/python3.8/site-packages/cosmos/converter.py", line 209, in __init__
    project_config.validate_project()
  File "/home/airflow/.local/lib/python3.8/site-packages/cosmos/config.py", line 193, in validate_project
    raise CosmosValueError(f"Could not find {name} at {path}")
cosmos.exceptions.CosmosValueError: Could not find dbt_project.yml at /opt/airflow/dbt/weather/dbt_project.yml
[2025-06-16T10:24:34.951+0000] {logging_mixin.py:188} WARNING - [2025-06-16T10:24:34.949+0000] {dagbag.py:348} ERROR - (astronomer-cosmos) - Failed to import: /opt/airflow/dags/weather_dbt_dag.py
Traceback (most recent call last):
  File "/home/airflow/.local/lib/python3.8/site-packages/airflow/models/dagbag.py", line 344, in parse
    loader.exec_module(new_module)
  File "<frozen importlib._bootstrap_external>", line 843, in exec_module
  File "<frozen importlib._bootstrap>", line 219, in _call_with_frames_removed
  File "/opt/airflow/dags/weather_dbt_dag.py", line 16, in <module>
    weather_dbt_dag = DbtDag(
  File "/home/airflow/.local/lib/python3.8/site-packages/cosmos/airflow/dag.py", line 25, in __init__
    DbtToAirflowConverter.__init__(self, *args, **specific_kwargs(**kwargs))
  File "/home/airflow/.local/lib/python3.8/site-packages/cosmos/converter.py", line 209, in __init__
    project_config.validate_project()
  File "/home/airflow/.local/lib/python3.8/site-packages/cosmos/config.py", line 193, in validate_project
    raise CosmosValueError(f"Could not find {name} at {path}")
cosmos.exceptions.CosmosValueError: Could not find dbt_project.yml at /opt/airflow/dbt/weather/dbt_project.yml
[2025-06-16T10:24:34.951+0000] {processor.py:842} WARNING - No viable dags retrieved from /opt/airflow/dags/weather_dbt_dag.py
[2025-06-16T10:24:34.964+0000] {processor.py:183} INFO - Processing /opt/airflow/dags/weather_dbt_dag.py took 0.617 seconds
[2025-06-16T10:25:05.810+0000] {processor.py:161} INFO - Started process (PID=470) to work on /opt/airflow/dags/weather_dbt_dag.py
[2025-06-16T10:25:05.811+0000] {processor.py:830} INFO - Processing file /opt/airflow/dags/weather_dbt_dag.py for tasks to queue
[2025-06-16T10:25:05.812+0000] {logging_mixin.py:188} INFO - [2025-06-16T10:25:05.812+0000] {dagbag.py:538} INFO - Filling up the DagBag from /opt/airflow/dags/weather_dbt_dag.py
[2025-06-16T10:25:05.856+0000] {logging_mixin.py:188} INFO - [2025-06-16T10:25:05.856+0000] {configuration.py:1046} WARNING - section/key [openlineage/namespace] not found in config
[2025-06-16T10:25:06.178+0000] {logging_mixin.py:188} INFO - [2025-06-16T10:25:06.177+0000] {dagbag.py:348} ERROR - Failed to import: /opt/airflow/dags/weather_dbt_dag.py
Traceback (most recent call last):
  File "/home/airflow/.local/lib/python3.8/site-packages/airflow/models/dagbag.py", line 344, in parse
    loader.exec_module(new_module)
  File "<frozen importlib._bootstrap_external>", line 843, in exec_module
  File "<frozen importlib._bootstrap>", line 219, in _call_with_frames_removed
  File "/opt/airflow/dags/weather_dbt_dag.py", line 16, in <module>
    weather_dbt_dag = DbtDag(
  File "/home/airflow/.local/lib/python3.8/site-packages/cosmos/airflow/dag.py", line 25, in __init__
    DbtToAirflowConverter.__init__(self, *args, **specific_kwargs(**kwargs))
  File "/home/airflow/.local/lib/python3.8/site-packages/cosmos/converter.py", line 209, in __init__
    project_config.validate_project()
  File "/home/airflow/.local/lib/python3.8/site-packages/cosmos/config.py", line 193, in validate_project
    raise CosmosValueError(f"Could not find {name} at {path}")
cosmos.exceptions.CosmosValueError: Could not find dbt_project.yml at /opt/airflow/dbt/weather/dbt_project.yml
[2025-06-16T10:25:06.178+0000] {logging_mixin.py:188} WARNING - [2025-06-16T10:25:06.177+0000] {dagbag.py:348} ERROR - (astronomer-cosmos) - Failed to import: /opt/airflow/dags/weather_dbt_dag.py
Traceback (most recent call last):
  File "/home/airflow/.local/lib/python3.8/site-packages/airflow/models/dagbag.py", line 344, in parse
    loader.exec_module(new_module)
  File "<frozen importlib._bootstrap_external>", line 843, in exec_module
  File "<frozen importlib._bootstrap>", line 219, in _call_with_frames_removed
  File "/opt/airflow/dags/weather_dbt_dag.py", line 16, in <module>
    weather_dbt_dag = DbtDag(
  File "/home/airflow/.local/lib/python3.8/site-packages/cosmos/airflow/dag.py", line 25, in __init__
    DbtToAirflowConverter.__init__(self, *args, **specific_kwargs(**kwargs))
  File "/home/airflow/.local/lib/python3.8/site-packages/cosmos/converter.py", line 209, in __init__
    project_config.validate_project()
  File "/home/airflow/.local/lib/python3.8/site-packages/cosmos/config.py", line 193, in validate_project
    raise CosmosValueError(f"Could not find {name} at {path}")
cosmos.exceptions.CosmosValueError: Could not find dbt_project.yml at /opt/airflow/dbt/weather/dbt_project.yml
[2025-06-16T10:25:06.179+0000] {processor.py:842} WARNING - No viable dags retrieved from /opt/airflow/dags/weather_dbt_dag.py
[2025-06-16T10:25:06.192+0000] {processor.py:183} INFO - Processing /opt/airflow/dags/weather_dbt_dag.py took 0.384 seconds
[2025-06-16T10:25:36.392+0000] {processor.py:161} INFO - Started process (PID=494) to work on /opt/airflow/dags/weather_dbt_dag.py
[2025-06-16T10:25:36.393+0000] {processor.py:830} INFO - Processing file /opt/airflow/dags/weather_dbt_dag.py for tasks to queue
[2025-06-16T10:25:36.395+0000] {logging_mixin.py:188} INFO - [2025-06-16T10:25:36.394+0000] {dagbag.py:538} INFO - Filling up the DagBag from /opt/airflow/dags/weather_dbt_dag.py
[2025-06-16T10:25:36.436+0000] {logging_mixin.py:188} INFO - [2025-06-16T10:25:36.435+0000] {configuration.py:1046} WARNING - section/key [openlineage/namespace] not found in config
[2025-06-16T10:25:36.766+0000] {logging_mixin.py:188} INFO - [2025-06-16T10:25:36.765+0000] {dagbag.py:348} ERROR - Failed to import: /opt/airflow/dags/weather_dbt_dag.py
Traceback (most recent call last):
  File "/home/airflow/.local/lib/python3.8/site-packages/airflow/models/dagbag.py", line 344, in parse
    loader.exec_module(new_module)
  File "<frozen importlib._bootstrap_external>", line 843, in exec_module
  File "<frozen importlib._bootstrap>", line 219, in _call_with_frames_removed
  File "/opt/airflow/dags/weather_dbt_dag.py", line 16, in <module>
    weather_dbt_dag = DbtDag(
  File "/home/airflow/.local/lib/python3.8/site-packages/cosmos/airflow/dag.py", line 25, in __init__
    DbtToAirflowConverter.__init__(self, *args, **specific_kwargs(**kwargs))
  File "/home/airflow/.local/lib/python3.8/site-packages/cosmos/converter.py", line 209, in __init__
    project_config.validate_project()
  File "/home/airflow/.local/lib/python3.8/site-packages/cosmos/config.py", line 193, in validate_project
    raise CosmosValueError(f"Could not find {name} at {path}")
cosmos.exceptions.CosmosValueError: Could not find dbt_project.yml at /opt/airflow/dbt/weather/dbt_project.yml
[2025-06-16T10:25:36.767+0000] {logging_mixin.py:188} WARNING - [2025-06-16T10:25:36.765+0000] {dagbag.py:348} ERROR - (astronomer-cosmos) - Failed to import: /opt/airflow/dags/weather_dbt_dag.py
Traceback (most recent call last):
  File "/home/airflow/.local/lib/python3.8/site-packages/airflow/models/dagbag.py", line 344, in parse
    loader.exec_module(new_module)
  File "<frozen importlib._bootstrap_external>", line 843, in exec_module
  File "<frozen importlib._bootstrap>", line 219, in _call_with_frames_removed
  File "/opt/airflow/dags/weather_dbt_dag.py", line 16, in <module>
    weather_dbt_dag = DbtDag(
  File "/home/airflow/.local/lib/python3.8/site-packages/cosmos/airflow/dag.py", line 25, in __init__
    DbtToAirflowConverter.__init__(self, *args, **specific_kwargs(**kwargs))
  File "/home/airflow/.local/lib/python3.8/site-packages/cosmos/converter.py", line 209, in __init__
    project_config.validate_project()
  File "/home/airflow/.local/lib/python3.8/site-packages/cosmos/config.py", line 193, in validate_project
    raise CosmosValueError(f"Could not find {name} at {path}")
cosmos.exceptions.CosmosValueError: Could not find dbt_project.yml at /opt/airflow/dbt/weather/dbt_project.yml
[2025-06-16T10:25:36.767+0000] {processor.py:842} WARNING - No viable dags retrieved from /opt/airflow/dags/weather_dbt_dag.py
[2025-06-16T10:25:36.780+0000] {processor.py:183} INFO - Processing /opt/airflow/dags/weather_dbt_dag.py took 0.391 seconds
[2025-06-16T10:26:06.844+0000] {processor.py:161} INFO - Started process (PID=518) to work on /opt/airflow/dags/weather_dbt_dag.py
[2025-06-16T10:26:06.845+0000] {processor.py:830} INFO - Processing file /opt/airflow/dags/weather_dbt_dag.py for tasks to queue
[2025-06-16T10:26:06.846+0000] {logging_mixin.py:188} INFO - [2025-06-16T10:26:06.846+0000] {dagbag.py:538} INFO - Filling up the DagBag from /opt/airflow/dags/weather_dbt_dag.py
[2025-06-16T10:26:06.886+0000] {logging_mixin.py:188} INFO - [2025-06-16T10:26:06.886+0000] {configuration.py:1046} WARNING - section/key [openlineage/namespace] not found in config
[2025-06-16T10:26:07.302+0000] {logging_mixin.py:188} INFO - [2025-06-16T10:26:07.301+0000] {dagbag.py:348} ERROR - Failed to import: /opt/airflow/dags/weather_dbt_dag.py
Traceback (most recent call last):
  File "/home/airflow/.local/lib/python3.8/site-packages/airflow/models/dagbag.py", line 344, in parse
    loader.exec_module(new_module)
  File "<frozen importlib._bootstrap_external>", line 843, in exec_module
  File "<frozen importlib._bootstrap>", line 219, in _call_with_frames_removed
  File "/opt/airflow/dags/weather_dbt_dag.py", line 16, in <module>
    weather_dbt_dag = DbtDag(
  File "/home/airflow/.local/lib/python3.8/site-packages/cosmos/airflow/dag.py", line 25, in __init__
    DbtToAirflowConverter.__init__(self, *args, **specific_kwargs(**kwargs))
  File "/home/airflow/.local/lib/python3.8/site-packages/cosmos/converter.py", line 209, in __init__
    project_config.validate_project()
  File "/home/airflow/.local/lib/python3.8/site-packages/cosmos/config.py", line 193, in validate_project
    raise CosmosValueError(f"Could not find {name} at {path}")
cosmos.exceptions.CosmosValueError: Could not find dbt_project.yml at /opt/airflow/dbt/weather/dbt_project.yml
[2025-06-16T10:26:07.303+0000] {logging_mixin.py:188} WARNING - [2025-06-16T10:26:07.301+0000] {dagbag.py:348} ERROR - (astronomer-cosmos) - Failed to import: /opt/airflow/dags/weather_dbt_dag.py
Traceback (most recent call last):
  File "/home/airflow/.local/lib/python3.8/site-packages/airflow/models/dagbag.py", line 344, in parse
    loader.exec_module(new_module)
  File "<frozen importlib._bootstrap_external>", line 843, in exec_module
  File "<frozen importlib._bootstrap>", line 219, in _call_with_frames_removed
  File "/opt/airflow/dags/weather_dbt_dag.py", line 16, in <module>
    weather_dbt_dag = DbtDag(
  File "/home/airflow/.local/lib/python3.8/site-packages/cosmos/airflow/dag.py", line 25, in __init__
    DbtToAirflowConverter.__init__(self, *args, **specific_kwargs(**kwargs))
  File "/home/airflow/.local/lib/python3.8/site-packages/cosmos/converter.py", line 209, in __init__
    project_config.validate_project()
  File "/home/airflow/.local/lib/python3.8/site-packages/cosmos/config.py", line 193, in validate_project
    raise CosmosValueError(f"Could not find {name} at {path}")
cosmos.exceptions.CosmosValueError: Could not find dbt_project.yml at /opt/airflow/dbt/weather/dbt_project.yml
[2025-06-16T10:26:07.304+0000] {processor.py:842} WARNING - No viable dags retrieved from /opt/airflow/dags/weather_dbt_dag.py
[2025-06-16T10:26:07.326+0000] {processor.py:183} INFO - Processing /opt/airflow/dags/weather_dbt_dag.py took 0.486 seconds
[2025-06-16T10:26:37.520+0000] {processor.py:161} INFO - Started process (PID=549) to work on /opt/airflow/dags/weather_dbt_dag.py
[2025-06-16T10:26:37.521+0000] {processor.py:830} INFO - Processing file /opt/airflow/dags/weather_dbt_dag.py for tasks to queue
[2025-06-16T10:26:37.522+0000] {logging_mixin.py:188} INFO - [2025-06-16T10:26:37.522+0000] {dagbag.py:538} INFO - Filling up the DagBag from /opt/airflow/dags/weather_dbt_dag.py
[2025-06-16T10:26:37.565+0000] {logging_mixin.py:188} INFO - [2025-06-16T10:26:37.565+0000] {configuration.py:1046} WARNING - section/key [openlineage/namespace] not found in config
[2025-06-16T10:26:38.075+0000] {logging_mixin.py:188} INFO - [2025-06-16T10:26:38.074+0000] {dagbag.py:348} ERROR - Failed to import: /opt/airflow/dags/weather_dbt_dag.py
Traceback (most recent call last):
  File "/home/airflow/.local/lib/python3.8/site-packages/airflow/models/dagbag.py", line 344, in parse
    loader.exec_module(new_module)
  File "<frozen importlib._bootstrap_external>", line 843, in exec_module
  File "<frozen importlib._bootstrap>", line 219, in _call_with_frames_removed
  File "/opt/airflow/dags/weather_dbt_dag.py", line 16, in <module>
    weather_dbt_dag = DbtDag(
  File "/home/airflow/.local/lib/python3.8/site-packages/cosmos/airflow/dag.py", line 25, in __init__
    DbtToAirflowConverter.__init__(self, *args, **specific_kwargs(**kwargs))
  File "/home/airflow/.local/lib/python3.8/site-packages/cosmos/converter.py", line 209, in __init__
    project_config.validate_project()
  File "/home/airflow/.local/lib/python3.8/site-packages/cosmos/config.py", line 193, in validate_project
    raise CosmosValueError(f"Could not find {name} at {path}")
cosmos.exceptions.CosmosValueError: Could not find dbt_project.yml at /opt/airflow/dbt/weather/dbt_project.yml
[2025-06-16T10:26:38.076+0000] {logging_mixin.py:188} WARNING - [2025-06-16T10:26:38.074+0000] {dagbag.py:348} ERROR - (astronomer-cosmos) - Failed to import: /opt/airflow/dags/weather_dbt_dag.py
Traceback (most recent call last):
  File "/home/airflow/.local/lib/python3.8/site-packages/airflow/models/dagbag.py", line 344, in parse
    loader.exec_module(new_module)
  File "<frozen importlib._bootstrap_external>", line 843, in exec_module
  File "<frozen importlib._bootstrap>", line 219, in _call_with_frames_removed
  File "/opt/airflow/dags/weather_dbt_dag.py", line 16, in <module>
    weather_dbt_dag = DbtDag(
  File "/home/airflow/.local/lib/python3.8/site-packages/cosmos/airflow/dag.py", line 25, in __init__
    DbtToAirflowConverter.__init__(self, *args, **specific_kwargs(**kwargs))
  File "/home/airflow/.local/lib/python3.8/site-packages/cosmos/converter.py", line 209, in __init__
    project_config.validate_project()
  File "/home/airflow/.local/lib/python3.8/site-packages/cosmos/config.py", line 193, in validate_project
    raise CosmosValueError(f"Could not find {name} at {path}")
cosmos.exceptions.CosmosValueError: Could not find dbt_project.yml at /opt/airflow/dbt/weather/dbt_project.yml
[2025-06-16T10:26:38.076+0000] {processor.py:842} WARNING - No viable dags retrieved from /opt/airflow/dags/weather_dbt_dag.py
[2025-06-16T10:26:38.089+0000] {processor.py:183} INFO - Processing /opt/airflow/dags/weather_dbt_dag.py took 0.572 seconds
[2025-06-16T10:27:08.914+0000] {processor.py:161} INFO - Started process (PID=573) to work on /opt/airflow/dags/weather_dbt_dag.py
[2025-06-16T10:27:08.915+0000] {processor.py:830} INFO - Processing file /opt/airflow/dags/weather_dbt_dag.py for tasks to queue
[2025-06-16T10:27:08.917+0000] {logging_mixin.py:188} INFO - [2025-06-16T10:27:08.917+0000] {dagbag.py:538} INFO - Filling up the DagBag from /opt/airflow/dags/weather_dbt_dag.py
[2025-06-16T10:27:08.958+0000] {logging_mixin.py:188} INFO - [2025-06-16T10:27:08.958+0000] {configuration.py:1046} WARNING - section/key [openlineage/namespace] not found in config
[2025-06-16T10:27:09.289+0000] {logging_mixin.py:188} INFO - [2025-06-16T10:27:09.289+0000] {dagbag.py:348} ERROR - Failed to import: /opt/airflow/dags/weather_dbt_dag.py
Traceback (most recent call last):
  File "/home/airflow/.local/lib/python3.8/site-packages/airflow/models/dagbag.py", line 344, in parse
    loader.exec_module(new_module)
  File "<frozen importlib._bootstrap_external>", line 843, in exec_module
  File "<frozen importlib._bootstrap>", line 219, in _call_with_frames_removed
  File "/opt/airflow/dags/weather_dbt_dag.py", line 16, in <module>
    weather_dbt_dag = DbtDag(
  File "/home/airflow/.local/lib/python3.8/site-packages/cosmos/airflow/dag.py", line 25, in __init__
    DbtToAirflowConverter.__init__(self, *args, **specific_kwargs(**kwargs))
  File "/home/airflow/.local/lib/python3.8/site-packages/cosmos/converter.py", line 209, in __init__
    project_config.validate_project()
  File "/home/airflow/.local/lib/python3.8/site-packages/cosmos/config.py", line 193, in validate_project
    raise CosmosValueError(f"Could not find {name} at {path}")
cosmos.exceptions.CosmosValueError: Could not find dbt_project.yml at /opt/airflow/dbt/weather/dbt_project.yml
[2025-06-16T10:27:09.290+0000] {logging_mixin.py:188} WARNING - [2025-06-16T10:27:09.289+0000] {dagbag.py:348} ERROR - (astronomer-cosmos) - Failed to import: /opt/airflow/dags/weather_dbt_dag.py
Traceback (most recent call last):
  File "/home/airflow/.local/lib/python3.8/site-packages/airflow/models/dagbag.py", line 344, in parse
    loader.exec_module(new_module)
  File "<frozen importlib._bootstrap_external>", line 843, in exec_module
  File "<frozen importlib._bootstrap>", line 219, in _call_with_frames_removed
  File "/opt/airflow/dags/weather_dbt_dag.py", line 16, in <module>
    weather_dbt_dag = DbtDag(
  File "/home/airflow/.local/lib/python3.8/site-packages/cosmos/airflow/dag.py", line 25, in __init__
    DbtToAirflowConverter.__init__(self, *args, **specific_kwargs(**kwargs))
  File "/home/airflow/.local/lib/python3.8/site-packages/cosmos/converter.py", line 209, in __init__
    project_config.validate_project()
  File "/home/airflow/.local/lib/python3.8/site-packages/cosmos/config.py", line 193, in validate_project
    raise CosmosValueError(f"Could not find {name} at {path}")
cosmos.exceptions.CosmosValueError: Could not find dbt_project.yml at /opt/airflow/dbt/weather/dbt_project.yml
[2025-06-16T10:27:09.290+0000] {processor.py:842} WARNING - No viable dags retrieved from /opt/airflow/dags/weather_dbt_dag.py
[2025-06-16T10:27:09.303+0000] {processor.py:183} INFO - Processing /opt/airflow/dags/weather_dbt_dag.py took 0.391 seconds
[2025-06-16T10:27:39.403+0000] {processor.py:161} INFO - Started process (PID=605) to work on /opt/airflow/dags/weather_dbt_dag.py
[2025-06-16T10:27:39.405+0000] {processor.py:830} INFO - Processing file /opt/airflow/dags/weather_dbt_dag.py for tasks to queue
[2025-06-16T10:27:39.408+0000] {logging_mixin.py:188} INFO - [2025-06-16T10:27:39.408+0000] {dagbag.py:538} INFO - Filling up the DagBag from /opt/airflow/dags/weather_dbt_dag.py
[2025-06-16T10:27:39.475+0000] {logging_mixin.py:188} INFO - [2025-06-16T10:27:39.475+0000] {configuration.py:1046} WARNING - section/key [openlineage/namespace] not found in config
[2025-06-16T10:27:39.993+0000] {logging_mixin.py:188} INFO - [2025-06-16T10:27:39.992+0000] {dagbag.py:348} ERROR - Failed to import: /opt/airflow/dags/weather_dbt_dag.py
Traceback (most recent call last):
  File "/home/airflow/.local/lib/python3.8/site-packages/airflow/models/dagbag.py", line 344, in parse
    loader.exec_module(new_module)
  File "<frozen importlib._bootstrap_external>", line 843, in exec_module
  File "<frozen importlib._bootstrap>", line 219, in _call_with_frames_removed
  File "/opt/airflow/dags/weather_dbt_dag.py", line 16, in <module>
    weather_dbt_dag = DbtDag(
  File "/home/airflow/.local/lib/python3.8/site-packages/cosmos/airflow/dag.py", line 25, in __init__
    DbtToAirflowConverter.__init__(self, *args, **specific_kwargs(**kwargs))
  File "/home/airflow/.local/lib/python3.8/site-packages/cosmos/converter.py", line 209, in __init__
    project_config.validate_project()
  File "/home/airflow/.local/lib/python3.8/site-packages/cosmos/config.py", line 193, in validate_project
    raise CosmosValueError(f"Could not find {name} at {path}")
cosmos.exceptions.CosmosValueError: Could not find dbt_project.yml at /opt/airflow/dbt/weather/dbt_project.yml
[2025-06-16T10:27:39.994+0000] {logging_mixin.py:188} WARNING - [2025-06-16T10:27:39.992+0000] {dagbag.py:348} ERROR - (astronomer-cosmos) - Failed to import: /opt/airflow/dags/weather_dbt_dag.py
Traceback (most recent call last):
  File "/home/airflow/.local/lib/python3.8/site-packages/airflow/models/dagbag.py", line 344, in parse
    loader.exec_module(new_module)
  File "<frozen importlib._bootstrap_external>", line 843, in exec_module
  File "<frozen importlib._bootstrap>", line 219, in _call_with_frames_removed
  File "/opt/airflow/dags/weather_dbt_dag.py", line 16, in <module>
    weather_dbt_dag = DbtDag(
  File "/home/airflow/.local/lib/python3.8/site-packages/cosmos/airflow/dag.py", line 25, in __init__
    DbtToAirflowConverter.__init__(self, *args, **specific_kwargs(**kwargs))
  File "/home/airflow/.local/lib/python3.8/site-packages/cosmos/converter.py", line 209, in __init__
    project_config.validate_project()
  File "/home/airflow/.local/lib/python3.8/site-packages/cosmos/config.py", line 193, in validate_project
    raise CosmosValueError(f"Could not find {name} at {path}")
cosmos.exceptions.CosmosValueError: Could not find dbt_project.yml at /opt/airflow/dbt/weather/dbt_project.yml
[2025-06-16T10:27:39.995+0000] {processor.py:842} WARNING - No viable dags retrieved from /opt/airflow/dags/weather_dbt_dag.py
[2025-06-16T10:27:40.012+0000] {processor.py:183} INFO - Processing /opt/airflow/dags/weather_dbt_dag.py took 0.614 seconds
[2025-06-16T10:28:10.448+0000] {processor.py:161} INFO - Started process (PID=626) to work on /opt/airflow/dags/weather_dbt_dag.py
[2025-06-16T10:28:10.453+0000] {processor.py:830} INFO - Processing file /opt/airflow/dags/weather_dbt_dag.py for tasks to queue
[2025-06-16T10:28:10.463+0000] {logging_mixin.py:188} INFO - [2025-06-16T10:28:10.462+0000] {dagbag.py:538} INFO - Filling up the DagBag from /opt/airflow/dags/weather_dbt_dag.py
[2025-06-16T10:28:10.596+0000] {logging_mixin.py:188} INFO - [2025-06-16T10:28:10.596+0000] {configuration.py:1046} WARNING - section/key [openlineage/namespace] not found in config
[2025-06-16T10:28:11.230+0000] {logging_mixin.py:188} INFO - [2025-06-16T10:28:11.228+0000] {dagbag.py:348} ERROR - Failed to import: /opt/airflow/dags/weather_dbt_dag.py
Traceback (most recent call last):
  File "/home/airflow/.local/lib/python3.8/site-packages/airflow/models/dagbag.py", line 344, in parse
    loader.exec_module(new_module)
  File "<frozen importlib._bootstrap_external>", line 843, in exec_module
  File "<frozen importlib._bootstrap>", line 219, in _call_with_frames_removed
  File "/opt/airflow/dags/weather_dbt_dag.py", line 16, in <module>
    weather_dbt_dag = DbtDag(
  File "/home/airflow/.local/lib/python3.8/site-packages/cosmos/airflow/dag.py", line 25, in __init__
    DbtToAirflowConverter.__init__(self, *args, **specific_kwargs(**kwargs))
  File "/home/airflow/.local/lib/python3.8/site-packages/cosmos/converter.py", line 209, in __init__
    project_config.validate_project()
  File "/home/airflow/.local/lib/python3.8/site-packages/cosmos/config.py", line 193, in validate_project
    raise CosmosValueError(f"Could not find {name} at {path}")
cosmos.exceptions.CosmosValueError: Could not find dbt_project.yml at /opt/airflow/dbt/weather/dbt_project.yml
[2025-06-16T10:28:11.231+0000] {logging_mixin.py:188} WARNING - [2025-06-16T10:28:11.228+0000] {dagbag.py:348} ERROR - (astronomer-cosmos) - Failed to import: /opt/airflow/dags/weather_dbt_dag.py
Traceback (most recent call last):
  File "/home/airflow/.local/lib/python3.8/site-packages/airflow/models/dagbag.py", line 344, in parse
    loader.exec_module(new_module)
  File "<frozen importlib._bootstrap_external>", line 843, in exec_module
  File "<frozen importlib._bootstrap>", line 219, in _call_with_frames_removed
  File "/opt/airflow/dags/weather_dbt_dag.py", line 16, in <module>
    weather_dbt_dag = DbtDag(
  File "/home/airflow/.local/lib/python3.8/site-packages/cosmos/airflow/dag.py", line 25, in __init__
    DbtToAirflowConverter.__init__(self, *args, **specific_kwargs(**kwargs))
  File "/home/airflow/.local/lib/python3.8/site-packages/cosmos/converter.py", line 209, in __init__
    project_config.validate_project()
  File "/home/airflow/.local/lib/python3.8/site-packages/cosmos/config.py", line 193, in validate_project
    raise CosmosValueError(f"Could not find {name} at {path}")
cosmos.exceptions.CosmosValueError: Could not find dbt_project.yml at /opt/airflow/dbt/weather/dbt_project.yml
[2025-06-16T10:28:11.231+0000] {processor.py:842} WARNING - No viable dags retrieved from /opt/airflow/dags/weather_dbt_dag.py
[2025-06-16T10:28:11.256+0000] {processor.py:183} INFO - Processing /opt/airflow/dags/weather_dbt_dag.py took 0.820 seconds
[2025-06-16T10:28:41.844+0000] {processor.py:161} INFO - Started process (PID=657) to work on /opt/airflow/dags/weather_dbt_dag.py
[2025-06-16T10:28:41.848+0000] {processor.py:830} INFO - Processing file /opt/airflow/dags/weather_dbt_dag.py for tasks to queue
[2025-06-16T10:28:41.849+0000] {logging_mixin.py:188} INFO - [2025-06-16T10:28:41.848+0000] {dagbag.py:538} INFO - Filling up the DagBag from /opt/airflow/dags/weather_dbt_dag.py
[2025-06-16T10:28:41.982+0000] {logging_mixin.py:188} INFO - [2025-06-16T10:28:41.980+0000] {configuration.py:1046} WARNING - section/key [openlineage/namespace] not found in config
[2025-06-16T10:30:30.288+0000] {processor.py:161} INFO - Started process (PID=56) to work on /opt/airflow/dags/weather_dbt_dag.py
[2025-06-16T10:30:30.292+0000] {processor.py:830} INFO - Processing file /opt/airflow/dags/weather_dbt_dag.py for tasks to queue
[2025-06-16T10:30:30.313+0000] {logging_mixin.py:188} INFO - [2025-06-16T10:30:30.313+0000] {dagbag.py:538} INFO - Filling up the DagBag from /opt/airflow/dags/weather_dbt_dag.py
[2025-06-16T10:30:30.805+0000] {logging_mixin.py:188} INFO - [2025-06-16T10:30:30.804+0000] {configuration.py:1046} WARNING - section/key [openlineage/namespace] not found in config
[2025-06-16T10:30:38.097+0000] {logging_mixin.py:188} INFO - [2025-06-16T10:30:38.084+0000] {dagbag.py:348} ERROR - Failed to import: /opt/airflow/dags/weather_dbt_dag.py
Traceback (most recent call last):
  File "/home/airflow/.local/lib/python3.8/site-packages/airflow/models/dagbag.py", line 344, in parse
    loader.exec_module(new_module)
  File "<frozen importlib._bootstrap_external>", line 843, in exec_module
  File "<frozen importlib._bootstrap>", line 219, in _call_with_frames_removed
  File "/opt/airflow/dags/weather_dbt_dag.py", line 16, in <module>
    weather_dbt_dag = DbtDag(
  File "/home/airflow/.local/lib/python3.8/site-packages/cosmos/airflow/dag.py", line 25, in __init__
    DbtToAirflowConverter.__init__(self, *args, **specific_kwargs(**kwargs))
  File "/home/airflow/.local/lib/python3.8/site-packages/cosmos/converter.py", line 209, in __init__
    project_config.validate_project()
  File "/home/airflow/.local/lib/python3.8/site-packages/cosmos/config.py", line 193, in validate_project
    raise CosmosValueError(f"Could not find {name} at {path}")
cosmos.exceptions.CosmosValueError: Could not find dbt_project.yml at /opt/airflow/dbt/weather/dbt_project.yml
[2025-06-16T10:30:38.100+0000] {logging_mixin.py:188} WARNING - [2025-06-16T10:30:38.084+0000] {dagbag.py:348} ERROR - (astronomer-cosmos) - Failed to import: /opt/airflow/dags/weather_dbt_dag.py
Traceback (most recent call last):
  File "/home/airflow/.local/lib/python3.8/site-packages/airflow/models/dagbag.py", line 344, in parse
    loader.exec_module(new_module)
  File "<frozen importlib._bootstrap_external>", line 843, in exec_module
  File "<frozen importlib._bootstrap>", line 219, in _call_with_frames_removed
  File "/opt/airflow/dags/weather_dbt_dag.py", line 16, in <module>
    weather_dbt_dag = DbtDag(
  File "/home/airflow/.local/lib/python3.8/site-packages/cosmos/airflow/dag.py", line 25, in __init__
    DbtToAirflowConverter.__init__(self, *args, **specific_kwargs(**kwargs))
  File "/home/airflow/.local/lib/python3.8/site-packages/cosmos/converter.py", line 209, in __init__
    project_config.validate_project()
  File "/home/airflow/.local/lib/python3.8/site-packages/cosmos/config.py", line 193, in validate_project
    raise CosmosValueError(f"Could not find {name} at {path}")
cosmos.exceptions.CosmosValueError: Could not find dbt_project.yml at /opt/airflow/dbt/weather/dbt_project.yml
[2025-06-16T10:30:38.102+0000] {processor.py:842} WARNING - No viable dags retrieved from /opt/airflow/dags/weather_dbt_dag.py
[2025-06-16T10:30:38.401+0000] {processor.py:183} INFO - Processing /opt/airflow/dags/weather_dbt_dag.py took 8.119 seconds
[2025-06-16T10:31:08.550+0000] {processor.py:161} INFO - Started process (PID=88) to work on /opt/airflow/dags/weather_dbt_dag.py
[2025-06-16T10:31:08.551+0000] {processor.py:830} INFO - Processing file /opt/airflow/dags/weather_dbt_dag.py for tasks to queue
[2025-06-16T10:31:08.555+0000] {logging_mixin.py:188} INFO - [2025-06-16T10:31:08.554+0000] {dagbag.py:538} INFO - Filling up the DagBag from /opt/airflow/dags/weather_dbt_dag.py
[2025-06-16T10:31:08.674+0000] {logging_mixin.py:188} INFO - [2025-06-16T10:31:08.674+0000] {configuration.py:1046} WARNING - section/key [openlineage/namespace] not found in config
[2025-06-16T10:31:09.126+0000] {logging_mixin.py:188} INFO - [2025-06-16T10:31:09.123+0000] {dagbag.py:348} ERROR - Failed to import: /opt/airflow/dags/weather_dbt_dag.py
Traceback (most recent call last):
  File "/home/airflow/.local/lib/python3.8/site-packages/airflow/models/dagbag.py", line 344, in parse
    loader.exec_module(new_module)
  File "<frozen importlib._bootstrap_external>", line 843, in exec_module
  File "<frozen importlib._bootstrap>", line 219, in _call_with_frames_removed
  File "/opt/airflow/dags/weather_dbt_dag.py", line 16, in <module>
    weather_dbt_dag = DbtDag(
  File "/home/airflow/.local/lib/python3.8/site-packages/cosmos/airflow/dag.py", line 25, in __init__
    DbtToAirflowConverter.__init__(self, *args, **specific_kwargs(**kwargs))
  File "/home/airflow/.local/lib/python3.8/site-packages/cosmos/converter.py", line 209, in __init__
    project_config.validate_project()
  File "/home/airflow/.local/lib/python3.8/site-packages/cosmos/config.py", line 193, in validate_project
    raise CosmosValueError(f"Could not find {name} at {path}")
cosmos.exceptions.CosmosValueError: Could not find dbt_project.yml at /opt/airflow/dbt/weather/dbt_project.yml
[2025-06-16T10:31:09.126+0000] {logging_mixin.py:188} WARNING - [2025-06-16T10:31:09.123+0000] {dagbag.py:348} ERROR - (astronomer-cosmos) - Failed to import: /opt/airflow/dags/weather_dbt_dag.py
Traceback (most recent call last):
  File "/home/airflow/.local/lib/python3.8/site-packages/airflow/models/dagbag.py", line 344, in parse
    loader.exec_module(new_module)
  File "<frozen importlib._bootstrap_external>", line 843, in exec_module
  File "<frozen importlib._bootstrap>", line 219, in _call_with_frames_removed
  File "/opt/airflow/dags/weather_dbt_dag.py", line 16, in <module>
    weather_dbt_dag = DbtDag(
  File "/home/airflow/.local/lib/python3.8/site-packages/cosmos/airflow/dag.py", line 25, in __init__
    DbtToAirflowConverter.__init__(self, *args, **specific_kwargs(**kwargs))
  File "/home/airflow/.local/lib/python3.8/site-packages/cosmos/converter.py", line 209, in __init__
    project_config.validate_project()
  File "/home/airflow/.local/lib/python3.8/site-packages/cosmos/config.py", line 193, in validate_project
    raise CosmosValueError(f"Could not find {name} at {path}")
cosmos.exceptions.CosmosValueError: Could not find dbt_project.yml at /opt/airflow/dbt/weather/dbt_project.yml
[2025-06-16T10:31:09.127+0000] {processor.py:842} WARNING - No viable dags retrieved from /opt/airflow/dags/weather_dbt_dag.py
[2025-06-16T10:31:09.140+0000] {processor.py:183} INFO - Processing /opt/airflow/dags/weather_dbt_dag.py took 0.594 seconds
[2025-06-16T10:31:39.770+0000] {processor.py:161} INFO - Started process (PID=111) to work on /opt/airflow/dags/weather_dbt_dag.py
[2025-06-16T10:31:39.771+0000] {processor.py:830} INFO - Processing file /opt/airflow/dags/weather_dbt_dag.py for tasks to queue
[2025-06-16T10:31:39.773+0000] {logging_mixin.py:188} INFO - [2025-06-16T10:31:39.772+0000] {dagbag.py:538} INFO - Filling up the DagBag from /opt/airflow/dags/weather_dbt_dag.py
[2025-06-16T10:31:39.858+0000] {logging_mixin.py:188} INFO - [2025-06-16T10:31:39.857+0000] {configuration.py:1046} WARNING - section/key [openlineage/namespace] not found in config
[2025-06-16T10:31:40.375+0000] {logging_mixin.py:188} INFO - [2025-06-16T10:31:40.370+0000] {dagbag.py:348} ERROR - Failed to import: /opt/airflow/dags/weather_dbt_dag.py
Traceback (most recent call last):
  File "/home/airflow/.local/lib/python3.8/site-packages/airflow/models/dagbag.py", line 344, in parse
    loader.exec_module(new_module)
  File "<frozen importlib._bootstrap_external>", line 843, in exec_module
  File "<frozen importlib._bootstrap>", line 219, in _call_with_frames_removed
  File "/opt/airflow/dags/weather_dbt_dag.py", line 16, in <module>
    weather_dbt_dag = DbtDag(
  File "/home/airflow/.local/lib/python3.8/site-packages/cosmos/airflow/dag.py", line 25, in __init__
    DbtToAirflowConverter.__init__(self, *args, **specific_kwargs(**kwargs))
  File "/home/airflow/.local/lib/python3.8/site-packages/cosmos/converter.py", line 209, in __init__
    project_config.validate_project()
  File "/home/airflow/.local/lib/python3.8/site-packages/cosmos/config.py", line 193, in validate_project
    raise CosmosValueError(f"Could not find {name} at {path}")
cosmos.exceptions.CosmosValueError: Could not find dbt_project.yml at /opt/airflow/dbt/weather/dbt_project.yml
[2025-06-16T10:31:40.375+0000] {logging_mixin.py:188} WARNING - [2025-06-16T10:31:40.370+0000] {dagbag.py:348} ERROR - (astronomer-cosmos) - Failed to import: /opt/airflow/dags/weather_dbt_dag.py
Traceback (most recent call last):
  File "/home/airflow/.local/lib/python3.8/site-packages/airflow/models/dagbag.py", line 344, in parse
    loader.exec_module(new_module)
  File "<frozen importlib._bootstrap_external>", line 843, in exec_module
  File "<frozen importlib._bootstrap>", line 219, in _call_with_frames_removed
  File "/opt/airflow/dags/weather_dbt_dag.py", line 16, in <module>
    weather_dbt_dag = DbtDag(
  File "/home/airflow/.local/lib/python3.8/site-packages/cosmos/airflow/dag.py", line 25, in __init__
    DbtToAirflowConverter.__init__(self, *args, **specific_kwargs(**kwargs))
  File "/home/airflow/.local/lib/python3.8/site-packages/cosmos/converter.py", line 209, in __init__
    project_config.validate_project()
  File "/home/airflow/.local/lib/python3.8/site-packages/cosmos/config.py", line 193, in validate_project
    raise CosmosValueError(f"Could not find {name} at {path}")
cosmos.exceptions.CosmosValueError: Could not find dbt_project.yml at /opt/airflow/dbt/weather/dbt_project.yml
[2025-06-16T10:31:40.376+0000] {processor.py:842} WARNING - No viable dags retrieved from /opt/airflow/dags/weather_dbt_dag.py
[2025-06-16T10:31:40.395+0000] {processor.py:183} INFO - Processing /opt/airflow/dags/weather_dbt_dag.py took 0.629 seconds
[2025-06-16T10:32:10.609+0000] {processor.py:161} INFO - Started process (PID=143) to work on /opt/airflow/dags/weather_dbt_dag.py
[2025-06-16T10:32:10.613+0000] {processor.py:830} INFO - Processing file /opt/airflow/dags/weather_dbt_dag.py for tasks to queue
[2025-06-16T10:32:10.619+0000] {logging_mixin.py:188} INFO - [2025-06-16T10:32:10.619+0000] {dagbag.py:538} INFO - Filling up the DagBag from /opt/airflow/dags/weather_dbt_dag.py
[2025-06-16T10:32:10.765+0000] {logging_mixin.py:188} INFO - [2025-06-16T10:32:10.764+0000] {configuration.py:1046} WARNING - section/key [openlineage/namespace] not found in config
[2025-06-16T10:32:11.503+0000] {logging_mixin.py:188} INFO - [2025-06-16T10:32:11.499+0000] {dagbag.py:348} ERROR - Failed to import: /opt/airflow/dags/weather_dbt_dag.py
Traceback (most recent call last):
  File "/home/airflow/.local/lib/python3.8/site-packages/airflow/models/dagbag.py", line 344, in parse
    loader.exec_module(new_module)
  File "<frozen importlib._bootstrap_external>", line 843, in exec_module
  File "<frozen importlib._bootstrap>", line 219, in _call_with_frames_removed
  File "/opt/airflow/dags/weather_dbt_dag.py", line 16, in <module>
    weather_dbt_dag = DbtDag(
  File "/home/airflow/.local/lib/python3.8/site-packages/cosmos/airflow/dag.py", line 25, in __init__
    DbtToAirflowConverter.__init__(self, *args, **specific_kwargs(**kwargs))
  File "/home/airflow/.local/lib/python3.8/site-packages/cosmos/converter.py", line 209, in __init__
    project_config.validate_project()
  File "/home/airflow/.local/lib/python3.8/site-packages/cosmos/config.py", line 193, in validate_project
    raise CosmosValueError(f"Could not find {name} at {path}")
cosmos.exceptions.CosmosValueError: Could not find dbt_project.yml at /opt/airflow/dbt/weather/dbt_project.yml
[2025-06-16T10:32:11.504+0000] {logging_mixin.py:188} WARNING - [2025-06-16T10:32:11.499+0000] {dagbag.py:348} ERROR - (astronomer-cosmos) - Failed to import: /opt/airflow/dags/weather_dbt_dag.py
Traceback (most recent call last):
  File "/home/airflow/.local/lib/python3.8/site-packages/airflow/models/dagbag.py", line 344, in parse
    loader.exec_module(new_module)
  File "<frozen importlib._bootstrap_external>", line 843, in exec_module
  File "<frozen importlib._bootstrap>", line 219, in _call_with_frames_removed
  File "/opt/airflow/dags/weather_dbt_dag.py", line 16, in <module>
    weather_dbt_dag = DbtDag(
  File "/home/airflow/.local/lib/python3.8/site-packages/cosmos/airflow/dag.py", line 25, in __init__
    DbtToAirflowConverter.__init__(self, *args, **specific_kwargs(**kwargs))
  File "/home/airflow/.local/lib/python3.8/site-packages/cosmos/converter.py", line 209, in __init__
    project_config.validate_project()
  File "/home/airflow/.local/lib/python3.8/site-packages/cosmos/config.py", line 193, in validate_project
    raise CosmosValueError(f"Could not find {name} at {path}")
cosmos.exceptions.CosmosValueError: Could not find dbt_project.yml at /opt/airflow/dbt/weather/dbt_project.yml
[2025-06-16T10:32:11.505+0000] {processor.py:842} WARNING - No viable dags retrieved from /opt/airflow/dags/weather_dbt_dag.py
[2025-06-16T10:32:11.527+0000] {processor.py:183} INFO - Processing /opt/airflow/dags/weather_dbt_dag.py took 0.926 seconds
[2025-06-16T10:32:41.708+0000] {processor.py:161} INFO - Started process (PID=167) to work on /opt/airflow/dags/weather_dbt_dag.py
[2025-06-16T10:32:41.711+0000] {processor.py:830} INFO - Processing file /opt/airflow/dags/weather_dbt_dag.py for tasks to queue
[2025-06-16T10:32:41.717+0000] {logging_mixin.py:188} INFO - [2025-06-16T10:32:41.717+0000] {dagbag.py:538} INFO - Filling up the DagBag from /opt/airflow/dags/weather_dbt_dag.py
[2025-06-16T10:32:41.787+0000] {logging_mixin.py:188} INFO - [2025-06-16T10:32:41.787+0000] {configuration.py:1046} WARNING - section/key [openlineage/namespace] not found in config
[2025-06-16T10:32:42.386+0000] {logging_mixin.py:188} INFO - [2025-06-16T10:32:42.382+0000] {dagbag.py:348} ERROR - Failed to import: /opt/airflow/dags/weather_dbt_dag.py
Traceback (most recent call last):
  File "/home/airflow/.local/lib/python3.8/site-packages/airflow/models/dagbag.py", line 344, in parse
    loader.exec_module(new_module)
  File "<frozen importlib._bootstrap_external>", line 843, in exec_module
  File "<frozen importlib._bootstrap>", line 219, in _call_with_frames_removed
  File "/opt/airflow/dags/weather_dbt_dag.py", line 16, in <module>
    weather_dbt_dag = DbtDag(
  File "/home/airflow/.local/lib/python3.8/site-packages/cosmos/airflow/dag.py", line 25, in __init__
    DbtToAirflowConverter.__init__(self, *args, **specific_kwargs(**kwargs))
  File "/home/airflow/.local/lib/python3.8/site-packages/cosmos/converter.py", line 209, in __init__
    project_config.validate_project()
  File "/home/airflow/.local/lib/python3.8/site-packages/cosmos/config.py", line 193, in validate_project
    raise CosmosValueError(f"Could not find {name} at {path}")
cosmos.exceptions.CosmosValueError: Could not find dbt_project.yml at /opt/airflow/dbt/weather/dbt_project.yml
[2025-06-16T10:32:42.387+0000] {logging_mixin.py:188} WARNING - [2025-06-16T10:32:42.382+0000] {dagbag.py:348} ERROR - (astronomer-cosmos) - Failed to import: /opt/airflow/dags/weather_dbt_dag.py
Traceback (most recent call last):
  File "/home/airflow/.local/lib/python3.8/site-packages/airflow/models/dagbag.py", line 344, in parse
    loader.exec_module(new_module)
  File "<frozen importlib._bootstrap_external>", line 843, in exec_module
  File "<frozen importlib._bootstrap>", line 219, in _call_with_frames_removed
  File "/opt/airflow/dags/weather_dbt_dag.py", line 16, in <module>
    weather_dbt_dag = DbtDag(
  File "/home/airflow/.local/lib/python3.8/site-packages/cosmos/airflow/dag.py", line 25, in __init__
    DbtToAirflowConverter.__init__(self, *args, **specific_kwargs(**kwargs))
  File "/home/airflow/.local/lib/python3.8/site-packages/cosmos/converter.py", line 209, in __init__
    project_config.validate_project()
  File "/home/airflow/.local/lib/python3.8/site-packages/cosmos/config.py", line 193, in validate_project
    raise CosmosValueError(f"Could not find {name} at {path}")
cosmos.exceptions.CosmosValueError: Could not find dbt_project.yml at /opt/airflow/dbt/weather/dbt_project.yml
[2025-06-16T10:32:42.387+0000] {processor.py:842} WARNING - No viable dags retrieved from /opt/airflow/dags/weather_dbt_dag.py
[2025-06-16T10:32:42.449+0000] {processor.py:183} INFO - Processing /opt/airflow/dags/weather_dbt_dag.py took 0.755 seconds
[2025-06-16T10:33:13.155+0000] {processor.py:161} INFO - Started process (PID=191) to work on /opt/airflow/dags/weather_dbt_dag.py
[2025-06-16T10:33:13.155+0000] {processor.py:830} INFO - Processing file /opt/airflow/dags/weather_dbt_dag.py for tasks to queue
[2025-06-16T10:33:13.157+0000] {logging_mixin.py:188} INFO - [2025-06-16T10:33:13.157+0000] {dagbag.py:538} INFO - Filling up the DagBag from /opt/airflow/dags/weather_dbt_dag.py
[2025-06-16T10:33:13.215+0000] {logging_mixin.py:188} INFO - [2025-06-16T10:33:13.215+0000] {configuration.py:1046} WARNING - section/key [openlineage/namespace] not found in config
[2025-06-16T10:33:13.747+0000] {logging_mixin.py:188} INFO - [2025-06-16T10:33:13.744+0000] {dagbag.py:348} ERROR - Failed to import: /opt/airflow/dags/weather_dbt_dag.py
Traceback (most recent call last):
  File "/home/airflow/.local/lib/python3.8/site-packages/airflow/models/dagbag.py", line 344, in parse
    loader.exec_module(new_module)
  File "<frozen importlib._bootstrap_external>", line 843, in exec_module
  File "<frozen importlib._bootstrap>", line 219, in _call_with_frames_removed
  File "/opt/airflow/dags/weather_dbt_dag.py", line 16, in <module>
    weather_dbt_dag = DbtDag(
  File "/home/airflow/.local/lib/python3.8/site-packages/cosmos/airflow/dag.py", line 25, in __init__
    DbtToAirflowConverter.__init__(self, *args, **specific_kwargs(**kwargs))
  File "/home/airflow/.local/lib/python3.8/site-packages/cosmos/converter.py", line 209, in __init__
    project_config.validate_project()
  File "/home/airflow/.local/lib/python3.8/site-packages/cosmos/config.py", line 193, in validate_project
    raise CosmosValueError(f"Could not find {name} at {path}")
cosmos.exceptions.CosmosValueError: Could not find dbt_project.yml at /opt/airflow/dbt/weather/dbt_project.yml
[2025-06-16T10:33:13.748+0000] {logging_mixin.py:188} WARNING - [2025-06-16T10:33:13.744+0000] {dagbag.py:348} ERROR - (astronomer-cosmos) - Failed to import: /opt/airflow/dags/weather_dbt_dag.py
Traceback (most recent call last):
  File "/home/airflow/.local/lib/python3.8/site-packages/airflow/models/dagbag.py", line 344, in parse
    loader.exec_module(new_module)
  File "<frozen importlib._bootstrap_external>", line 843, in exec_module
  File "<frozen importlib._bootstrap>", line 219, in _call_with_frames_removed
  File "/opt/airflow/dags/weather_dbt_dag.py", line 16, in <module>
    weather_dbt_dag = DbtDag(
  File "/home/airflow/.local/lib/python3.8/site-packages/cosmos/airflow/dag.py", line 25, in __init__
    DbtToAirflowConverter.__init__(self, *args, **specific_kwargs(**kwargs))
  File "/home/airflow/.local/lib/python3.8/site-packages/cosmos/converter.py", line 209, in __init__
    project_config.validate_project()
  File "/home/airflow/.local/lib/python3.8/site-packages/cosmos/config.py", line 193, in validate_project
    raise CosmosValueError(f"Could not find {name} at {path}")
cosmos.exceptions.CosmosValueError: Could not find dbt_project.yml at /opt/airflow/dbt/weather/dbt_project.yml
[2025-06-16T10:33:13.749+0000] {processor.py:842} WARNING - No viable dags retrieved from /opt/airflow/dags/weather_dbt_dag.py
[2025-06-16T10:33:13.771+0000] {processor.py:183} INFO - Processing /opt/airflow/dags/weather_dbt_dag.py took 0.619 seconds
[2025-06-16T10:33:44.638+0000] {processor.py:161} INFO - Started process (PID=223) to work on /opt/airflow/dags/weather_dbt_dag.py
[2025-06-16T10:33:44.641+0000] {processor.py:830} INFO - Processing file /opt/airflow/dags/weather_dbt_dag.py for tasks to queue
[2025-06-16T10:33:44.650+0000] {logging_mixin.py:188} INFO - [2025-06-16T10:33:44.650+0000] {dagbag.py:538} INFO - Filling up the DagBag from /opt/airflow/dags/weather_dbt_dag.py
[2025-06-16T10:33:44.723+0000] {logging_mixin.py:188} INFO - [2025-06-16T10:33:44.723+0000] {configuration.py:1046} WARNING - section/key [openlineage/namespace] not found in config
[2025-06-16T10:33:45.183+0000] {logging_mixin.py:188} INFO - [2025-06-16T10:33:45.181+0000] {dagbag.py:348} ERROR - Failed to import: /opt/airflow/dags/weather_dbt_dag.py
Traceback (most recent call last):
  File "/home/airflow/.local/lib/python3.8/site-packages/airflow/models/dagbag.py", line 344, in parse
    loader.exec_module(new_module)
  File "<frozen importlib._bootstrap_external>", line 843, in exec_module
  File "<frozen importlib._bootstrap>", line 219, in _call_with_frames_removed
  File "/opt/airflow/dags/weather_dbt_dag.py", line 16, in <module>
    weather_dbt_dag = DbtDag(
  File "/home/airflow/.local/lib/python3.8/site-packages/cosmos/airflow/dag.py", line 25, in __init__
    DbtToAirflowConverter.__init__(self, *args, **specific_kwargs(**kwargs))
  File "/home/airflow/.local/lib/python3.8/site-packages/cosmos/converter.py", line 209, in __init__
    project_config.validate_project()
  File "/home/airflow/.local/lib/python3.8/site-packages/cosmos/config.py", line 193, in validate_project
    raise CosmosValueError(f"Could not find {name} at {path}")
cosmos.exceptions.CosmosValueError: Could not find dbt_project.yml at /opt/airflow/dbt/weather/dbt_project.yml
[2025-06-16T10:33:45.184+0000] {logging_mixin.py:188} WARNING - [2025-06-16T10:33:45.181+0000] {dagbag.py:348} ERROR - (astronomer-cosmos) - Failed to import: /opt/airflow/dags/weather_dbt_dag.py
Traceback (most recent call last):
  File "/home/airflow/.local/lib/python3.8/site-packages/airflow/models/dagbag.py", line 344, in parse
    loader.exec_module(new_module)
  File "<frozen importlib._bootstrap_external>", line 843, in exec_module
  File "<frozen importlib._bootstrap>", line 219, in _call_with_frames_removed
  File "/opt/airflow/dags/weather_dbt_dag.py", line 16, in <module>
    weather_dbt_dag = DbtDag(
  File "/home/airflow/.local/lib/python3.8/site-packages/cosmos/airflow/dag.py", line 25, in __init__
    DbtToAirflowConverter.__init__(self, *args, **specific_kwargs(**kwargs))
  File "/home/airflow/.local/lib/python3.8/site-packages/cosmos/converter.py", line 209, in __init__
    project_config.validate_project()
  File "/home/airflow/.local/lib/python3.8/site-packages/cosmos/config.py", line 193, in validate_project
    raise CosmosValueError(f"Could not find {name} at {path}")
cosmos.exceptions.CosmosValueError: Could not find dbt_project.yml at /opt/airflow/dbt/weather/dbt_project.yml
[2025-06-16T10:33:45.184+0000] {processor.py:842} WARNING - No viable dags retrieved from /opt/airflow/dags/weather_dbt_dag.py
[2025-06-16T10:33:45.198+0000] {processor.py:183} INFO - Processing /opt/airflow/dags/weather_dbt_dag.py took 0.574 seconds
[2025-06-16T10:34:15.634+0000] {processor.py:161} INFO - Started process (PID=246) to work on /opt/airflow/dags/weather_dbt_dag.py
[2025-06-16T10:34:15.634+0000] {processor.py:830} INFO - Processing file /opt/airflow/dags/weather_dbt_dag.py for tasks to queue
[2025-06-16T10:34:15.637+0000] {logging_mixin.py:188} INFO - [2025-06-16T10:34:15.636+0000] {dagbag.py:538} INFO - Filling up the DagBag from /opt/airflow/dags/weather_dbt_dag.py
[2025-06-16T10:34:15.678+0000] {logging_mixin.py:188} INFO - [2025-06-16T10:34:15.678+0000] {configuration.py:1046} WARNING - section/key [openlineage/namespace] not found in config
[2025-06-16T10:34:16.073+0000] {logging_mixin.py:188} INFO - [2025-06-16T10:34:16.072+0000] {dagbag.py:348} ERROR - Failed to import: /opt/airflow/dags/weather_dbt_dag.py
Traceback (most recent call last):
  File "/home/airflow/.local/lib/python3.8/site-packages/airflow/models/dagbag.py", line 344, in parse
    loader.exec_module(new_module)
  File "<frozen importlib._bootstrap_external>", line 843, in exec_module
  File "<frozen importlib._bootstrap>", line 219, in _call_with_frames_removed
  File "/opt/airflow/dags/weather_dbt_dag.py", line 16, in <module>
    weather_dbt_dag = DbtDag(
  File "/home/airflow/.local/lib/python3.8/site-packages/cosmos/airflow/dag.py", line 25, in __init__
    DbtToAirflowConverter.__init__(self, *args, **specific_kwargs(**kwargs))
  File "/home/airflow/.local/lib/python3.8/site-packages/cosmos/converter.py", line 209, in __init__
    project_config.validate_project()
  File "/home/airflow/.local/lib/python3.8/site-packages/cosmos/config.py", line 193, in validate_project
    raise CosmosValueError(f"Could not find {name} at {path}")
cosmos.exceptions.CosmosValueError: Could not find dbt_project.yml at /opt/airflow/dbt/weather/dbt_project.yml
[2025-06-16T10:34:16.074+0000] {logging_mixin.py:188} WARNING - [2025-06-16T10:34:16.072+0000] {dagbag.py:348} ERROR - (astronomer-cosmos) - Failed to import: /opt/airflow/dags/weather_dbt_dag.py
Traceback (most recent call last):
  File "/home/airflow/.local/lib/python3.8/site-packages/airflow/models/dagbag.py", line 344, in parse
    loader.exec_module(new_module)
  File "<frozen importlib._bootstrap_external>", line 843, in exec_module
  File "<frozen importlib._bootstrap>", line 219, in _call_with_frames_removed
  File "/opt/airflow/dags/weather_dbt_dag.py", line 16, in <module>
    weather_dbt_dag = DbtDag(
  File "/home/airflow/.local/lib/python3.8/site-packages/cosmos/airflow/dag.py", line 25, in __init__
    DbtToAirflowConverter.__init__(self, *args, **specific_kwargs(**kwargs))
  File "/home/airflow/.local/lib/python3.8/site-packages/cosmos/converter.py", line 209, in __init__
    project_config.validate_project()
  File "/home/airflow/.local/lib/python3.8/site-packages/cosmos/config.py", line 193, in validate_project
    raise CosmosValueError(f"Could not find {name} at {path}")
cosmos.exceptions.CosmosValueError: Could not find dbt_project.yml at /opt/airflow/dbt/weather/dbt_project.yml
[2025-06-16T10:34:16.075+0000] {processor.py:842} WARNING - No viable dags retrieved from /opt/airflow/dags/weather_dbt_dag.py
[2025-06-16T10:34:16.095+0000] {processor.py:183} INFO - Processing /opt/airflow/dags/weather_dbt_dag.py took 0.464 seconds
[2025-06-16T10:34:47.075+0000] {processor.py:161} INFO - Started process (PID=277) to work on /opt/airflow/dags/weather_dbt_dag.py
[2025-06-16T10:34:47.078+0000] {processor.py:830} INFO - Processing file /opt/airflow/dags/weather_dbt_dag.py for tasks to queue
[2025-06-16T10:34:47.087+0000] {logging_mixin.py:188} INFO - [2025-06-16T10:34:47.087+0000] {dagbag.py:538} INFO - Filling up the DagBag from /opt/airflow/dags/weather_dbt_dag.py
[2025-06-16T10:34:47.281+0000] {logging_mixin.py:188} INFO - [2025-06-16T10:34:47.280+0000] {configuration.py:1046} WARNING - section/key [openlineage/namespace] not found in config
[2025-06-16T10:34:48.183+0000] {logging_mixin.py:188} INFO - [2025-06-16T10:34:48.180+0000] {dagbag.py:348} ERROR - Failed to import: /opt/airflow/dags/weather_dbt_dag.py
Traceback (most recent call last):
  File "/home/airflow/.local/lib/python3.8/site-packages/airflow/models/dagbag.py", line 344, in parse
    loader.exec_module(new_module)
  File "<frozen importlib._bootstrap_external>", line 843, in exec_module
  File "<frozen importlib._bootstrap>", line 219, in _call_with_frames_removed
  File "/opt/airflow/dags/weather_dbt_dag.py", line 16, in <module>
    weather_dbt_dag = DbtDag(
  File "/home/airflow/.local/lib/python3.8/site-packages/cosmos/airflow/dag.py", line 25, in __init__
    DbtToAirflowConverter.__init__(self, *args, **specific_kwargs(**kwargs))
  File "/home/airflow/.local/lib/python3.8/site-packages/cosmos/converter.py", line 209, in __init__
    project_config.validate_project()
  File "/home/airflow/.local/lib/python3.8/site-packages/cosmos/config.py", line 193, in validate_project
    raise CosmosValueError(f"Could not find {name} at {path}")
cosmos.exceptions.CosmosValueError: Could not find dbt_project.yml at /opt/airflow/dbt/weather/dbt_project.yml
[2025-06-16T10:34:48.189+0000] {logging_mixin.py:188} WARNING - [2025-06-16T10:34:48.180+0000] {dagbag.py:348} ERROR - (astronomer-cosmos) - Failed to import: /opt/airflow/dags/weather_dbt_dag.py
Traceback (most recent call last):
  File "/home/airflow/.local/lib/python3.8/site-packages/airflow/models/dagbag.py", line 344, in parse
    loader.exec_module(new_module)
  File "<frozen importlib._bootstrap_external>", line 843, in exec_module
  File "<frozen importlib._bootstrap>", line 219, in _call_with_frames_removed
  File "/opt/airflow/dags/weather_dbt_dag.py", line 16, in <module>
    weather_dbt_dag = DbtDag(
  File "/home/airflow/.local/lib/python3.8/site-packages/cosmos/airflow/dag.py", line 25, in __init__
    DbtToAirflowConverter.__init__(self, *args, **specific_kwargs(**kwargs))
  File "/home/airflow/.local/lib/python3.8/site-packages/cosmos/converter.py", line 209, in __init__
    project_config.validate_project()
  File "/home/airflow/.local/lib/python3.8/site-packages/cosmos/config.py", line 193, in validate_project
    raise CosmosValueError(f"Could not find {name} at {path}")
cosmos.exceptions.CosmosValueError: Could not find dbt_project.yml at /opt/airflow/dbt/weather/dbt_project.yml
[2025-06-16T10:34:48.189+0000] {processor.py:842} WARNING - No viable dags retrieved from /opt/airflow/dags/weather_dbt_dag.py
[2025-06-16T10:34:48.238+0000] {processor.py:183} INFO - Processing /opt/airflow/dags/weather_dbt_dag.py took 1.173 seconds
[2025-06-16T10:35:19.077+0000] {processor.py:161} INFO - Started process (PID=299) to work on /opt/airflow/dags/weather_dbt_dag.py
[2025-06-16T10:35:19.077+0000] {processor.py:830} INFO - Processing file /opt/airflow/dags/weather_dbt_dag.py for tasks to queue
[2025-06-16T10:35:19.080+0000] {logging_mixin.py:188} INFO - [2025-06-16T10:35:19.080+0000] {dagbag.py:538} INFO - Filling up the DagBag from /opt/airflow/dags/weather_dbt_dag.py
[2025-06-16T10:35:19.145+0000] {logging_mixin.py:188} INFO - [2025-06-16T10:35:19.145+0000] {configuration.py:1046} WARNING - section/key [openlineage/namespace] not found in config
[2025-06-16T10:35:19.628+0000] {logging_mixin.py:188} INFO - [2025-06-16T10:35:19.626+0000] {dagbag.py:348} ERROR - Failed to import: /opt/airflow/dags/weather_dbt_dag.py
Traceback (most recent call last):
  File "/home/airflow/.local/lib/python3.8/site-packages/airflow/models/dagbag.py", line 344, in parse
    loader.exec_module(new_module)
  File "<frozen importlib._bootstrap_external>", line 843, in exec_module
  File "<frozen importlib._bootstrap>", line 219, in _call_with_frames_removed
  File "/opt/airflow/dags/weather_dbt_dag.py", line 16, in <module>
    weather_dbt_dag = DbtDag(
  File "/home/airflow/.local/lib/python3.8/site-packages/cosmos/airflow/dag.py", line 25, in __init__
    DbtToAirflowConverter.__init__(self, *args, **specific_kwargs(**kwargs))
  File "/home/airflow/.local/lib/python3.8/site-packages/cosmos/converter.py", line 209, in __init__
    project_config.validate_project()
  File "/home/airflow/.local/lib/python3.8/site-packages/cosmos/config.py", line 193, in validate_project
    raise CosmosValueError(f"Could not find {name} at {path}")
cosmos.exceptions.CosmosValueError: Could not find dbt_project.yml at /opt/airflow/dbt/weather/dbt_project.yml
[2025-06-16T10:35:19.629+0000] {logging_mixin.py:188} WARNING - [2025-06-16T10:35:19.626+0000] {dagbag.py:348} ERROR - (astronomer-cosmos) - Failed to import: /opt/airflow/dags/weather_dbt_dag.py
Traceback (most recent call last):
  File "/home/airflow/.local/lib/python3.8/site-packages/airflow/models/dagbag.py", line 344, in parse
    loader.exec_module(new_module)
  File "<frozen importlib._bootstrap_external>", line 843, in exec_module
  File "<frozen importlib._bootstrap>", line 219, in _call_with_frames_removed
  File "/opt/airflow/dags/weather_dbt_dag.py", line 16, in <module>
    weather_dbt_dag = DbtDag(
  File "/home/airflow/.local/lib/python3.8/site-packages/cosmos/airflow/dag.py", line 25, in __init__
    DbtToAirflowConverter.__init__(self, *args, **specific_kwargs(**kwargs))
  File "/home/airflow/.local/lib/python3.8/site-packages/cosmos/converter.py", line 209, in __init__
    project_config.validate_project()
  File "/home/airflow/.local/lib/python3.8/site-packages/cosmos/config.py", line 193, in validate_project
    raise CosmosValueError(f"Could not find {name} at {path}")
cosmos.exceptions.CosmosValueError: Could not find dbt_project.yml at /opt/airflow/dbt/weather/dbt_project.yml
[2025-06-16T10:35:19.632+0000] {processor.py:842} WARNING - No viable dags retrieved from /opt/airflow/dags/weather_dbt_dag.py
[2025-06-16T10:35:19.658+0000] {processor.py:183} INFO - Processing /opt/airflow/dags/weather_dbt_dag.py took 0.585 seconds
[2025-06-16T10:35:50.402+0000] {processor.py:161} INFO - Started process (PID=322) to work on /opt/airflow/dags/weather_dbt_dag.py
[2025-06-16T10:35:50.403+0000] {processor.py:830} INFO - Processing file /opt/airflow/dags/weather_dbt_dag.py for tasks to queue
[2025-06-16T10:35:50.407+0000] {logging_mixin.py:188} INFO - [2025-06-16T10:35:50.407+0000] {dagbag.py:538} INFO - Filling up the DagBag from /opt/airflow/dags/weather_dbt_dag.py
[2025-06-16T10:35:50.459+0000] {logging_mixin.py:188} INFO - [2025-06-16T10:35:50.459+0000] {configuration.py:1046} WARNING - section/key [openlineage/namespace] not found in config
[2025-06-16T10:35:50.909+0000] {logging_mixin.py:188} INFO - [2025-06-16T10:35:50.908+0000] {dagbag.py:348} ERROR - Failed to import: /opt/airflow/dags/weather_dbt_dag.py
Traceback (most recent call last):
  File "/home/airflow/.local/lib/python3.8/site-packages/airflow/models/dagbag.py", line 344, in parse
    loader.exec_module(new_module)
  File "<frozen importlib._bootstrap_external>", line 843, in exec_module
  File "<frozen importlib._bootstrap>", line 219, in _call_with_frames_removed
  File "/opt/airflow/dags/weather_dbt_dag.py", line 16, in <module>
    weather_dbt_dag = DbtDag(
  File "/home/airflow/.local/lib/python3.8/site-packages/cosmos/airflow/dag.py", line 25, in __init__
    DbtToAirflowConverter.__init__(self, *args, **specific_kwargs(**kwargs))
  File "/home/airflow/.local/lib/python3.8/site-packages/cosmos/converter.py", line 209, in __init__
    project_config.validate_project()
  File "/home/airflow/.local/lib/python3.8/site-packages/cosmos/config.py", line 193, in validate_project
    raise CosmosValueError(f"Could not find {name} at {path}")
cosmos.exceptions.CosmosValueError: Could not find dbt_project.yml at /opt/airflow/dbt/weather/dbt_project.yml
[2025-06-16T10:35:50.910+0000] {logging_mixin.py:188} WARNING - [2025-06-16T10:35:50.908+0000] {dagbag.py:348} ERROR - (astronomer-cosmos) - Failed to import: /opt/airflow/dags/weather_dbt_dag.py
Traceback (most recent call last):
  File "/home/airflow/.local/lib/python3.8/site-packages/airflow/models/dagbag.py", line 344, in parse
    loader.exec_module(new_module)
  File "<frozen importlib._bootstrap_external>", line 843, in exec_module
  File "<frozen importlib._bootstrap>", line 219, in _call_with_frames_removed
  File "/opt/airflow/dags/weather_dbt_dag.py", line 16, in <module>
    weather_dbt_dag = DbtDag(
  File "/home/airflow/.local/lib/python3.8/site-packages/cosmos/airflow/dag.py", line 25, in __init__
    DbtToAirflowConverter.__init__(self, *args, **specific_kwargs(**kwargs))
  File "/home/airflow/.local/lib/python3.8/site-packages/cosmos/converter.py", line 209, in __init__
    project_config.validate_project()
  File "/home/airflow/.local/lib/python3.8/site-packages/cosmos/config.py", line 193, in validate_project
    raise CosmosValueError(f"Could not find {name} at {path}")
cosmos.exceptions.CosmosValueError: Could not find dbt_project.yml at /opt/airflow/dbt/weather/dbt_project.yml
[2025-06-16T10:35:50.910+0000] {processor.py:842} WARNING - No viable dags retrieved from /opt/airflow/dags/weather_dbt_dag.py
[2025-06-16T10:35:50.923+0000] {processor.py:183} INFO - Processing /opt/airflow/dags/weather_dbt_dag.py took 0.525 seconds
[2025-06-16T10:36:21.540+0000] {processor.py:161} INFO - Started process (PID=354) to work on /opt/airflow/dags/weather_dbt_dag.py
[2025-06-16T10:36:21.544+0000] {processor.py:830} INFO - Processing file /opt/airflow/dags/weather_dbt_dag.py for tasks to queue
[2025-06-16T10:36:21.547+0000] {logging_mixin.py:188} INFO - [2025-06-16T10:36:21.547+0000] {dagbag.py:538} INFO - Filling up the DagBag from /opt/airflow/dags/weather_dbt_dag.py
[2025-06-16T10:36:21.608+0000] {logging_mixin.py:188} INFO - [2025-06-16T10:36:21.608+0000] {configuration.py:1046} WARNING - section/key [openlineage/namespace] not found in config
[2025-06-16T10:36:22.045+0000] {logging_mixin.py:188} INFO - [2025-06-16T10:36:22.044+0000] {dagbag.py:348} ERROR - Failed to import: /opt/airflow/dags/weather_dbt_dag.py
Traceback (most recent call last):
  File "/home/airflow/.local/lib/python3.8/site-packages/airflow/models/dagbag.py", line 344, in parse
    loader.exec_module(new_module)
  File "<frozen importlib._bootstrap_external>", line 843, in exec_module
  File "<frozen importlib._bootstrap>", line 219, in _call_with_frames_removed
  File "/opt/airflow/dags/weather_dbt_dag.py", line 16, in <module>
    weather_dbt_dag = DbtDag(
  File "/home/airflow/.local/lib/python3.8/site-packages/cosmos/airflow/dag.py", line 25, in __init__
    DbtToAirflowConverter.__init__(self, *args, **specific_kwargs(**kwargs))
  File "/home/airflow/.local/lib/python3.8/site-packages/cosmos/converter.py", line 209, in __init__
    project_config.validate_project()
  File "/home/airflow/.local/lib/python3.8/site-packages/cosmos/config.py", line 193, in validate_project
    raise CosmosValueError(f"Could not find {name} at {path}")
cosmos.exceptions.CosmosValueError: Could not find dbt_project.yml at /opt/airflow/dbt/weather/dbt_project.yml
[2025-06-16T10:36:22.045+0000] {logging_mixin.py:188} WARNING - [2025-06-16T10:36:22.044+0000] {dagbag.py:348} ERROR - (astronomer-cosmos) - Failed to import: /opt/airflow/dags/weather_dbt_dag.py
Traceback (most recent call last):
  File "/home/airflow/.local/lib/python3.8/site-packages/airflow/models/dagbag.py", line 344, in parse
    loader.exec_module(new_module)
  File "<frozen importlib._bootstrap_external>", line 843, in exec_module
  File "<frozen importlib._bootstrap>", line 219, in _call_with_frames_removed
  File "/opt/airflow/dags/weather_dbt_dag.py", line 16, in <module>
    weather_dbt_dag = DbtDag(
  File "/home/airflow/.local/lib/python3.8/site-packages/cosmos/airflow/dag.py", line 25, in __init__
    DbtToAirflowConverter.__init__(self, *args, **specific_kwargs(**kwargs))
  File "/home/airflow/.local/lib/python3.8/site-packages/cosmos/converter.py", line 209, in __init__
    project_config.validate_project()
  File "/home/airflow/.local/lib/python3.8/site-packages/cosmos/config.py", line 193, in validate_project
    raise CosmosValueError(f"Could not find {name} at {path}")
cosmos.exceptions.CosmosValueError: Could not find dbt_project.yml at /opt/airflow/dbt/weather/dbt_project.yml
[2025-06-16T10:36:22.046+0000] {processor.py:842} WARNING - No viable dags retrieved from /opt/airflow/dags/weather_dbt_dag.py
[2025-06-16T10:36:22.058+0000] {processor.py:183} INFO - Processing /opt/airflow/dags/weather_dbt_dag.py took 0.525 seconds
[2025-06-16T10:36:52.175+0000] {processor.py:161} INFO - Started process (PID=378) to work on /opt/airflow/dags/weather_dbt_dag.py
[2025-06-16T10:36:52.176+0000] {processor.py:830} INFO - Processing file /opt/airflow/dags/weather_dbt_dag.py for tasks to queue
[2025-06-16T10:36:52.177+0000] {logging_mixin.py:188} INFO - [2025-06-16T10:36:52.177+0000] {dagbag.py:538} INFO - Filling up the DagBag from /opt/airflow/dags/weather_dbt_dag.py
[2025-06-16T10:36:52.219+0000] {logging_mixin.py:188} INFO - [2025-06-16T10:36:52.218+0000] {configuration.py:1046} WARNING - section/key [openlineage/namespace] not found in config
[2025-06-16T10:36:52.547+0000] {logging_mixin.py:188} INFO - [2025-06-16T10:36:52.546+0000] {dagbag.py:348} ERROR - Failed to import: /opt/airflow/dags/weather_dbt_dag.py
Traceback (most recent call last):
  File "/home/airflow/.local/lib/python3.8/site-packages/airflow/models/dagbag.py", line 344, in parse
    loader.exec_module(new_module)
  File "<frozen importlib._bootstrap_external>", line 843, in exec_module
  File "<frozen importlib._bootstrap>", line 219, in _call_with_frames_removed
  File "/opt/airflow/dags/weather_dbt_dag.py", line 16, in <module>
    weather_dbt_dag = DbtDag(
  File "/home/airflow/.local/lib/python3.8/site-packages/cosmos/airflow/dag.py", line 25, in __init__
    DbtToAirflowConverter.__init__(self, *args, **specific_kwargs(**kwargs))
  File "/home/airflow/.local/lib/python3.8/site-packages/cosmos/converter.py", line 209, in __init__
    project_config.validate_project()
  File "/home/airflow/.local/lib/python3.8/site-packages/cosmos/config.py", line 193, in validate_project
    raise CosmosValueError(f"Could not find {name} at {path}")
cosmos.exceptions.CosmosValueError: Could not find dbt_project.yml at /opt/airflow/dbt/weather/dbt_project.yml
[2025-06-16T10:36:52.547+0000] {logging_mixin.py:188} WARNING - [2025-06-16T10:36:52.546+0000] {dagbag.py:348} ERROR - (astronomer-cosmos) - Failed to import: /opt/airflow/dags/weather_dbt_dag.py
Traceback (most recent call last):
  File "/home/airflow/.local/lib/python3.8/site-packages/airflow/models/dagbag.py", line 344, in parse
    loader.exec_module(new_module)
  File "<frozen importlib._bootstrap_external>", line 843, in exec_module
  File "<frozen importlib._bootstrap>", line 219, in _call_with_frames_removed
  File "/opt/airflow/dags/weather_dbt_dag.py", line 16, in <module>
    weather_dbt_dag = DbtDag(
  File "/home/airflow/.local/lib/python3.8/site-packages/cosmos/airflow/dag.py", line 25, in __init__
    DbtToAirflowConverter.__init__(self, *args, **specific_kwargs(**kwargs))
  File "/home/airflow/.local/lib/python3.8/site-packages/cosmos/converter.py", line 209, in __init__
    project_config.validate_project()
  File "/home/airflow/.local/lib/python3.8/site-packages/cosmos/config.py", line 193, in validate_project
    raise CosmosValueError(f"Could not find {name} at {path}")
cosmos.exceptions.CosmosValueError: Could not find dbt_project.yml at /opt/airflow/dbt/weather/dbt_project.yml
[2025-06-16T10:36:52.548+0000] {processor.py:842} WARNING - No viable dags retrieved from /opt/airflow/dags/weather_dbt_dag.py
[2025-06-16T10:36:52.561+0000] {processor.py:183} INFO - Processing /opt/airflow/dags/weather_dbt_dag.py took 0.389 seconds
[2025-06-16T10:38:25.280+0000] {processor.py:161} INFO - Started process (PID=46) to work on /opt/airflow/dags/weather_dbt_dag.py
[2025-06-16T10:38:25.282+0000] {processor.py:830} INFO - Processing file /opt/airflow/dags/weather_dbt_dag.py for tasks to queue
[2025-06-16T10:38:25.285+0000] {logging_mixin.py:188} INFO - [2025-06-16T10:38:25.285+0000] {dagbag.py:538} INFO - Filling up the DagBag from /opt/airflow/dags/weather_dbt_dag.py
[2025-06-16T10:38:25.359+0000] {logging_mixin.py:188} INFO - [2025-06-16T10:38:25.359+0000] {configuration.py:1046} WARNING - section/key [openlineage/namespace] not found in config
[2025-06-16T10:38:26.697+0000] {logging_mixin.py:188} INFO - [2025-06-16T10:38:26.696+0000] {dagbag.py:348} ERROR - Failed to import: /opt/airflow/dags/weather_dbt_dag.py
Traceback (most recent call last):
  File "/home/airflow/.local/lib/python3.8/site-packages/airflow/models/dagbag.py", line 344, in parse
    loader.exec_module(new_module)
  File "<frozen importlib._bootstrap_external>", line 843, in exec_module
  File "<frozen importlib._bootstrap>", line 219, in _call_with_frames_removed
  File "/opt/airflow/dags/weather_dbt_dag.py", line 16, in <module>
    weather_dbt_dag = DbtDag(
  File "/home/airflow/.local/lib/python3.8/site-packages/cosmos/airflow/dag.py", line 25, in __init__
    DbtToAirflowConverter.__init__(self, *args, **specific_kwargs(**kwargs))
  File "/home/airflow/.local/lib/python3.8/site-packages/cosmos/converter.py", line 209, in __init__
    project_config.validate_project()
  File "/home/airflow/.local/lib/python3.8/site-packages/cosmos/config.py", line 193, in validate_project
    raise CosmosValueError(f"Could not find {name} at {path}")
cosmos.exceptions.CosmosValueError: Could not find dbt_project.yml at /opt/airflow/dbt/weather/dbt_project.yml
[2025-06-16T10:38:26.699+0000] {logging_mixin.py:188} WARNING - [2025-06-16T10:38:26.696+0000] {dagbag.py:348} ERROR - (astronomer-cosmos) - Failed to import: /opt/airflow/dags/weather_dbt_dag.py
Traceback (most recent call last):
  File "/home/airflow/.local/lib/python3.8/site-packages/airflow/models/dagbag.py", line 344, in parse
    loader.exec_module(new_module)
  File "<frozen importlib._bootstrap_external>", line 843, in exec_module
  File "<frozen importlib._bootstrap>", line 219, in _call_with_frames_removed
  File "/opt/airflow/dags/weather_dbt_dag.py", line 16, in <module>
    weather_dbt_dag = DbtDag(
  File "/home/airflow/.local/lib/python3.8/site-packages/cosmos/airflow/dag.py", line 25, in __init__
    DbtToAirflowConverter.__init__(self, *args, **specific_kwargs(**kwargs))
  File "/home/airflow/.local/lib/python3.8/site-packages/cosmos/converter.py", line 209, in __init__
    project_config.validate_project()
  File "/home/airflow/.local/lib/python3.8/site-packages/cosmos/config.py", line 193, in validate_project
    raise CosmosValueError(f"Could not find {name} at {path}")
cosmos.exceptions.CosmosValueError: Could not find dbt_project.yml at /opt/airflow/dbt/weather/dbt_project.yml
[2025-06-16T10:38:26.700+0000] {processor.py:842} WARNING - No viable dags retrieved from /opt/airflow/dags/weather_dbt_dag.py
[2025-06-16T10:38:26.921+0000] {processor.py:183} INFO - Processing /opt/airflow/dags/weather_dbt_dag.py took 1.648 seconds
[2025-06-16T10:38:57.082+0000] {processor.py:161} INFO - Started process (PID=70) to work on /opt/airflow/dags/weather_dbt_dag.py
[2025-06-16T10:38:57.083+0000] {processor.py:830} INFO - Processing file /opt/airflow/dags/weather_dbt_dag.py for tasks to queue
[2025-06-16T10:38:57.085+0000] {logging_mixin.py:188} INFO - [2025-06-16T10:38:57.085+0000] {dagbag.py:538} INFO - Filling up the DagBag from /opt/airflow/dags/weather_dbt_dag.py
[2025-06-16T10:38:57.134+0000] {logging_mixin.py:188} INFO - [2025-06-16T10:38:57.133+0000] {configuration.py:1046} WARNING - section/key [openlineage/namespace] not found in config
[2025-06-16T10:38:57.455+0000] {logging_mixin.py:188} INFO - [2025-06-16T10:38:57.454+0000] {dagbag.py:348} ERROR - Failed to import: /opt/airflow/dags/weather_dbt_dag.py
Traceback (most recent call last):
  File "/home/airflow/.local/lib/python3.8/site-packages/airflow/models/dagbag.py", line 344, in parse
    loader.exec_module(new_module)
  File "<frozen importlib._bootstrap_external>", line 843, in exec_module
  File "<frozen importlib._bootstrap>", line 219, in _call_with_frames_removed
  File "/opt/airflow/dags/weather_dbt_dag.py", line 16, in <module>
    weather_dbt_dag = DbtDag(
  File "/home/airflow/.local/lib/python3.8/site-packages/cosmos/airflow/dag.py", line 25, in __init__
    DbtToAirflowConverter.__init__(self, *args, **specific_kwargs(**kwargs))
  File "/home/airflow/.local/lib/python3.8/site-packages/cosmos/converter.py", line 209, in __init__
    project_config.validate_project()
  File "/home/airflow/.local/lib/python3.8/site-packages/cosmos/config.py", line 193, in validate_project
    raise CosmosValueError(f"Could not find {name} at {path}")
cosmos.exceptions.CosmosValueError: Could not find dbt_project.yml at /opt/airflow/dbt/weather/dbt_project.yml
[2025-06-16T10:38:57.456+0000] {logging_mixin.py:188} WARNING - [2025-06-16T10:38:57.454+0000] {dagbag.py:348} ERROR - (astronomer-cosmos) - Failed to import: /opt/airflow/dags/weather_dbt_dag.py
Traceback (most recent call last):
  File "/home/airflow/.local/lib/python3.8/site-packages/airflow/models/dagbag.py", line 344, in parse
    loader.exec_module(new_module)
  File "<frozen importlib._bootstrap_external>", line 843, in exec_module
  File "<frozen importlib._bootstrap>", line 219, in _call_with_frames_removed
  File "/opt/airflow/dags/weather_dbt_dag.py", line 16, in <module>
    weather_dbt_dag = DbtDag(
  File "/home/airflow/.local/lib/python3.8/site-packages/cosmos/airflow/dag.py", line 25, in __init__
    DbtToAirflowConverter.__init__(self, *args, **specific_kwargs(**kwargs))
  File "/home/airflow/.local/lib/python3.8/site-packages/cosmos/converter.py", line 209, in __init__
    project_config.validate_project()
  File "/home/airflow/.local/lib/python3.8/site-packages/cosmos/config.py", line 193, in validate_project
    raise CosmosValueError(f"Could not find {name} at {path}")
cosmos.exceptions.CosmosValueError: Could not find dbt_project.yml at /opt/airflow/dbt/weather/dbt_project.yml
[2025-06-16T10:38:57.456+0000] {processor.py:842} WARNING - No viable dags retrieved from /opt/airflow/dags/weather_dbt_dag.py
[2025-06-16T10:38:57.470+0000] {processor.py:183} INFO - Processing /opt/airflow/dags/weather_dbt_dag.py took 0.392 seconds
[2025-06-16T10:39:27.595+0000] {processor.py:161} INFO - Started process (PID=102) to work on /opt/airflow/dags/weather_dbt_dag.py
[2025-06-16T10:39:27.599+0000] {processor.py:830} INFO - Processing file /opt/airflow/dags/weather_dbt_dag.py for tasks to queue
[2025-06-16T10:39:27.616+0000] {logging_mixin.py:188} INFO - [2025-06-16T10:39:27.613+0000] {dagbag.py:538} INFO - Filling up the DagBag from /opt/airflow/dags/weather_dbt_dag.py
[2025-06-16T10:39:27.826+0000] {logging_mixin.py:188} INFO - [2025-06-16T10:39:27.825+0000] {configuration.py:1046} WARNING - section/key [openlineage/namespace] not found in config
[2025-06-16T10:39:28.486+0000] {logging_mixin.py:188} INFO - [2025-06-16T10:39:28.484+0000] {dagbag.py:348} ERROR - Failed to import: /opt/airflow/dags/weather_dbt_dag.py
Traceback (most recent call last):
  File "/home/airflow/.local/lib/python3.8/site-packages/airflow/models/dagbag.py", line 344, in parse
    loader.exec_module(new_module)
  File "<frozen importlib._bootstrap_external>", line 843, in exec_module
  File "<frozen importlib._bootstrap>", line 219, in _call_with_frames_removed
  File "/opt/airflow/dags/weather_dbt_dag.py", line 16, in <module>
    weather_dbt_dag = DbtDag(
  File "/home/airflow/.local/lib/python3.8/site-packages/cosmos/airflow/dag.py", line 25, in __init__
    DbtToAirflowConverter.__init__(self, *args, **specific_kwargs(**kwargs))
  File "/home/airflow/.local/lib/python3.8/site-packages/cosmos/converter.py", line 209, in __init__
    project_config.validate_project()
  File "/home/airflow/.local/lib/python3.8/site-packages/cosmos/config.py", line 193, in validate_project
    raise CosmosValueError(f"Could not find {name} at {path}")
cosmos.exceptions.CosmosValueError: Could not find dbt_project.yml at /opt/airflow/dbt/weather/dbt_project.yml
[2025-06-16T10:39:28.487+0000] {logging_mixin.py:188} WARNING - [2025-06-16T10:39:28.484+0000] {dagbag.py:348} ERROR - (astronomer-cosmos) - Failed to import: /opt/airflow/dags/weather_dbt_dag.py
Traceback (most recent call last):
  File "/home/airflow/.local/lib/python3.8/site-packages/airflow/models/dagbag.py", line 344, in parse
    loader.exec_module(new_module)
  File "<frozen importlib._bootstrap_external>", line 843, in exec_module
  File "<frozen importlib._bootstrap>", line 219, in _call_with_frames_removed
  File "/opt/airflow/dags/weather_dbt_dag.py", line 16, in <module>
    weather_dbt_dag = DbtDag(
  File "/home/airflow/.local/lib/python3.8/site-packages/cosmos/airflow/dag.py", line 25, in __init__
    DbtToAirflowConverter.__init__(self, *args, **specific_kwargs(**kwargs))
  File "/home/airflow/.local/lib/python3.8/site-packages/cosmos/converter.py", line 209, in __init__
    project_config.validate_project()
  File "/home/airflow/.local/lib/python3.8/site-packages/cosmos/config.py", line 193, in validate_project
    raise CosmosValueError(f"Could not find {name} at {path}")
cosmos.exceptions.CosmosValueError: Could not find dbt_project.yml at /opt/airflow/dbt/weather/dbt_project.yml
[2025-06-16T10:39:28.487+0000] {processor.py:842} WARNING - No viable dags retrieved from /opt/airflow/dags/weather_dbt_dag.py
[2025-06-16T10:39:28.500+0000] {processor.py:183} INFO - Processing /opt/airflow/dags/weather_dbt_dag.py took 0.920 seconds
[2025-06-16T10:39:58.897+0000] {processor.py:161} INFO - Started process (PID=125) to work on /opt/airflow/dags/weather_dbt_dag.py
[2025-06-16T10:39:58.897+0000] {processor.py:830} INFO - Processing file /opt/airflow/dags/weather_dbt_dag.py for tasks to queue
[2025-06-16T10:39:58.899+0000] {logging_mixin.py:188} INFO - [2025-06-16T10:39:58.899+0000] {dagbag.py:538} INFO - Filling up the DagBag from /opt/airflow/dags/weather_dbt_dag.py
[2025-06-16T10:39:58.963+0000] {logging_mixin.py:188} INFO - [2025-06-16T10:39:58.963+0000] {configuration.py:1046} WARNING - section/key [openlineage/namespace] not found in config
[2025-06-16T10:39:59.306+0000] {logging_mixin.py:188} INFO - [2025-06-16T10:39:59.305+0000] {dagbag.py:348} ERROR - Failed to import: /opt/airflow/dags/weather_dbt_dag.py
Traceback (most recent call last):
  File "/home/airflow/.local/lib/python3.8/site-packages/airflow/models/dagbag.py", line 344, in parse
    loader.exec_module(new_module)
  File "<frozen importlib._bootstrap_external>", line 843, in exec_module
  File "<frozen importlib._bootstrap>", line 219, in _call_with_frames_removed
  File "/opt/airflow/dags/weather_dbt_dag.py", line 16, in <module>
    weather_dbt_dag = DbtDag(
  File "/home/airflow/.local/lib/python3.8/site-packages/cosmos/airflow/dag.py", line 25, in __init__
    DbtToAirflowConverter.__init__(self, *args, **specific_kwargs(**kwargs))
  File "/home/airflow/.local/lib/python3.8/site-packages/cosmos/converter.py", line 209, in __init__
    project_config.validate_project()
  File "/home/airflow/.local/lib/python3.8/site-packages/cosmos/config.py", line 193, in validate_project
    raise CosmosValueError(f"Could not find {name} at {path}")
cosmos.exceptions.CosmosValueError: Could not find dbt_project.yml at /opt/airflow/dbt/weather/dbt_project.yml
[2025-06-16T10:39:59.306+0000] {logging_mixin.py:188} WARNING - [2025-06-16T10:39:59.305+0000] {dagbag.py:348} ERROR - (astronomer-cosmos) - Failed to import: /opt/airflow/dags/weather_dbt_dag.py
Traceback (most recent call last):
  File "/home/airflow/.local/lib/python3.8/site-packages/airflow/models/dagbag.py", line 344, in parse
    loader.exec_module(new_module)
  File "<frozen importlib._bootstrap_external>", line 843, in exec_module
  File "<frozen importlib._bootstrap>", line 219, in _call_with_frames_removed
  File "/opt/airflow/dags/weather_dbt_dag.py", line 16, in <module>
    weather_dbt_dag = DbtDag(
  File "/home/airflow/.local/lib/python3.8/site-packages/cosmos/airflow/dag.py", line 25, in __init__
    DbtToAirflowConverter.__init__(self, *args, **specific_kwargs(**kwargs))
  File "/home/airflow/.local/lib/python3.8/site-packages/cosmos/converter.py", line 209, in __init__
    project_config.validate_project()
  File "/home/airflow/.local/lib/python3.8/site-packages/cosmos/config.py", line 193, in validate_project
    raise CosmosValueError(f"Could not find {name} at {path}")
cosmos.exceptions.CosmosValueError: Could not find dbt_project.yml at /opt/airflow/dbt/weather/dbt_project.yml
[2025-06-16T10:39:59.307+0000] {processor.py:842} WARNING - No viable dags retrieved from /opt/airflow/dags/weather_dbt_dag.py
[2025-06-16T10:39:59.320+0000] {processor.py:183} INFO - Processing /opt/airflow/dags/weather_dbt_dag.py took 0.426 seconds
[2025-06-16T10:40:29.397+0000] {processor.py:161} INFO - Started process (PID=157) to work on /opt/airflow/dags/weather_dbt_dag.py
[2025-06-16T10:40:29.401+0000] {processor.py:830} INFO - Processing file /opt/airflow/dags/weather_dbt_dag.py for tasks to queue
[2025-06-16T10:40:29.404+0000] {logging_mixin.py:188} INFO - [2025-06-16T10:40:29.403+0000] {dagbag.py:538} INFO - Filling up the DagBag from /opt/airflow/dags/weather_dbt_dag.py
[2025-06-16T10:40:29.521+0000] {logging_mixin.py:188} INFO - [2025-06-16T10:40:29.521+0000] {configuration.py:1046} WARNING - section/key [openlineage/namespace] not found in config
[2025-06-16T10:40:30.140+0000] {logging_mixin.py:188} INFO - [2025-06-16T10:40:30.138+0000] {dagbag.py:348} ERROR - Failed to import: /opt/airflow/dags/weather_dbt_dag.py
Traceback (most recent call last):
  File "/home/airflow/.local/lib/python3.8/site-packages/airflow/models/dagbag.py", line 344, in parse
    loader.exec_module(new_module)
  File "<frozen importlib._bootstrap_external>", line 843, in exec_module
  File "<frozen importlib._bootstrap>", line 219, in _call_with_frames_removed
  File "/opt/airflow/dags/weather_dbt_dag.py", line 16, in <module>
    weather_dbt_dag = DbtDag(
  File "/home/airflow/.local/lib/python3.8/site-packages/cosmos/airflow/dag.py", line 25, in __init__
    DbtToAirflowConverter.__init__(self, *args, **specific_kwargs(**kwargs))
  File "/home/airflow/.local/lib/python3.8/site-packages/cosmos/converter.py", line 209, in __init__
    project_config.validate_project()
  File "/home/airflow/.local/lib/python3.8/site-packages/cosmos/config.py", line 193, in validate_project
    raise CosmosValueError(f"Could not find {name} at {path}")
cosmos.exceptions.CosmosValueError: Could not find dbt_project.yml at /opt/airflow/dbt/weather/dbt_project.yml
[2025-06-16T10:40:30.141+0000] {logging_mixin.py:188} WARNING - [2025-06-16T10:40:30.138+0000] {dagbag.py:348} ERROR - (astronomer-cosmos) - Failed to import: /opt/airflow/dags/weather_dbt_dag.py
Traceback (most recent call last):
  File "/home/airflow/.local/lib/python3.8/site-packages/airflow/models/dagbag.py", line 344, in parse
    loader.exec_module(new_module)
  File "<frozen importlib._bootstrap_external>", line 843, in exec_module
  File "<frozen importlib._bootstrap>", line 219, in _call_with_frames_removed
  File "/opt/airflow/dags/weather_dbt_dag.py", line 16, in <module>
    weather_dbt_dag = DbtDag(
  File "/home/airflow/.local/lib/python3.8/site-packages/cosmos/airflow/dag.py", line 25, in __init__
    DbtToAirflowConverter.__init__(self, *args, **specific_kwargs(**kwargs))
  File "/home/airflow/.local/lib/python3.8/site-packages/cosmos/converter.py", line 209, in __init__
    project_config.validate_project()
  File "/home/airflow/.local/lib/python3.8/site-packages/cosmos/config.py", line 193, in validate_project
    raise CosmosValueError(f"Could not find {name} at {path}")
cosmos.exceptions.CosmosValueError: Could not find dbt_project.yml at /opt/airflow/dbt/weather/dbt_project.yml
[2025-06-16T10:40:30.141+0000] {processor.py:842} WARNING - No viable dags retrieved from /opt/airflow/dags/weather_dbt_dag.py
[2025-06-16T10:40:30.170+0000] {processor.py:183} INFO - Processing /opt/airflow/dags/weather_dbt_dag.py took 0.780 seconds
[2025-06-16T10:41:01.021+0000] {processor.py:161} INFO - Started process (PID=182) to work on /opt/airflow/dags/weather_dbt_dag.py
[2025-06-16T10:41:01.022+0000] {processor.py:830} INFO - Processing file /opt/airflow/dags/weather_dbt_dag.py for tasks to queue
[2025-06-16T10:41:01.024+0000] {logging_mixin.py:188} INFO - [2025-06-16T10:41:01.023+0000] {dagbag.py:538} INFO - Filling up the DagBag from /opt/airflow/dags/weather_dbt_dag.py
[2025-06-16T10:41:01.063+0000] {logging_mixin.py:188} INFO - [2025-06-16T10:41:01.063+0000] {configuration.py:1046} WARNING - section/key [openlineage/namespace] not found in config
[2025-06-16T10:41:01.434+0000] {logging_mixin.py:188} INFO - [2025-06-16T10:41:01.433+0000] {dagbag.py:348} ERROR - Failed to import: /opt/airflow/dags/weather_dbt_dag.py
Traceback (most recent call last):
  File "/home/airflow/.local/lib/python3.8/site-packages/airflow/models/dagbag.py", line 344, in parse
    loader.exec_module(new_module)
  File "<frozen importlib._bootstrap_external>", line 843, in exec_module
  File "<frozen importlib._bootstrap>", line 219, in _call_with_frames_removed
  File "/opt/airflow/dags/weather_dbt_dag.py", line 16, in <module>
    weather_dbt_dag = DbtDag(
  File "/home/airflow/.local/lib/python3.8/site-packages/cosmos/airflow/dag.py", line 25, in __init__
    DbtToAirflowConverter.__init__(self, *args, **specific_kwargs(**kwargs))
  File "/home/airflow/.local/lib/python3.8/site-packages/cosmos/converter.py", line 209, in __init__
    project_config.validate_project()
  File "/home/airflow/.local/lib/python3.8/site-packages/cosmos/config.py", line 193, in validate_project
    raise CosmosValueError(f"Could not find {name} at {path}")
cosmos.exceptions.CosmosValueError: Could not find dbt_project.yml at /opt/airflow/dbt/weather/dbt_project.yml
[2025-06-16T10:41:01.435+0000] {logging_mixin.py:188} WARNING - [2025-06-16T10:41:01.433+0000] {dagbag.py:348} ERROR - (astronomer-cosmos) - Failed to import: /opt/airflow/dags/weather_dbt_dag.py
Traceback (most recent call last):
  File "/home/airflow/.local/lib/python3.8/site-packages/airflow/models/dagbag.py", line 344, in parse
    loader.exec_module(new_module)
  File "<frozen importlib._bootstrap_external>", line 843, in exec_module
  File "<frozen importlib._bootstrap>", line 219, in _call_with_frames_removed
  File "/opt/airflow/dags/weather_dbt_dag.py", line 16, in <module>
    weather_dbt_dag = DbtDag(
  File "/home/airflow/.local/lib/python3.8/site-packages/cosmos/airflow/dag.py", line 25, in __init__
    DbtToAirflowConverter.__init__(self, *args, **specific_kwargs(**kwargs))
  File "/home/airflow/.local/lib/python3.8/site-packages/cosmos/converter.py", line 209, in __init__
    project_config.validate_project()
  File "/home/airflow/.local/lib/python3.8/site-packages/cosmos/config.py", line 193, in validate_project
    raise CosmosValueError(f"Could not find {name} at {path}")
cosmos.exceptions.CosmosValueError: Could not find dbt_project.yml at /opt/airflow/dbt/weather/dbt_project.yml
[2025-06-16T10:41:01.437+0000] {processor.py:842} WARNING - No viable dags retrieved from /opt/airflow/dags/weather_dbt_dag.py
[2025-06-16T10:41:01.453+0000] {processor.py:183} INFO - Processing /opt/airflow/dags/weather_dbt_dag.py took 0.435 seconds
[2025-06-16T10:41:32.124+0000] {processor.py:161} INFO - Started process (PID=214) to work on /opt/airflow/dags/weather_dbt_dag.py
[2025-06-16T10:41:32.125+0000] {processor.py:830} INFO - Processing file /opt/airflow/dags/weather_dbt_dag.py for tasks to queue
[2025-06-16T10:41:32.128+0000] {logging_mixin.py:188} INFO - [2025-06-16T10:41:32.127+0000] {dagbag.py:538} INFO - Filling up the DagBag from /opt/airflow/dags/weather_dbt_dag.py
[2025-06-16T10:41:32.241+0000] {logging_mixin.py:188} INFO - [2025-06-16T10:41:32.241+0000] {configuration.py:1046} WARNING - section/key [openlineage/namespace] not found in config
[2025-06-16T10:41:32.868+0000] {logging_mixin.py:188} INFO - [2025-06-16T10:41:32.866+0000] {dagbag.py:348} ERROR - Failed to import: /opt/airflow/dags/weather_dbt_dag.py
Traceback (most recent call last):
  File "/home/airflow/.local/lib/python3.8/site-packages/airflow/models/dagbag.py", line 344, in parse
    loader.exec_module(new_module)
  File "<frozen importlib._bootstrap_external>", line 843, in exec_module
  File "<frozen importlib._bootstrap>", line 219, in _call_with_frames_removed
  File "/opt/airflow/dags/weather_dbt_dag.py", line 16, in <module>
    weather_dbt_dag = DbtDag(
  File "/home/airflow/.local/lib/python3.8/site-packages/cosmos/airflow/dag.py", line 25, in __init__
    DbtToAirflowConverter.__init__(self, *args, **specific_kwargs(**kwargs))
  File "/home/airflow/.local/lib/python3.8/site-packages/cosmos/converter.py", line 209, in __init__
    project_config.validate_project()
  File "/home/airflow/.local/lib/python3.8/site-packages/cosmos/config.py", line 193, in validate_project
    raise CosmosValueError(f"Could not find {name} at {path}")
cosmos.exceptions.CosmosValueError: Could not find dbt_project.yml at /opt/airflow/dbt/weather/dbt_project.yml
[2025-06-16T10:41:32.868+0000] {logging_mixin.py:188} WARNING - [2025-06-16T10:41:32.866+0000] {dagbag.py:348} ERROR - (astronomer-cosmos) - Failed to import: /opt/airflow/dags/weather_dbt_dag.py
Traceback (most recent call last):
  File "/home/airflow/.local/lib/python3.8/site-packages/airflow/models/dagbag.py", line 344, in parse
    loader.exec_module(new_module)
  File "<frozen importlib._bootstrap_external>", line 843, in exec_module
  File "<frozen importlib._bootstrap>", line 219, in _call_with_frames_removed
  File "/opt/airflow/dags/weather_dbt_dag.py", line 16, in <module>
    weather_dbt_dag = DbtDag(
  File "/home/airflow/.local/lib/python3.8/site-packages/cosmos/airflow/dag.py", line 25, in __init__
    DbtToAirflowConverter.__init__(self, *args, **specific_kwargs(**kwargs))
  File "/home/airflow/.local/lib/python3.8/site-packages/cosmos/converter.py", line 209, in __init__
    project_config.validate_project()
  File "/home/airflow/.local/lib/python3.8/site-packages/cosmos/config.py", line 193, in validate_project
    raise CosmosValueError(f"Could not find {name} at {path}")
cosmos.exceptions.CosmosValueError: Could not find dbt_project.yml at /opt/airflow/dbt/weather/dbt_project.yml
[2025-06-16T10:41:32.870+0000] {processor.py:842} WARNING - No viable dags retrieved from /opt/airflow/dags/weather_dbt_dag.py
[2025-06-16T10:41:32.905+0000] {processor.py:183} INFO - Processing /opt/airflow/dags/weather_dbt_dag.py took 0.785 seconds
[2025-06-16T10:42:03.001+0000] {processor.py:161} INFO - Started process (PID=237) to work on /opt/airflow/dags/weather_dbt_dag.py
[2025-06-16T10:42:03.001+0000] {processor.py:830} INFO - Processing file /opt/airflow/dags/weather_dbt_dag.py for tasks to queue
[2025-06-16T10:42:03.003+0000] {logging_mixin.py:188} INFO - [2025-06-16T10:42:03.003+0000] {dagbag.py:538} INFO - Filling up the DagBag from /opt/airflow/dags/weather_dbt_dag.py
[2025-06-16T10:42:03.049+0000] {logging_mixin.py:188} INFO - [2025-06-16T10:42:03.049+0000] {configuration.py:1046} WARNING - section/key [openlineage/namespace] not found in config
[2025-06-16T10:42:03.394+0000] {logging_mixin.py:188} INFO - [2025-06-16T10:42:03.393+0000] {dagbag.py:348} ERROR - Failed to import: /opt/airflow/dags/weather_dbt_dag.py
Traceback (most recent call last):
  File "/home/airflow/.local/lib/python3.8/site-packages/airflow/models/dagbag.py", line 344, in parse
    loader.exec_module(new_module)
  File "<frozen importlib._bootstrap_external>", line 843, in exec_module
  File "<frozen importlib._bootstrap>", line 219, in _call_with_frames_removed
  File "/opt/airflow/dags/weather_dbt_dag.py", line 16, in <module>
    weather_dbt_dag = DbtDag(
  File "/home/airflow/.local/lib/python3.8/site-packages/cosmos/airflow/dag.py", line 25, in __init__
    DbtToAirflowConverter.__init__(self, *args, **specific_kwargs(**kwargs))
  File "/home/airflow/.local/lib/python3.8/site-packages/cosmos/converter.py", line 209, in __init__
    project_config.validate_project()
  File "/home/airflow/.local/lib/python3.8/site-packages/cosmos/config.py", line 193, in validate_project
    raise CosmosValueError(f"Could not find {name} at {path}")
cosmos.exceptions.CosmosValueError: Could not find dbt_project.yml at /opt/airflow/dbt/weather/dbt_project.yml
[2025-06-16T10:42:03.394+0000] {logging_mixin.py:188} WARNING - [2025-06-16T10:42:03.393+0000] {dagbag.py:348} ERROR - (astronomer-cosmos) - Failed to import: /opt/airflow/dags/weather_dbt_dag.py
Traceback (most recent call last):
  File "/home/airflow/.local/lib/python3.8/site-packages/airflow/models/dagbag.py", line 344, in parse
    loader.exec_module(new_module)
  File "<frozen importlib._bootstrap_external>", line 843, in exec_module
  File "<frozen importlib._bootstrap>", line 219, in _call_with_frames_removed
  File "/opt/airflow/dags/weather_dbt_dag.py", line 16, in <module>
    weather_dbt_dag = DbtDag(
  File "/home/airflow/.local/lib/python3.8/site-packages/cosmos/airflow/dag.py", line 25, in __init__
    DbtToAirflowConverter.__init__(self, *args, **specific_kwargs(**kwargs))
  File "/home/airflow/.local/lib/python3.8/site-packages/cosmos/converter.py", line 209, in __init__
    project_config.validate_project()
  File "/home/airflow/.local/lib/python3.8/site-packages/cosmos/config.py", line 193, in validate_project
    raise CosmosValueError(f"Could not find {name} at {path}")
cosmos.exceptions.CosmosValueError: Could not find dbt_project.yml at /opt/airflow/dbt/weather/dbt_project.yml
[2025-06-16T10:42:03.394+0000] {processor.py:842} WARNING - No viable dags retrieved from /opt/airflow/dags/weather_dbt_dag.py
[2025-06-16T10:42:03.407+0000] {processor.py:183} INFO - Processing /opt/airflow/dags/weather_dbt_dag.py took 0.409 seconds
