[2025-06-19T11:31:16.929+0000] {taskinstance.py:1957} INFO - Dependencies all met for dep_context=non-requeueable deps ti=<TaskInstance: week_3_weather_api_dag.create_weather_table scheduled__2025-06-19T03:00:00+00:00 [queued]>
[2025-06-19T11:31:16.986+0000] {taskinstance.py:1957} INFO - Dependencies all met for dep_context=requeueable deps ti=<TaskInstance: week_3_weather_api_dag.create_weather_table scheduled__2025-06-19T03:00:00+00:00 [queued]>
[2025-06-19T11:31:16.994+0000] {taskinstance.py:2171} INFO - Starting attempt 1 of 1
[2025-06-19T11:31:17.065+0000] {taskinstance.py:2192} INFO - Executing <Task(PythonOperator): create_weather_table> on 2025-06-19 03:00:00+00:00
[2025-06-19T11:31:17.097+0000] {standard_task_runner.py:87} INFO - Running: ['***', 'tasks', 'run', 'week_3_weather_api_dag', 'create_weather_table', 'scheduled__2025-06-19T03:00:00+00:00', '--job-id', '21', '--raw', '--subdir', 'DAGS_FOLDER/week_3_weather_api_dag.py', '--cfg-path', '/tmp/tmpactwv87a']
[2025-06-19T11:31:17.106+0000] {standard_task_runner.py:88} INFO - Job 21: Subtask create_weather_table
[2025-06-19T11:31:17.091+0000] {standard_task_runner.py:60} INFO - Started process 1061 to run task
[2025-06-19T11:31:17.210+0000] {task_command.py:423} INFO - Running <TaskInstance: week_3_weather_api_dag.create_weather_table scheduled__2025-06-19T03:00:00+00:00 [running]> on host 77bf71b7bc3a
[2025-06-19T11:31:17.497+0000] {taskinstance.py:2481} INFO - Exporting env vars: AIRFLOW_CTX_DAG_OWNER='***' AIRFLOW_CTX_DAG_ID='week_3_weather_api_dag' AIRFLOW_CTX_TASK_ID='create_weather_table' AIRFLOW_CTX_EXECUTION_DATE='2025-06-19T03:00:00+00:00' AIRFLOW_CTX_TRY_NUMBER='1' AIRFLOW_CTX_DAG_RUN_ID='scheduled__2025-06-19T03:00:00+00:00'
[2025-06-19T11:31:17.575+0000] {taskinstance.py:2699} ERROR - Task failed with exception
Traceback (most recent call last):
  File "/home/airflow/.local/lib/python3.8/site-packages/airflow/models/taskinstance.py", line 433, in _execute_task
    result = execute_callable(context=context, **execute_callable_kwargs)
  File "/home/airflow/.local/lib/python3.8/site-packages/airflow/operators/python.py", line 199, in execute
    return_value = self.execute_callable()
  File "/home/airflow/.local/lib/python3.8/site-packages/airflow/operators/python.py", line 216, in execute_callable
    return self.python_callable(*self.op_args, **self.op_kwargs)
  File "/opt/airflow/dags/week_3_weather_api_dag.py", line 47, in _create_weather_table
    connection = pg_hook.get_conn()
  File "/home/airflow/.local/lib/python3.8/site-packages/airflow/providers/postgres/hooks/postgres.py", line 128, in get_conn
    conn = deepcopy(self.connection or self.get_connection(conn_id))
  File "/home/airflow/.local/lib/python3.8/site-packages/airflow/hooks/base.py", line 82, in get_connection
    conn = Connection.get_connection_from_secrets(conn_id)
  File "/home/airflow/.local/lib/python3.8/site-packages/airflow/models/connection.py", line 479, in get_connection_from_secrets
    raise AirflowNotFoundException(f"The conn_id `{conn_id}` isn't defined")
airflow.exceptions.AirflowNotFoundException: The conn_id `weather_postgres_conn` isn't defined
[2025-06-19T11:31:17.589+0000] {taskinstance.py:1138} INFO - Marking task as FAILED. dag_id=week_3_weather_api_dag, task_id=create_weather_table, execution_date=20250619T030000, start_date=20250619T113116, end_date=20250619T113117
[2025-06-19T11:31:17.623+0000] {standard_task_runner.py:107} ERROR - Failed to execute job 21 for task create_weather_table (The conn_id `weather_postgres_conn` isn't defined; 1061)
[2025-06-19T11:31:17.656+0000] {local_task_job_runner.py:234} INFO - Task exited with return code 1
[2025-06-19T11:31:17.748+0000] {taskinstance.py:3281} INFO - 0 downstream tasks scheduled from follow-on schedule check
[2025-06-19T12:06:10.739+0000] {taskinstance.py:1957} INFO - Dependencies all met for dep_context=non-requeueable deps ti=<TaskInstance: week_3_weather_api_dag.create_weather_table scheduled__2025-06-19T03:00:00+00:00 [queued]>
[2025-06-19T12:06:10.899+0000] {taskinstance.py:1957} INFO - Dependencies all met for dep_context=requeueable deps ti=<TaskInstance: week_3_weather_api_dag.create_weather_table scheduled__2025-06-19T03:00:00+00:00 [queued]>
[2025-06-19T12:06:10.913+0000] {taskinstance.py:2171} INFO - Starting attempt 1 of 1
[2025-06-19T12:06:11.016+0000] {taskinstance.py:2192} INFO - Executing <Task(PythonOperator): create_weather_table> on 2025-06-19 03:00:00+00:00
[2025-06-19T12:06:11.057+0000] {standard_task_runner.py:60} INFO - Started process 1583 to run task
[2025-06-19T12:06:11.076+0000] {standard_task_runner.py:87} INFO - Running: ['***', 'tasks', 'run', 'week_3_weather_api_dag', 'create_weather_table', 'scheduled__2025-06-19T03:00:00+00:00', '--job-id', '30', '--raw', '--subdir', 'DAGS_FOLDER/week_3_weather_api_dag.py', '--cfg-path', '/tmp/tmpx63wlqfi']
[2025-06-19T12:06:11.095+0000] {standard_task_runner.py:88} INFO - Job 30: Subtask create_weather_table
[2025-06-19T12:06:11.526+0000] {task_command.py:423} INFO - Running <TaskInstance: week_3_weather_api_dag.create_weather_table scheduled__2025-06-19T03:00:00+00:00 [running]> on host 77bf71b7bc3a
[2025-06-19T12:06:12.051+0000] {taskinstance.py:2481} INFO - Exporting env vars: AIRFLOW_CTX_DAG_OWNER='***' AIRFLOW_CTX_DAG_ID='week_3_weather_api_dag' AIRFLOW_CTX_TASK_ID='create_weather_table' AIRFLOW_CTX_EXECUTION_DATE='2025-06-19T03:00:00+00:00' AIRFLOW_CTX_TRY_NUMBER='1' AIRFLOW_CTX_DAG_RUN_ID='scheduled__2025-06-19T03:00:00+00:00'
[2025-06-19T12:06:12.198+0000] {taskinstance.py:2699} ERROR - Task failed with exception
Traceback (most recent call last):
  File "/home/airflow/.local/lib/python3.8/site-packages/airflow/models/taskinstance.py", line 433, in _execute_task
    result = execute_callable(context=context, **execute_callable_kwargs)
  File "/home/airflow/.local/lib/python3.8/site-packages/airflow/operators/python.py", line 199, in execute
    return_value = self.execute_callable()
  File "/home/airflow/.local/lib/python3.8/site-packages/airflow/operators/python.py", line 216, in execute_callable
    return self.python_callable(*self.op_args, **self.op_kwargs)
  File "/opt/airflow/dags/week_3_weather_api_dag.py", line 44, in _create_weather_table
    connection = pg_hook.get_conn()
  File "/home/airflow/.local/lib/python3.8/site-packages/airflow/providers/postgres/hooks/postgres.py", line 128, in get_conn
    conn = deepcopy(self.connection or self.get_connection(conn_id))
  File "/home/airflow/.local/lib/python3.8/site-packages/airflow/hooks/base.py", line 82, in get_connection
    conn = Connection.get_connection_from_secrets(conn_id)
  File "/home/airflow/.local/lib/python3.8/site-packages/airflow/models/connection.py", line 479, in get_connection_from_secrets
    raise AirflowNotFoundException(f"The conn_id `{conn_id}` isn't defined")
airflow.exceptions.AirflowNotFoundException: The conn_id `weather_postgres_conn` isn't defined
[2025-06-19T12:06:12.258+0000] {taskinstance.py:1138} INFO - Marking task as FAILED. dag_id=week_3_weather_api_dag, task_id=create_weather_table, execution_date=20250619T030000, start_date=20250619T120610, end_date=20250619T120612
[2025-06-19T12:06:12.420+0000] {standard_task_runner.py:107} ERROR - Failed to execute job 30 for task create_weather_table (The conn_id `weather_postgres_conn` isn't defined; 1583)
[2025-06-19T12:06:12.552+0000] {local_task_job_runner.py:234} INFO - Task exited with return code 1
[2025-06-19T12:06:12.951+0000] {taskinstance.py:3281} INFO - 0 downstream tasks scheduled from follow-on schedule check
[2025-06-19T12:19:02.141+0000] {taskinstance.py:1957} INFO - Dependencies all met for dep_context=non-requeueable deps ti=<TaskInstance: week_3_weather_api_dag.create_weather_table scheduled__2025-06-19T03:00:00+00:00 [queued]>
[2025-06-19T12:19:02.224+0000] {taskinstance.py:1957} INFO - Dependencies all met for dep_context=requeueable deps ti=<TaskInstance: week_3_weather_api_dag.create_weather_table scheduled__2025-06-19T03:00:00+00:00 [queued]>
[2025-06-19T12:19:02.230+0000] {taskinstance.py:2171} INFO - Starting attempt 1 of 1
[2025-06-19T12:19:02.358+0000] {taskinstance.py:2192} INFO - Executing <Task(PythonOperator): create_weather_table> on 2025-06-19 03:00:00+00:00
[2025-06-19T12:19:02.445+0000] {standard_task_runner.py:60} INFO - Started process 137 to run task
[2025-06-19T12:19:02.514+0000] {standard_task_runner.py:87} INFO - Running: ['***', 'tasks', 'run', 'week_3_weather_api_dag', 'create_weather_table', 'scheduled__2025-06-19T03:00:00+00:00', '--job-id', '48', '--raw', '--subdir', 'DAGS_FOLDER/week_3_weather_api_dag.py', '--cfg-path', '/tmp/tmp2keuixmo']
[2025-06-19T12:19:02.555+0000] {standard_task_runner.py:88} INFO - Job 48: Subtask create_weather_table
[2025-06-19T12:19:03.236+0000] {task_command.py:423} INFO - Running <TaskInstance: week_3_weather_api_dag.create_weather_table scheduled__2025-06-19T03:00:00+00:00 [running]> on host b96384fab38e
[2025-06-19T12:19:03.908+0000] {taskinstance.py:2481} INFO - Exporting env vars: AIRFLOW_CTX_DAG_OWNER='***' AIRFLOW_CTX_DAG_ID='week_3_weather_api_dag' AIRFLOW_CTX_TASK_ID='create_weather_table' AIRFLOW_CTX_EXECUTION_DATE='2025-06-19T03:00:00+00:00' AIRFLOW_CTX_TRY_NUMBER='1' AIRFLOW_CTX_DAG_RUN_ID='scheduled__2025-06-19T03:00:00+00:00'
[2025-06-19T12:19:03.981+0000] {base.py:83} INFO - Using connection ID 'weather_***_conn' for task execution.
[2025-06-19T12:19:04.008+0000] {python.py:201} INFO - Done. Returned value was: None
[2025-06-19T12:19:04.090+0000] {taskinstance.py:1138} INFO - Marking task as SUCCESS. dag_id=week_3_weather_api_dag, task_id=create_weather_table, execution_date=20250619T030000, start_date=20250619T121902, end_date=20250619T121904
[2025-06-19T12:19:04.298+0000] {local_task_job_runner.py:234} INFO - Task exited with return code 0
[2025-06-19T12:19:04.564+0000] {taskinstance.py:3281} INFO - 0 downstream tasks scheduled from follow-on schedule check
