[2025-06-19T11:31:14.151+0000] {taskinstance.py:1957} INFO - Dependencies all met for dep_context=non-requeueable deps ti=<TaskInstance: week_3_weather_api_dag.create_weather_table scheduled__2025-06-19T00:00:00+00:00 [queued]>
[2025-06-19T11:31:14.196+0000] {taskinstance.py:1957} INFO - Dependencies all met for dep_context=requeueable deps ti=<TaskInstance: week_3_weather_api_dag.create_weather_table scheduled__2025-06-19T00:00:00+00:00 [queued]>
[2025-06-19T11:31:14.196+0000] {taskinstance.py:2171} INFO - Starting attempt 1 of 1
[2025-06-19T11:31:14.241+0000] {taskinstance.py:2192} INFO - Executing <Task(PythonOperator): create_weather_table> on 2025-06-19 00:00:00+00:00
[2025-06-19T11:31:14.271+0000] {standard_task_runner.py:60} INFO - Started process 1059 to run task
[2025-06-19T11:31:14.286+0000] {standard_task_runner.py:87} INFO - Running: ['***', 'tasks', 'run', 'week_3_weather_api_dag', 'create_weather_table', 'scheduled__2025-06-19T00:00:00+00:00', '--job-id', '19', '--raw', '--subdir', 'DAGS_FOLDER/week_3_weather_api_dag.py', '--cfg-path', '/tmp/tmpzoiv4_q1']
[2025-06-19T11:31:14.294+0000] {standard_task_runner.py:88} INFO - Job 19: Subtask create_weather_table
[2025-06-19T11:31:14.496+0000] {task_command.py:423} INFO - Running <TaskInstance: week_3_weather_api_dag.create_weather_table scheduled__2025-06-19T00:00:00+00:00 [running]> on host 77bf71b7bc3a
[2025-06-19T11:31:14.975+0000] {taskinstance.py:2481} INFO - Exporting env vars: AIRFLOW_CTX_DAG_OWNER='***' AIRFLOW_CTX_DAG_ID='week_3_weather_api_dag' AIRFLOW_CTX_TASK_ID='create_weather_table' AIRFLOW_CTX_EXECUTION_DATE='2025-06-19T00:00:00+00:00' AIRFLOW_CTX_TRY_NUMBER='1' AIRFLOW_CTX_DAG_RUN_ID='scheduled__2025-06-19T00:00:00+00:00'
[2025-06-19T11:31:15.097+0000] {taskinstance.py:2699} ERROR - Task failed with exception
Traceback (most recent call last):
  File "/home/airflow/.local/lib/python3.8/site-packages/airflow/models/taskinstance.py", line 433, in _execute_task
    result = execute_callable(context=context, **execute_callable_kwargs)
  File "/home/airflow/.local/lib/python3.8/site-packages/airflow/operators/python.py", line 199, in execute
    return_value = self.execute_callable()
  File "/home/airflow/.local/lib/python3.8/site-packages/airflow/operators/python.py", line 216, in execute_callable
    return self.python_callable(*self.op_args, **self.op_kwargs)
  File "/opt/airflow/dags/week_3_weather_api_dag.py", line 47, in _create_weather_table
    connection = pg_hook.get_conn()
  File "/home/airflow/.local/lib/python3.8/site-packages/airflow/providers/postgres/hooks/postgres.py", line 128, in get_conn
    conn = deepcopy(self.connection or self.get_connection(conn_id))
  File "/home/airflow/.local/lib/python3.8/site-packages/airflow/hooks/base.py", line 82, in get_connection
    conn = Connection.get_connection_from_secrets(conn_id)
  File "/home/airflow/.local/lib/python3.8/site-packages/airflow/models/connection.py", line 479, in get_connection_from_secrets
    raise AirflowNotFoundException(f"The conn_id `{conn_id}` isn't defined")
airflow.exceptions.AirflowNotFoundException: The conn_id `weather_postgres_conn` isn't defined
[2025-06-19T11:31:15.174+0000] {taskinstance.py:1138} INFO - Marking task as FAILED. dag_id=week_3_weather_api_dag, task_id=create_weather_table, execution_date=20250619T000000, start_date=20250619T113114, end_date=20250619T113115
[2025-06-19T11:31:15.379+0000] {standard_task_runner.py:107} ERROR - Failed to execute job 19 for task create_weather_table (The conn_id `weather_postgres_conn` isn't defined; 1059)
[2025-06-19T11:31:15.639+0000] {local_task_job_runner.py:234} INFO - Task exited with return code 1
[2025-06-19T11:31:16.086+0000] {taskinstance.py:3281} INFO - 0 downstream tasks scheduled from follow-on schedule check
[2025-06-19T12:06:08.952+0000] {taskinstance.py:1957} INFO - Dependencies all met for dep_context=non-requeueable deps ti=<TaskInstance: week_3_weather_api_dag.create_weather_table scheduled__2025-06-19T00:00:00+00:00 [queued]>
[2025-06-19T12:06:09.163+0000] {taskinstance.py:1957} INFO - Dependencies all met for dep_context=requeueable deps ti=<TaskInstance: week_3_weather_api_dag.create_weather_table scheduled__2025-06-19T00:00:00+00:00 [queued]>
[2025-06-19T12:06:09.191+0000] {taskinstance.py:2171} INFO - Starting attempt 1 of 1
[2025-06-19T12:06:09.314+0000] {taskinstance.py:2192} INFO - Executing <Task(PythonOperator): create_weather_table> on 2025-06-19 00:00:00+00:00
[2025-06-19T12:06:09.360+0000] {standard_task_runner.py:60} INFO - Started process 1579 to run task
[2025-06-19T12:06:09.377+0000] {standard_task_runner.py:87} INFO - Running: ['***', 'tasks', 'run', 'week_3_weather_api_dag', 'create_weather_table', 'scheduled__2025-06-19T00:00:00+00:00', '--job-id', '28', '--raw', '--subdir', 'DAGS_FOLDER/week_3_weather_api_dag.py', '--cfg-path', '/tmp/tmpb_8u1ufi']
[2025-06-19T12:06:09.390+0000] {standard_task_runner.py:88} INFO - Job 28: Subtask create_weather_table
[2025-06-19T12:06:09.728+0000] {task_command.py:423} INFO - Running <TaskInstance: week_3_weather_api_dag.create_weather_table scheduled__2025-06-19T00:00:00+00:00 [running]> on host 77bf71b7bc3a
[2025-06-19T12:06:10.515+0000] {taskinstance.py:2481} INFO - Exporting env vars: AIRFLOW_CTX_DAG_OWNER='***' AIRFLOW_CTX_DAG_ID='week_3_weather_api_dag' AIRFLOW_CTX_TASK_ID='create_weather_table' AIRFLOW_CTX_EXECUTION_DATE='2025-06-19T00:00:00+00:00' AIRFLOW_CTX_TRY_NUMBER='1' AIRFLOW_CTX_DAG_RUN_ID='scheduled__2025-06-19T00:00:00+00:00'
[2025-06-19T12:06:10.727+0000] {taskinstance.py:2699} ERROR - Task failed with exception
Traceback (most recent call last):
  File "/home/airflow/.local/lib/python3.8/site-packages/airflow/models/taskinstance.py", line 433, in _execute_task
    result = execute_callable(context=context, **execute_callable_kwargs)
  File "/home/airflow/.local/lib/python3.8/site-packages/airflow/operators/python.py", line 199, in execute
    return_value = self.execute_callable()
  File "/home/airflow/.local/lib/python3.8/site-packages/airflow/operators/python.py", line 216, in execute_callable
    return self.python_callable(*self.op_args, **self.op_kwargs)
  File "/opt/airflow/dags/week_3_weather_api_dag.py", line 44, in _create_weather_table
    connection = pg_hook.get_conn()
  File "/home/airflow/.local/lib/python3.8/site-packages/airflow/providers/postgres/hooks/postgres.py", line 128, in get_conn
    conn = deepcopy(self.connection or self.get_connection(conn_id))
  File "/home/airflow/.local/lib/python3.8/site-packages/airflow/hooks/base.py", line 82, in get_connection
    conn = Connection.get_connection_from_secrets(conn_id)
  File "/home/airflow/.local/lib/python3.8/site-packages/airflow/models/connection.py", line 479, in get_connection_from_secrets
    raise AirflowNotFoundException(f"The conn_id `{conn_id}` isn't defined")
airflow.exceptions.AirflowNotFoundException: The conn_id `weather_postgres_conn` isn't defined
[2025-06-19T12:06:10.777+0000] {taskinstance.py:1138} INFO - Marking task as FAILED. dag_id=week_3_weather_api_dag, task_id=create_weather_table, execution_date=20250619T000000, start_date=20250619T120608, end_date=20250619T120610
[2025-06-19T12:06:10.845+0000] {standard_task_runner.py:107} ERROR - Failed to execute job 28 for task create_weather_table (The conn_id `weather_postgres_conn` isn't defined; 1579)
[2025-06-19T12:06:10.982+0000] {local_task_job_runner.py:234} INFO - Task exited with return code 1
[2025-06-19T12:06:11.121+0000] {taskinstance.py:3281} INFO - 0 downstream tasks scheduled from follow-on schedule check
[2025-06-19T12:18:58.045+0000] {taskinstance.py:1957} INFO - Dependencies all met for dep_context=non-requeueable deps ti=<TaskInstance: week_3_weather_api_dag.create_weather_table scheduled__2025-06-19T00:00:00+00:00 [queued]>
[2025-06-19T12:18:58.152+0000] {taskinstance.py:1957} INFO - Dependencies all met for dep_context=requeueable deps ti=<TaskInstance: week_3_weather_api_dag.create_weather_table scheduled__2025-06-19T00:00:00+00:00 [queued]>
[2025-06-19T12:18:58.160+0000] {taskinstance.py:2171} INFO - Starting attempt 1 of 1
[2025-06-19T12:18:58.282+0000] {taskinstance.py:2192} INFO - Executing <Task(PythonOperator): create_weather_table> on 2025-06-19 00:00:00+00:00
[2025-06-19T12:18:58.347+0000] {standard_task_runner.py:60} INFO - Started process 130 to run task
[2025-06-19T12:18:58.358+0000] {standard_task_runner.py:87} INFO - Running: ['***', 'tasks', 'run', 'week_3_weather_api_dag', 'create_weather_table', 'scheduled__2025-06-19T00:00:00+00:00', '--job-id', '46', '--raw', '--subdir', 'DAGS_FOLDER/week_3_weather_api_dag.py', '--cfg-path', '/tmp/tmpxk88dzvi']
[2025-06-19T12:18:58.377+0000] {standard_task_runner.py:88} INFO - Job 46: Subtask create_weather_table
[2025-06-19T12:18:58.661+0000] {task_command.py:423} INFO - Running <TaskInstance: week_3_weather_api_dag.create_weather_table scheduled__2025-06-19T00:00:00+00:00 [running]> on host b96384fab38e
[2025-06-19T12:18:59.132+0000] {taskinstance.py:2481} INFO - Exporting env vars: AIRFLOW_CTX_DAG_OWNER='***' AIRFLOW_CTX_DAG_ID='week_3_weather_api_dag' AIRFLOW_CTX_TASK_ID='create_weather_table' AIRFLOW_CTX_EXECUTION_DATE='2025-06-19T00:00:00+00:00' AIRFLOW_CTX_TRY_NUMBER='1' AIRFLOW_CTX_DAG_RUN_ID='scheduled__2025-06-19T00:00:00+00:00'
[2025-06-19T12:18:59.196+0000] {base.py:83} INFO - Using connection ID 'weather_***_conn' for task execution.
[2025-06-19T12:18:59.225+0000] {python.py:201} INFO - Done. Returned value was: None
[2025-06-19T12:18:59.307+0000] {taskinstance.py:1138} INFO - Marking task as SUCCESS. dag_id=week_3_weather_api_dag, task_id=create_weather_table, execution_date=20250619T000000, start_date=20250619T121858, end_date=20250619T121859
[2025-06-19T12:18:59.582+0000] {local_task_job_runner.py:234} INFO - Task exited with return code 0
[2025-06-19T12:19:00.062+0000] {taskinstance.py:3281} INFO - 0 downstream tasks scheduled from follow-on schedule check
