[2025-06-20T10:05:42.142+0000] {taskinstance.py:1957} INFO - Dependencies all met for dep_context=non-requeueable deps ti=<TaskInstance: week_4_weather_api_dag_test_fail.get_weather_data scheduled__2025-06-20T09:00:00+00:00 [queued]>
[2025-06-20T10:05:42.170+0000] {taskinstance.py:1957} INFO - Dependencies all met for dep_context=requeueable deps ti=<TaskInstance: week_4_weather_api_dag_test_fail.get_weather_data scheduled__2025-06-20T09:00:00+00:00 [queued]>
[2025-06-20T10:05:42.171+0000] {taskinstance.py:2171} INFO - Starting attempt 1 of 1
[2025-06-20T10:05:42.195+0000] {taskinstance.py:2192} INFO - Executing <Task(PythonOperator): get_weather_data> on 2025-06-20 09:00:00+00:00
[2025-06-20T10:05:42.223+0000] {standard_task_runner.py:60} INFO - Started process 105 to run task
[2025-06-20T10:05:42.237+0000] {standard_task_runner.py:87} INFO - Running: ['***', 'tasks', 'run', 'week_4_weather_api_dag_test_fail', 'get_weather_data', 'scheduled__2025-06-20T09:00:00+00:00', '--job-id', '94', '--raw', '--subdir', 'DAGS_FOLDER/week_4_weather_api_dag_test_fail.py', '--cfg-path', '/tmp/tmpuuxxy5_7']
[2025-06-20T10:05:42.241+0000] {standard_task_runner.py:88} INFO - Job 94: Subtask get_weather_data
[2025-06-20T10:05:42.366+0000] {task_command.py:423} INFO - Running <TaskInstance: week_4_weather_api_dag_test_fail.get_weather_data scheduled__2025-06-20T09:00:00+00:00 [running]> on host 2bcc52851b40
[2025-06-20T10:05:42.566+0000] {taskinstance.py:2481} INFO - Exporting env vars: AIRFLOW_CTX_DAG_EMAIL='supitchaya.p99@gmail.com' AIRFLOW_CTX_DAG_OWNER='***' AIRFLOW_CTX_DAG_ID='week_4_weather_api_dag_test_fail' AIRFLOW_CTX_TASK_ID='get_weather_data' AIRFLOW_CTX_EXECUTION_DATE='2025-06-20T09:00:00+00:00' AIRFLOW_CTX_TRY_NUMBER='1' AIRFLOW_CTX_DAG_RUN_ID='scheduled__2025-06-20T09:00:00+00:00'
[2025-06-20T10:05:42.907+0000] {taskinstance.py:2699} ERROR - Task failed with exception
Traceback (most recent call last):
  File "/home/airflow/.local/lib/python3.8/site-packages/airflow/models/taskinstance.py", line 433, in _execute_task
    result = execute_callable(context=context, **execute_callable_kwargs)
  File "/home/airflow/.local/lib/python3.8/site-packages/airflow/operators/python.py", line 199, in execute
    return_value = self.execute_callable()
  File "/home/airflow/.local/lib/python3.8/site-packages/airflow/operators/python.py", line 216, in execute_callable
    return self.python_callable(*self.op_args, **self.op_kwargs)
  File "/opt/airflow/dags/week_4_weather_api_dag_test_fail.py", line 24, in _get_weather_data
    print(reponse.uri)
NameError: name 'reponse' is not defined
[2025-06-20T10:05:42.945+0000] {taskinstance.py:1138} INFO - Marking task as FAILED. dag_id=week_4_weather_api_dag_test_fail, task_id=get_weather_data, execution_date=20250620T090000, start_date=20250620T100542, end_date=20250620T100542
[2025-06-20T10:05:43.003+0000] {warnings.py:109} WARNING - /home/***/.local/lib/python3.8/site-packages/***/utils/email.py:154: RemovedInAirflow3Warning: Fetching SMTP credentials from configuration variables will be deprecated in a future release. Please set credentials using a connection instead.
  send_mime_email(e_from=mail_from, e_to=recipients, mime_msg=msg, conn_id=conn_id, dryrun=dryrun)

[2025-06-20T10:05:43.013+0000] {configuration.py:1046} WARNING - section/key [smtp/smtp_user] not found in config
[2025-06-20T10:05:43.020+0000] {email.py:270} INFO - Email alerting: attempt 1
[2025-06-20T10:05:43.035+0000] {email.py:281} INFO - Sent an alert email to ['supitchaya.p99@gmail.com']
[2025-06-20T10:05:43.105+0000] {standard_task_runner.py:107} ERROR - Failed to execute job 94 for task get_weather_data (name 'reponse' is not defined; 105)
[2025-06-20T10:05:43.221+0000] {local_task_job_runner.py:234} INFO - Task exited with return code 1
[2025-06-20T10:05:43.400+0000] {taskinstance.py:3281} INFO - 0 downstream tasks scheduled from follow-on schedule check
